Workbook

Sheet 계좌현황
C3: 종목별 실적 & 비중
I5: $1 = ￦1,379 | J5: 1379.48
C6: 국가 | D6: 종목코드 (티커) | E6: 종목명 | F6: 수량 | G6: 평단가 | I6: 현재가 | K6: 평가액 [원화] | L6: 투자비중 | M6: 누적수익 [원화] | N6: 총수익률 [평가+배당] | O6: 종목
G7: 원화 | H7: 달러 | I7: 원화 | J7: 달러
A8: 계좌 | B8: 번호 | K8: =SUM(K9:K84) | M8: =SUM(M9:M84) | N8: =IFERROR(M8/(K8-M8),)
A9: DC | B9: 1 | C9: 한국 | D9: 458760 | E9: TIGER 미배당다우커버드콜2호 | F9: 9359 | G9: 9435 | I9: 11285 | K9: =IFERROR(I9*F9+J9*$J$5*F9,) | L9: =IFERROR(K9/$K$8,) | M9: =IFERROR(K9-G9*F9-H9*$J$5*F9,) | N9: =IFERROR(M9/(K9-M9),) | O9: 다우커
A10: DC | B10: 2 | C10: 한국 | D10: 490490 | E10: SOL미국배당미국채혼합50 | F10: 3821 | G10: 10603 | I10: 11200 | K10: =IFERROR(I10*F10+J10*$J$5*F10,) | L10: =IFERROR(K10/$K$8,) | M10: =IFERROR(K10-G10*F10-H10*$J$5*F10,) | N10: =IFERROR(M10/(K10-M10),) | O10: 미배당국채
A11: DC | B11: 3 | C11: 한국 | D11: 0008S0 | E11: TIGER 미국배당다우존스타겟데일리커버드콜 | F11: 3000 | G11: 8910 | I11: 10175 | K11: =IFERROR(I11*F11+J11*$J$5*F11,) | L11: =IFERROR(K11/$K$8,) | M11: =IFERROR(K11-G11*F11-H11*$J$5*F11,) | N11: =IFERROR(M11/(K11-M11),) | O11: 다우커
A12: DC | B12: 4 | C12: 한국 | D12: 498410 | E12: KODEX금융고배당TOP10타겟위클리커버드콜 | F12: 2377 | G12: 12286 | I12: 11470 | K12: =IFERROR(I12*F12+J12*$J$5*F12,) | L12: =IFERROR(K12/$K$8,) | M12: =IFERROR(K12-G12*F12-H12*$J$5*F12,) | N12: =IFERROR(M12/(K12-M12),) | O12: 국내금융배당
A13: DC | B13: 5 | C13: 한국 | D13: 472170 | E13: TIGER 미국테크TOP10채권혼합 | F13: 1971 | G13: 14081 | I13: 13750 | K13: =IFERROR(I13*F13+J13*$J$5*F13,) | L13: =IFERROR(K13/$K$8,) | M13: =IFERROR(K13-G13*F13-H13*$J$5*F13,) | N13: =IFERROR(M13/(K13-M13),) | O13: 테크채권
A14: DC | B14: 6 | C14: 한국 | D14: 468380 | E14: KODEX iShares미국하이일드액티브 | F14: 2000 | G14: 11685 | I14: 10965 | K14: =IFERROR(I14*F14+J14*$J$5*F14,) | L14: =IFERROR(K14/$K$8,) | M14: =IFERROR(K14-G14*F14-H14*$J$5*F14,) | N14: =IFERROR(M14/(K14-M14),) | O14: 달러
A15: DC | B15: 7 | C15: 한국 | D15: 481060 | E15: KODEX 미국30년국채타겟커버드콜(H) | F15: 3060 | G15: 8675 | I15: 7420 | K15: =IFERROR(I15*F15+J15*$J$5*F15,) | L15: =IFERROR(K15/$K$8,) | M15: =IFERROR(K15-G15*F15-H15*$J$5*F15,) | N15: =IFERROR(M15/(K15-M15),) | O15: 미국채커
A16: DC | B16: 8 | C16: 한국 | D16: 329200 | E16: TIGER리츠부동산인프라 | F16: 5000 | G16: 4395 | I16: 4110 | K16: =IFERROR(I16*F16+J16*$J$5*F16,) | L16: =IFERROR(K16/$K$8,) | M16: =IFERROR(K16-G16*F16-H16*$J$5*F16,) | N16: =IFERROR(M16/(K16-M16),) | O16: 국내리츠
A17: DC | B17: 9 | C17: 한국 | D17: 379810 | E17: KODEX 미국나스닥100 | F17: 386 | G17: 27067 | I17: 26570 | K17: =IFERROR(I17*F17+J17*$J$5*F17,) | L17: =IFERROR(K17/$K$8,) | M17: =IFERROR(K17-G17*F17-H17*$J$5*F17,) | N17: =IFERROR(M17/(K17-M17),) | O17: 나스닥
A18: 개인연금1 | B18: 10 | C18: 한국 | D18: 474220 | E18: TIGER미국테크TOP10커버드콜 | F18: 3260 | G18: 10680 | I18: 14665 | K18: =IFERROR(I18*F18+J18*$J$5*F18,) | L18: =IFERROR(K18/$K$8,) | M18: =IFERROR(K18-G18*F18-H18*$J$5*F18,) | N18: =IFERROR(M18/(K18-M18),) | O18: 테커
A19: 개인연금1 | B19: 11 | C19: 한국 | D19: 458760 | E19: TIGER 미배당다우커버드콜2호 | F19: 4055 | G19: 10101 | I19: 11285 | K19: =IFERROR(I19*F19+J19*$J$5*F19,) | L19: =IFERROR(K19/$K$8,) | M19: =IFERROR(K19-G19*F19-H19*$J$5*F19,) | N19: =IFERROR(M19/(K19-M19),) | O19: 다우커
A20: 개인연금1 | B20: 12 | C20: 한국 | D20: 446720 | E20: SOL 미국배당다우존스 | F20: 1330 | G20: 10517 | I20: 14085 | K20: =IFERROR(I20*F20+J20*$J$5*F20,) | L20: =IFERROR(K20/$K$8,) | M20: =IFERROR(K20-G20*F20-H20*$J$5*F20,) | N20: =IFERROR(M20/(K20-M20),) | O20: 다우
... A24: 개인연금2 | B24: 16 | C24: 한국 | D24: 360750 | E24: TIGER미국S&P500 | F24: 219 | G24: 25492 | I24: 26202 | K24: =IFERROR(I24*F24+J24*$J$5*F24,) | L24: =IFERROR(K24/$K$8,) | M24: =IFERROR(K24-G24*F24-H24*$J$5*F24,) | N24: =IFERROR(M24/(K24-M24),) | O24: 슨피
A25: ISA | B25: 17 | C25: 한국 | D25: 483280 | E25: KODEX 미국AI테크TOP10타겟커버드콜 | F25: 2226 | G25: 10928 | I25: 11490 | K25: =IFERROR(I25*F25+J25*$J$5*F25,) | L25: =IFERROR(K25/$K$8,) | M25: =IFERROR(K25-G25*F25-H25*$J$5*F25,) | N25: =IFERROR(M25/(K25-M25),)
A26: ISA | B26: 18 | C26: 한국 | D26: 458760 | E26: TIGER 미배당다우커버드콜2호 | F26: 1939 | G26: 9901 | I26: 11285 | K26: =IFERROR(I26*F26+J26*$J$5*F26,) | L26: =IFERROR(K26/$K$8,) | M26: =IFERROR(K26-G26*F26-H26*$J$5*F26,) | N26: =IFERROR(M26/(K26-M26),) | O26: 다우커
A27: ISA | B27: 19 | C27: 한국 | D27: 474220 | E27: TIGER미국테크TOP10커버드콜 | F27: 1300 | G27: 11901 | I27: 14665 | K27: =IFERROR(I27*F27+J27*$J$5*F27,) | L27: =IFERROR(K27/$K$8,) | M27: =IFERROR(K27-G27*F27-H27*$J$5*F27,) | N27: =IFERROR(M27/(K27-M27),) | O27: 테커
A28: ISA | B28: 20 | C28: 한국 | D28: 457480 | E28: ACE테슬라밸류체인액티브 | F28: 505 | G28: 16714 | I28: 18965 | K28: =IFERROR(I28*F28+J28*$J$5*F28,) | L28: =IFERROR(K28/$K$8,) | M28: =IFERROR(K28-G28*F28-H28*$J$5*F28,) | N28: =IFERROR(M28/(K28-M28),) | O28: 테슬라
A29: ISA | B29: 21 | C29: 한국 | D29: 473330 | E29: SOL 미국 30년국채커버드콜(합성) | F29: 960 | G29: 9360 | I29: 8010 | K29: =IFERROR(I29*F29+J29*$J$5*F29,) | L29: =IFERROR(K29/$K$8,) | M29: =IFERROR(K29-G29*F29-H29*$J$5*F29,) | N29: =IFERROR(M29/(K29-M29),) | O29: 미국채커
A30: ISA | B30: 22 | C30: 한국 | D30: 000270 | E30: 기아 | F30: 34 | G30: 110746 | I30: 130700 | K30: =IFERROR(I30*F30+J30*$J$5*F30,) | L30: =IFERROR(K30/$K$8,) | M30: =IFERROR(K30-G30*F30-H30*$J$5*F30,) | N30: =IFERROR(M30/(K30-M30),) | O30: 기아
A31: ISA | B31: 23 | C31: 한국 | D31: 498270 | E31: KIWOOM 미국양자컴퓨팅 | F31: 297 | G31: 12814 | I31: 14805 | K31: =IFERROR(I31*F31+J31*$J$5*F31,) | L31: =IFERROR(K31/$K$8,) | M31: =IFERROR(K31-G31*F31-H31*$J$5*F31,) | N31: =IFERROR(M31/(K31-M31),) | O31: 양자
A32: ISA | B32: 24 | C32: 한국 | D32: 476550 | E32: TIGER 미국30년국채커버드콜액티브(H) | F32: 431 | G32: 9583 | I32: 6840 | K32: =IFERROR(I32*F32+J32*$J$5*F32,) | L32: =IFERROR(K32/$K$8,) | M32: =IFERROR(K32-G32*F32-H32*$J$5*F32,) | N32: =IFERROR(M32/(K32-M32),) | O32: 미국채커
A33: ISA | B33: 25 | C33: 한국 | D33: 0072R0 | E33: TIGER KRX금현물 | F33: 210 | G33: 14544 | I33: 13815 | K33: =IFERROR(I33*F33+J33*$J$5*F33,) | L33: =IFERROR(K33/$K$8,) | M33: =IFERROR(K33-G33*F33-H33*$J$5*F33,) | N33: =IFERROR(M33/(K33-M33),) | O33: 금
A34: ISA | B34: 26 | C34: 한국 | D34: 005389 | E34: 현대차3우B | F34: 13 | G34: 160810 | I34: 190700 | K34: =IFERROR(I34*F34+J34*$J$5*F34,) | L34: =IFERROR(K34/$K$8,) | M34: =IFERROR(K34-G34*F34-H34*$J$5*F34,) | N34: =IFERROR(M34/(K34-M34),) | O34: 현대차
A35: ISA | B35: 27 | C35: 한국 | D35: 364980 | E35: TIGER 2차전지TOP10 | F35: 176 | G35: 8477 | I35: 10190 | K35: =IFERROR(I35*F35+J35*$J$5*F35,) | L35: =IFERROR(K35/$K$8,) | M35: =IFERROR(K35-G35*F35-H35*$J$5*F35,) | N35: =IFERROR(M35/(K35-M35),) | O35: 이차전지
A36: ISA | B36: 28 | C36: 한국 | D36: 476690 | E36: TIGER 글로벌비만치료제 TOP2 Plus | F36: 100 | G36: 9378 | I36: 11090 | K36: =IFERROR(I36*F36+J36*$J$5*F36,) | L36: =IFERROR(K36/$K$8,) | M36: =IFERROR(K36-G36*F36-H36*$J$5*F36,) | N36: =IFERROR(M36/(K36-M36),) | O36: 헬스
A37: ISA | B37: 29 | C37: 한국 | D37: 475380 | E37: RISE 글로벌리얼티인컴 | F37: 101 | G37: 9891 | I37: 10435 | K37: =IFERROR(I37*F37+J37*$J$5*F37,) | L37: =IFERROR(K37/$K$8,) | M37: =IFERROR(K37-G37*F37-H37*$J$5*F37,) | N37: =IFERROR(M37/(K37-M37),) | O37: 리츠
... A40: 일반계좌 | B40: 32 | C40: 한국 | D40: 498400 | E40: KODEX 200타켓위클리커버드콜 | F40: 611 | G40: 21321 | I40: 20025 | K40: =IFERROR(I40*F40+J40*$J$5*F40,) | L40: =IFERROR(K40/$K$8,) | M40: =IFERROR(K40-G40*F40-H40*$J$5*F40,) | N40: =IFERROR(M40/(K40-M40),) | O40: 헬스
A41: 일반계좌 | B41: 33 | C41: 미국 | D41: TSLA | E41: 테슬라 | F41: 17 | H41: 280.9963 | J41: 362.85999 | K41: =IFERROR(I41*F41+J41*$J$5*F41,) | L41: =IFERROR(K41/$K$8,) | M41: =IFERROR(K41-G41*F41-H41*$J$5*F41,) | N41: =IFERROR(M41/(K41-M41),) | O41: 테슬라
A42: 일반계좌 | B42: 34 | C42: 미국 | D42: O | E42: 리얼티인컴 | F42: 53 | H42: 53.53 | J42: 62.599998 | K42: =IFERROR(I42*F42+J42*$J$5*F42,) | L42: =IFERROR(K42/$K$8,) | M42: =IFERROR(K42-G42*F42-H42*$J$5*F42,) | N42: =IFERROR(M42/(K42-M42),) | O42: 미국리츠
A43: 일반계좌 | B43: 35 | C43: 미국 | D43: IONQ | E43: 아이온큐 | F43: 91 | H43: 29.68 | J43: 44.860001 | K43: =IFERROR(I43*F43+J43*$J$5*F43,) | L43: =IFERROR(K43/$K$8,) | M43: =IFERROR(K43-G43*F43-H43*$J$5*F43,) | N43: =IFERROR(M43/(K43-M43),) | O43: 양자
A44: 일반계좌 | B44: 36 | C44: 미국 | D44: AAPL | E44: 애플 | F44: 9 | H44: 208.16 | J44: 309.35001 | K44: =IFERROR(I44*F44+J44*$J$5*F44,) | L44: =IFERROR(K44/$K$8,) | M44: =IFERROR(K44-G44*F44-H44*$J$5*F44,) | N44: =IFERROR(M44/(K44-M44),) | O44: 애플
A45: 일반계좌 | B45: 37 | C45: 한국 | D45: 024110 | E45: 기업은행 | F45: 179 | G45: 21932 | I45: 20200 | K45: =IFERROR(I45*F45+J45*$J$5*F45,) | L45: =IFERROR(K45/$K$8,) | M45: =IFERROR(K45-G45*F45-H45*$J$5*F45,) | N45: =IFERROR(M45/(K45-M45),) | O45: 기업은행
A46: 일반계좌 | B46: 38 | C46: 한국 | D46: 352820 | E46: 하이브 | F46: 18 | G46: 222701 | I46: 174400 | K46: =IFERROR(I46*F46+J46*$J$5*F46,) | L46: =IFERROR(K46/$K$8,) | M46: =IFERROR(K46-G46*F46-H46*$J$5*F46,) | N46: =IFERROR(M46/(K46-M46),) | O46: 엔터
A47: 일반계좌 | B47: 39 | C47: 미국 | D47: QLD | E47: QLD | F47: 43 | H47: 87.3673 | J47: 89.529999 | K47: =IFERROR(I47*F47+J47*$J$5*F47,) | L47: =IFERROR(K47/$K$8,) | M47: =IFERROR(K47-G47*F47-H47*$J$5*F47,) | N47: =IFERROR(M47/(K47-M47),) | O47: 나스닥
A48: 일반계좌 | B48: 40 | C48: 한국 | D48: 105560 | E48: KB금융 | F48: 12 | G48: 173127 | I48: 162700 | K48: =IFERROR(I48*F48+J48*$J$5*F48,) | L48: =IFERROR(K48/$K$8,) | M48: =IFERROR(K48-G48*F48-H48*$J$5*F48,) | N48: =IFERROR(M48/(K48-M48),) | O48: KB금융
...

Sheet 금액순
A1: 금액순 · 포트폴리오 비중 100% (계좌현황 자동연동)
A2: 왼쪽 '계좌현황' 시트의 평가액(K열)·계좌(A열)을 수식으로 참조합니다. 왼쪽을 수정·정렬하면 이 탭 수치가 함께 바뀝니다. (Google 스프레드시트 / Excel 365 권장)
A3: 총 평가액 | B3: =SUM('계좌현황'!K9:K84) | C3: 종목수 | D3: =COUNTA('계좌현황'!E9:E84)
A5: ① 계좌별 합계 (왼쪽 자동집계)
A6: 계좌 | B6: 평가액 | C6: 비중 | D6: 종목수
A7: DC | B7: =SUMIF('계좌현황'!A:A,A7,'계좌현황'!K:K) | C7: =IF($B$3=0,0,B7/$B$3) | D7: =COUNTIF('계좌현황'!A9:A84,A7)
A8: 개인연금1 | B8: =SUMIF('계좌현황'!A:A,A8,'계좌현황'!K:K) | C8: =IF($B$3=0,0,B8/$B$3) | D8: =COUNTIF('계좌현황'!A9:A84,A8)
A9: 개인연금2 | B9: =SUMIF('계좌현황'!A:A,A9,'계좌현황'!K:K) | C9: =IF($B$3=0,0,B9/$B$3) | D9: =COUNTIF('계좌현황'!A9:A84,A9)
A10: ISA | B10: =SUMIF('계좌현황'!A:A,A10,'계좌현황'!K:K) | C10: =IF($B$3=0,0,B10/$B$3) | D10: =COUNTIF('계좌현황'!A9:A84,A10)
A11: 일반계좌 | B11: =SUMIF('계좌현황'!A:A,A11,'계좌현황'!K:K) | C11: =IF($B$3=0,0,B11/$B$3) | D11: =COUNTIF('계좌현황'!A9:A84,A11)
A12: CMA | B12: =SUMIF('계좌현황'!A:A,A12,'계좌현황'!K:K) | C12: =IF($B$3=0,0,B12/$B$3) | D12: =COUNTIF('계좌현황'!A9:A84,A12)
A13: IRP | B13: =SUMIF('계좌현황'!A:A,A13,'계좌현황'!K:K) | C13: =IF($B$3=0,0,B13/$B$3) | D13: =COUNTIF('계좌현황'!A9:A84,A13)
A14: 은행예금 | B14: =SUMIF('계좌현황'!A:A,A14,'계좌현황'!K:K) | C14: =IF($B$3=0,0,B14/$B$3) | D14: =COUNTIF('계좌현황'!A9:A84,A14)
A15: TOSS | B15: =SUMIF('계좌현황'!A:A,A15,'계좌현황'!K:K) | C15: =IF($B$3=0,0,B15/$B$3) | D15: =COUNTIF('계좌현황'!A9:A84,A15)
A18: ② 전체 종목 금액 내림차순 100% (왼쪽 K열 기준 자동정렬) | L18: ← 자동계산용(원본행/미러)
A19: 순위 | B19: 계좌 | C19: 국가 | D19: 종목코드 | E19: 종목명 | F19: 수량 | G19: 평가액 | H19: 비중 | I19: 누적비중 | L19: 원본행 | M19: 평가액미러 | N19: 정렬키
A20: 1 | B20: =IFERROR(INDEX('계좌현황'!A:A,INDEX($L$20:$L$95,MATCH(LARGE($N$20:$N$95,1),$N$20:$N$95,0))),"") | C20: =IFERROR(INDEX('계좌현황'!C:C,INDEX($L$20:$L$95,MATCH(LARGE($N$20:$N$95,1),$N$20:$N$95,0))),"") | D20: =IFERROR(INDEX('계좌현황'!D:D,INDEX($L$20:$L$95,MATCH(LARGE($N$20:$N$95,1),$N$20:$N$95,0))),"") | E20: =IFERROR(INDEX('계좌현황'!E:E,INDEX($L$20:$L$95,MATCH(LARGE($N$20:$N$95,1),$N$20:$N$95,0))),"") | F20: =IFERROR(INDEX('계좌현황'!F:F,INDEX($L$20:$L$95,MATCH(LARGE($N$20:$N$95,1),$N$20:$N$95,0))),"") | G20: =IFERROR(INDEX('계좌현황'!K:K,INDEX($L$20:$L$95,MATCH(LARGE($N$20:$N$95,1),$N$20:$N$95,0))),0) | H20: =IF($B$3=0,0,G20/$B$3) | I20: =H20 | L20: 9 | M20: ='계좌현황'!K9 | N20: =IF(M20="",-1E99,M20*100000+(10000-L20))
A21: 2 | B21: =IFERROR(INDEX('계좌현황'!A:A,INDEX($L$20:$L$95,MATCH(LARGE($N$20:$N$95,2),$N$20:$N$95,0))),"") | C21: =IFERROR(INDEX('계좌현황'!C:C,INDEX($L$20:$L$95,MATCH(LARGE($N$20:$N$95,2),$N$20:$N$95,0))),"") | D21: =IFERROR(INDEX('계좌현황'!D:D,INDEX($L$20:$L$95,MATCH(LARGE($N$20:$N$95,2),$N$20:$N$95,0))),"") | E21: =IFERROR(INDEX('계좌현황'!E:E,INDEX($L$20:$L$95,MATCH(LARGE($N$20:$N$95,2),$N$20:$N$95,0))),"") | F21: =IFERROR(INDEX('계좌현황'!F:F,INDEX($L$20:$L$95,MATCH(LARGE($N$20:$N$95,2),$N$20:$N$95,0))),"") | G21: =IFERROR(INDEX('계좌현황'!K:K,INDEX($L$20:$L$95,MATCH(LARGE($N$20:$N$95,2),$N$20:$N$95,0))),0) | H21: =IF($B$3=0,0,G21/$B$3) | I21: =I20+H21 | L21: 10 | M21: ='계좌현황'!K10 | N21: =IF(M21="",-1E99,M21*100000+(10000-L21))
A22: 3 | B22: =IFERROR(INDEX('계좌현황'!A:A,INDEX($L$20:$L$95,MATCH(LARGE($N$20:$N$95,3),$N$20:$N$95,0))),"") | C22: =IFERROR(INDEX('계좌현황'!C:C,INDEX($L$20:$L$95,MATCH(LARGE($N$20:$N$95,3),$N$20:$N$95,0))),"") | D22: =IFERROR(INDEX('계좌현황'!D:D,INDEX($L$20:$L$95,MATCH(LARGE($N$20:$N$95,3),$N$20:$N$95,0))),"") | E22: =IFERROR(INDEX('계좌현황'!E:E,INDEX($L$20:$L$95,MATCH(LARGE($N$20:$N$95,3),$N$20:$N$95,0))),"") | F22: =IFERROR(INDEX('계좌현황'!F:F,INDEX($L$20:$L$95,MATCH(LARGE($N$20:$N$95,3),$N$20:$N$95,0))),"") | G22: =IFERROR(INDEX('계좌현황'!K:K,INDEX($L$20:$L$95,MATCH(LARGE($N$20:$N$95,3),$N$20:$N$95,0))),0) | H22: =IF($B$3=0,0,G22/$B$3) | I22: =I21+H22 | L22: 11 | M22: ='계좌현황'!K11 | N22: =IF(M22="",-1E99,M22*100000+(10000-L22))
A23: 4 | B23: =IFERROR(INDEX('계좌현황'!A:A,INDEX($L$20:$L$95,MATCH(LARGE($N$20:$N$95,4),$N$20:$N$95,0))),"") | C23: =IFERROR(INDEX('계좌현황'!C:C,INDEX($L$20:$L$95,MATCH(LARGE($N$20:$N$95,4),$N$20:$N$95,0))),"") | D23: =IFERROR(INDEX('계좌현황'!D:D,INDEX($L$20:$L$95,MATCH(LARGE($N$20:$N$95,4),$N$20:$N$95,0))),"") | E23: =IFERROR(INDEX('계좌현황'!E:E,INDEX($L$20:$L$95,MATCH(LARGE($N$20:$N$95,4),$N$20:$N$95,0))),"") | F23: =IFERROR(INDEX('계좌현황'!F:F,INDEX($L$20:$L$95,MATCH(LARGE($N$20:$N$95,4),$N$20:$N$95,0))),"") | G23: =IFERROR(INDEX('계좌현황'!K:K,INDEX($L$20:$L$95,MATCH(LARGE($N$20:$N$95,4),$N$20:$N$95,0))),0) | H23: =IF($B$3=0,0,G23/$B$3) | I23: =I22+H23 | L23: 12 | M23: ='계좌현황'!K12 | N23: =IF(M23="",-1E99,M23*100000+(10000-L23))
A24: 5 | B24: =IFERROR(INDEX('계좌현황'!A:A,INDEX($L$20:$L$95,MATCH(LARGE($N$20:$N$95,5),$N$20:$N$95,0))),"") | C24: =IFERROR(INDEX('계좌현황'!C:C,INDEX($L$20:$L$95,MATCH(LARGE($N$20:$N$95,5),$N$20:$N$95,0))),"") | D24: =IFERROR(INDEX('계좌현황'!D:D,INDEX($L$20:$L$95,MATCH(LARGE($N$20:$N$95,5),$N$20:$N$95,0))),"") | E24: =IFERROR(INDEX('계좌현황'!E:E,INDEX($L$20:$L$95,MATCH(LARGE($N$20:$N$95,5),$N$20:$N$95,0))),"") | F24: =IFERROR(INDEX('계좌현황'!F:F,INDEX($L$20:$L$95,MATCH(LARGE($N$20:$N$95,5),$N$20:$N$95,0))),"") | G24: =IFERROR(INDEX('계좌현황'!K:K,INDEX($L$20:$L$95,MATCH(LARGE($N$20:$N$95,5),$N$20:$N$95,0))),0) | H24: =IF($B$3=0,0,G24/$B$3) | I24: =I23+H24 | L24: 13 | M24: ='계좌현황'!K13 | N24: =IF(M24="",-1E99,M24*100000+(10000-L24))
A25: 6 | B25: =IFERROR(INDEX('계좌현황'!A:A,INDEX($L$20:$L$95,MATCH(LARGE($N$20:$N$95,6),$N$20:$N$95,0))),"") | C25: =IFERROR(INDEX('계좌현황'!C:C,INDEX($L$20:$L$95,MATCH(LARGE($N$20:$N$95,6),$N$20:$N$95,0))),"") | D25: =IFERROR(INDEX('계좌현황'!D:D,INDEX($L$20:$L$95,MATCH(LARGE($N$20:$N$95,6),$N$20:$N$95,0))),"") | E25: =IFERROR(INDEX('계좌현황'!E:E,INDEX($L$20:$L$95,MATCH(LARGE($N$20:$N$95,6),$N$20:$N$95,0))),"") | F25: =IFERROR(INDEX('계좌현황'!F:F,INDEX($L$20:$L$95,MATCH(LARGE($N$20:$N$95,6),$N$20:$N$95,0))),"") | G25: =IFERROR(INDEX('계좌현황'!K:K,INDEX($L$20:$L$95,MATCH(LARGE($N$20:$N$95,6),$N$20:$N$95,0))),0) | H25: =IF($B$3=0,0,G25/$B$3) | I25: =I24+H25 | L25: 14 | M25: ='계좌현황'!K14 | N25: =IF(M25="",-1E99,M25*100000+(10000-L25))
A26: 7 | B26: =IFERROR(INDEX('계좌현황'!A:A,INDEX($L$20:$L$95,MATCH(LARGE($N$20:$N$95,7),$N$20:$N$95,0))),"") | C26: =IFERROR(INDEX('계좌현황'!C:C,INDEX($L$20:$L$95,MATCH(LARGE($N$20:$N$95,7),$N$20:$N$95,0))),"") | D26: =IFERROR(INDEX('계좌현황'!D:D,INDEX($L$20:$L$95,MATCH(LARGE($N$20:$N$95,7),$N$20:$N$95,0))),"") | E26: =IFERROR(INDEX('계좌현황'!E:E,INDEX($L$20:$L$95,MATCH(LARGE($N$20:$N$95,7),$N$20:$N$95,0))),"") | F26: =IFERROR(INDEX('계좌현황'!F:F,INDEX($L$20:$L$95,MATCH(LARGE($N$20:$N$95,7),$N$20:$N$95,0))),"") | G26: =IFERROR(INDEX('계좌현황'!K:K,INDEX($L$20:$L$95,MATCH(LARGE($N$20:$N$95,7),$N$20:$N$95,0))),0) | H26: =IF($B$3=0,0,G26/$B$3) | I26: =I25+H26 | L26: 15 | M26: ='계좌현황'!K15 | N26: =IF(M26="",-1E99,M26*100000+(10000-L26))
A27: 8 | B27: =IFERROR(INDEX('계좌현황'!A:A,INDEX($L$20:$L$95,MATCH(LARGE($N$20:$N$95,8),$N$20:$N$95,0))),"") | C27: =IFERROR(INDEX('계좌현황'!C:C,INDEX($L$20:$L$95,MATCH(LARGE($N$20:$N$95,8),$N$20:$N$95,0))),"") | D27: =IFERROR(INDEX('계좌현황'!D:D,INDEX($L$20:$L$95,MATCH(LARGE($N$20:$N$95,8),$N$20:$N$95,0))),"") | E27: =IFERROR(INDEX('계좌현황'!E:E,INDEX($L$20:$L$95,MATCH(LARGE($N$20:$N$95,8),$N$20:$N$95,0))),"") | F27: =IFERROR(INDEX('계좌현황'!F:F,INDEX($L$20:$L$95,MATCH(LARGE($N$20:$N$95,8),$N$20:$N$95,0))),"") | G27: =IFERROR(INDEX('계좌현황'!K:K,INDEX($L$20:$L$95,MATCH(LARGE($N$20:$N$95,8),$N$20:$N$95,0))),0) | H27: =IF($B$3=0,0,G27/$B$3) | I27: =I26+H27 | L27: 16 | M27: ='계좌현황'!K16 | N27: =IF(M27="",-1E99,M27*100000+(10000-L27))
A28: 9 | B28: =IFERROR(INDEX('계좌현황'!A:A,INDEX($L$20:$L$95,MATCH(LARGE($N$20:$N$95,9),$N$20:$N$95,0))),"") | C28: =IFERROR(INDEX('계좌현황'!C:C,INDEX($L$20:$L$95,MATCH(LARGE($N$20:$N$95,9),$N$20:$N$95,0))),"") | D28: =IFERROR(INDEX('계좌현황'!D:D,INDEX($L$20:$L$95,MATCH(LARGE($N$20:$N$95,9),$N$20:$N$95,0))),"") | E28: =IFERROR(INDEX('계좌현황'!E:E,INDEX($L$20:$L$95,MATCH(LARGE($N$20:$N$95,9),$N$20:$N$95,0))),"") | F28: =IFERROR(INDEX('계좌현황'!F:F,INDEX($L$20:$L$95,MATCH(LARGE($N$20:$N$95,9),$N$20:$N$95,0))),"") | G28: =IFERROR(INDEX('계좌현황'!K:K,INDEX($L$20:$L$95,MATCH(LARGE($N$20:$N$95,9),$N$20:$N$95,0))),0) | H28: =IF($B$3=0,0,G28/$B$3) | I28: =I27+H28 | L28: 17 | M28: ='계좌현황'!K17 | N28: =IF(M28="",-1E99,M28*100000+(10000-L28))
A29: 10 | B29: =IFERROR(INDEX('계좌현황'!A:A,INDEX($L$20:$L$95,MATCH(LARGE($N$20:$N$95,10),$N$20:$N$95,0))),"") | C29: =IFERROR(INDEX('계좌현황'!C:C,INDEX($L$20:$L$95,MATCH(LARGE($N$20:$N$95,10),$N$20:$N$95,0))),"") | D29: =IFERROR(INDEX('계좌현황'!D:D,INDEX($L$20:$L$95,MATCH(LARGE($N$20:$N$95,10),$N$20:$N$95,0))),"") | E29: =IFERROR(INDEX('계좌현황'!E:E,INDEX($L$20:$L$95,MATCH(LARGE($N$20:$N$95,10),$N$20:$N$95,0))),"") | F29: =IFERROR(INDEX('계좌현황'!F:F,INDEX($L$20:$L$95,MATCH(LARGE($N$20:$N$95,10),$N$20:$N$95,0))),"") | G29: =IFERROR(INDEX('계좌현황'!K:K,INDEX($L$20:$L$95,MATCH(LARGE($N$20:$N$95,10),$N$20:$N$95,0))),0) | H29: =IF($B$3=0,0,G29/$B$3) | I29: =I28+H29 | L29: 18 | M29: ='계좌현황'!K18 | N29: =IF(M29="",-1E99,M29*100000+(10000-L29))
A30: 11 | B30: =IFERROR(INDEX('계좌현황'!A:A,INDEX($L$20:$L$95,MATCH(LARGE($N$20:$N$95,11),$N$20:$N$95,0))),"") | C30: =IFERROR(INDEX('계좌현황'!C:C,INDEX($L$20:$L$95,MATCH(LARGE($N$20:$N$95,11),$N$20:$N$95,0))),"") | D30: =IFERROR(INDEX('계좌현황'!D:D,INDEX($L$20:$L$95,MATCH(LARGE($N$20:$N$95,11),$N$20:$N$95,0))),"") | E30: =IFERROR(INDEX('계좌현황'!E:E,INDEX($L$20:$L$95,MATCH(LARGE($N$20:$N$95,11),$N$20:$N$95,0))),"") | F30: =IFERROR(INDEX('계좌현황'!F:F,INDEX($L$20:$L$95,MATCH(LARGE($N$20:$N$95,11),$N$20:$N$95,0))),"") | G30: =IFERROR(INDEX('계좌현황'!K:K,INDEX($L$20:$L$95,MATCH(LARGE($N$20:$N$95,11),$N$20:$N$95,0))),0) | H30: =IF($B$3=0,0,G30/$B$3) | I30: =I29+H30 | L30: 19 | M30: ='계좌현황'!K19 | N30: =IF(M30="",-1E99,M30*100000+(10000-L30))
A31: 12 | B31: =IFERROR(INDEX('계좌현황'!A:A,INDEX($L$20:$L$95,MATCH(LARGE($N$20:$N$95,12),$N$20:$N$95,0))),"") | C31: =IFERROR(INDEX('계좌현황'!C:C,INDEX($L$20:$L$95,MATCH(LARGE($N$20:$N$95,12),$N$20:$N$95,0))),"") | D31: =IFERROR(INDEX('계좌현황'!D:D,INDEX($L$20:$L$95,MATCH(LARGE($N$20:$N$95,12),$N$20:$N$95,0))),"") | E31: =IFERROR(INDEX('계좌현황'!E:E,INDEX($L$20:$L$95,MATCH(LARGE($N$20:$N$95,12),$N$20:$N$95,0))),"") | F31: =IFERROR(INDEX('계좌현황'!F:F,INDEX($L$20:$L$95,MATCH(LARGE($N$20:$N$95,12),$N$20:$N$95,0))),"") | G31: =IFERROR(INDEX('계좌현황'!K:K,INDEX($L$20:$L$95,MATCH(LARGE($N$20:$N$95,12),$N$20:$N$95,0))),0) | H31: =IF($B$3=0,0,G31/$B$3) | I31: =I30+H31 | L31: 20 | M31: ='계좌현황'!K20 | N31: =IF(M31="",-1E99,M31*100000+(10000-L31))
A32: 13 | B32: =IFERROR(INDEX('계좌현황'!A:A,INDEX($L$20:$L$95,MATCH(LARGE($N$20:$N$95,13),$N$20:$N$95,0))),"") | C32: =IFERROR(INDEX('계좌현황'!C:C,INDEX($L$20:$L$95,MATCH(LARGE($N$20:$N$95,13),$N$20:$N$95,0))),"") | D32: =IFERROR(INDEX('계좌현황'!D:D,INDEX($L$20:$L$95,MATCH(LARGE($N$20:$N$95,13),$N$20:$N$95,0))),"") | E32: =IFERROR(INDEX('계좌현황'!E:E,INDEX($L$20:$L$95,MATCH(LARGE($N$20:$N$95,13),$N$20:$N$95,0))),"") | F32: =IFERROR(INDEX('계좌현황'!F:F,INDEX($L$20:$L$95,MATCH(LARGE($N$20:$N$95,13),$N$20:$N$95,0))),"") | G32: =IFERROR(INDEX('계좌현황'!K:K,INDEX($L$20:$L$95,MATCH(LARGE($N$20:$N$95,13),$N$20:$N$95,0))),0) | H32: =IF($B$3=0,0,G32/$B$3) | I32: =I31+H32 | L32: 21 | M32: ='계좌현황'!K21 | N32: =IF(M32="",-1E99,M32*100000+(10000-L32))
A33: 14 | B33: =IFERROR(INDEX('계좌현황'!A:A,INDEX($L$20:$L$95,MATCH(LARGE($N$20:$N$95,14),$N$20:$N$95,0))),"") | C33: =IFERROR(INDEX('계좌현황'!C:C,INDEX($L$20:$L$95,MATCH(LARGE($N$20:$N$95,14),$N$20:$N$95,0))),"") | D33: =IFERROR(INDEX('계좌현황'!D:D,INDEX($L$20:$L$95,MATCH(LARGE($N$20:$N$95,14),$N$20:$N$95,0))),"") | E33: =IFERROR(INDEX('계좌현황'!E:E,INDEX($L$20:$L$95,MATCH(LARGE($N$20:$N$95,14),$N$20:$N$95,0))),"") | F33: =IFERROR(INDEX('계좌현황'!F:F,INDEX($L$20:$L$95,MATCH(LARGE($N$20:$N$95,14),$N$20:$N$95,0))),"") | G33: =IFERROR(INDEX('계좌현황'!K:K,INDEX($L$20:$L$95,MATCH(LARGE($N$20:$N$95,14),$N$20:$N$95,0))),0) | H33: =IF($B$3=0,0,G33/$B$3) | I33: =I32+H33 | L33: 22 | M33: ='계좌현황'!K22 | N33: =IF(M33="",-1E99,M33*100000+(10000-L33))
A34: 15 | B34: =IFERROR(INDEX('계좌현황'!A:A,INDEX($L$20:$L$95,MATCH(LARGE($N$20:$N$95,15),$N$20:$N$95,0))),"") | C34: =IFERROR(INDEX('계좌현황'!C:C,INDEX($L$20:$L$95,MATCH(LARGE($N$20:$N$95,15),$N$20:$N$95,0))),"") | D34: =IFERROR(INDEX('계좌현황'!D:D,INDEX($L$20:$L$95,MATCH(LARGE($N$20:$N$95,15),$N$20:$N$95,0))),"") | E34: =IFERROR(INDEX('계좌현황'!E:E,INDEX($L$20:$L$95,MATCH(LARGE($N$20:$N$95,15),$N$20:$N$95,0))),"") | F34: =IFERROR(INDEX('계좌현황'!F:F,INDEX($L$20:$L$95,MATCH(LARGE($N$20:$N$95,15),$N$20:$N$95,0))),"") | G34: =IFERROR(INDEX('계좌현황'!K:K,INDEX($L$20:$L$95,MATCH(LARGE($N$20:$N$95,15),$N$20:$N$95,0))),0) | H34: =IF($B$3=0,0,G34/$B$3) | I34: =I33+H34 | L34: 23 | M34: ='계좌현황'!K23 | N34: =IF(M34="",-1E99,M34*100000+(10000-L34))
A35: 16 | B35: =IFERROR(INDEX('계좌현황'!A:A,INDEX($L$20:$L$95,MATCH(LARGE($N$20:$N$95,16),$N$20:$N$95,0))),"") | C35: =IFERROR(INDEX('계좌현황'!C:C,INDEX($L$20:$L$95,MATCH(LARGE($N$20:$N$95,16),$N$20:$N$95,0))),"") | D35: =IFERROR(INDEX('계좌현황'!D:D,INDEX($L$20:$L$95,MATCH(LARGE($N$20:$N$95,16),$N$20:$N$95,0))),"") | E35: =IFERROR(INDEX('계좌현황'!E:E,INDEX($L$20:$L$95,MATCH(LARGE($N$20:$N$95,16),$N$20:$N$95,0))),"") | F35: =IFERROR(INDEX('계좌현황'!F:F,INDEX($L$20:$L$95,MATCH(LARGE($N$20:$N$95,16),$N$20:$N$95,0))),"") | G35: =IFERROR(INDEX('계좌현황'!K:K,INDEX($L$20:$L$95,MATCH(LARGE($N$20:$N$95,16),$N$20:$N$95,0))),0) | H35: =IF($B$3=0,0,G35/$B$3) | I35: =I34+H35 | L35: 24 | M35: ='계좌현황'!K24 | N35: =IF(M35="",-1E99,M35*100000+(10000-L35))
A36: 17 | B36: =IFERROR(INDEX('계좌현황'!A:A,INDEX($L$20:$L$95,MATCH(LARGE($N$20:$N$95,17),$N$20:$N$95,0))),"") | C36: =IFERROR(INDEX('계좌현황'!C:C,INDEX($L$20:$L$95,MATCH(LARGE($N$20:$N$95,17),$N$20:$N$95,0))),"") | D36: =IFERROR(INDEX('계좌현황'!D:D,INDEX($L$20:$L$95,MATCH(LARGE($N$20:$N$95,17),$N$20:$N$95,0))),"") | E36: =IFERROR(INDEX('계좌현황'!E:E,INDEX($L$20:$L$95,MATCH(LARGE($N$20:$N$95,17),$N$20:$N$95,0))),"") | F36: =IFERROR(INDEX('계좌현황'!F:F,INDEX($L$20:$L$95,MATCH(LARGE($N$20:$N$95,17),$N$20:$N$95,0))),"") | G36: =IFERROR(INDEX('계좌현황'!K:K,INDEX($L$20:$L$95,MATCH(LARGE($N$20:$N$95,17),$N$20:$N$95,0))),0) | H36: =IF($B$3=0,0,G36/$B$3) | I36: =I35+H36 | L36: 25 | M36: ='계좌현황'!K25 | N36: =IF(M36="",-1E99,M36*100000+(10000-L36))
A37: 18 | B37: =IFERROR(INDEX('계좌현황'!A:A,INDEX($L$20:$L$95,MATCH(LARGE($N$20:$N$95,18),$N$20:$N$95,0))),"") | C37: =IFERROR(INDEX('계좌현황'!C:C,INDEX($L$20:$L$95,MATCH(LARGE($N$20:$N$95,18),$N$20:$N$95,0))),"") | D37: =IFERROR(INDEX('계좌현황'!D:D,INDEX($L$20:$L$95,MATCH(LARGE($N$20:$N$95,18),$N$20:$N$95,0))),"") | E37: =IFERROR(INDEX('계좌현황'!E:E,INDEX($L$20:$L$95,MATCH(LARGE($N$20:$N$95,18),$N$20:$N$95,0))),"") | F37: =IFERROR(INDEX('계좌현황'!F:F,INDEX($L$20:$L$95,MATCH(LARGE($N$20:$N$95,18),$N$20:$N$95,0))),"") | G37: =IFERROR(INDEX('계좌현황'!K:K,INDEX($L$20:$L$95,MATCH(LARGE($N$20:$N$95,18),$N$20:$N$95,0))),0) | H37: =IF($B$3=0,0,G37/$B$3) | I37: =I36+H37 | L37: 26 | M37: ='계좌현황'!K26 | N37: =IF(M37="",-1E99,M37*100000+(10000-L37))
A38: 19 | B38: =IFERROR(INDEX('계좌현황'!A:A,INDEX($L$20:$L$95,MATCH(LARGE($N$20:$N$95,19),$N$20:$N$95,0))),"") | C38: =IFERROR(INDEX('계좌현황'!C:C,INDEX($L$20:$L$95,MATCH(LARGE($N$20:$N$95,19),$N$20:$N$95,0))),"") | D38: =IFERROR(INDEX('계좌현황'!D:D,INDEX($L$20:$L$95,MATCH(LARGE($N$20:$N$95,19),$N$20:$N$95,0))),"") | E38: =IFERROR(INDEX('계좌현황'!E:E,INDEX($L$20:$L$95,MATCH(LARGE($N$20:$N$95,19),$N$20:$N$95,0))),"") | F38: =IFERROR(INDEX('계좌현황'!F:F,INDEX($L$20:$L$95,MATCH(LARGE($N$20:$N$95,19),$N$20:$N$95,0))),"") | G38: =IFERROR(INDEX('계좌현황'!K:K,INDEX($L$20:$L$95,MATCH(LARGE($N$20:$N$95,19),$N$20:$N$95,0))),0) | H38: =IF($B$3=0,0,G38/$B$3) | I38: =I37+H38 | L38: 27 | M38: ='계좌현황'!K27 | N38: =IF(M38="",-1E99,M38*100000+(10000-L38))
A39: 20 | B39: =IFERROR(INDEX('계좌현황'!A:A,INDEX($L$20:$L$95,MATCH(LARGE($N$20:$N$95,20),$N$20:$N$95,0))),"") | C39: =IFERROR(INDEX('계좌현황'!C:C,INDEX($L$20:$L$95,MATCH(LARGE($N$20:$N$95,20),$N$20:$N$95,0))),"") | D39: =IFERROR(INDEX('계좌현황'!D:D,INDEX($L$20:$L$95,MATCH(LARGE($N$20:$N$95,20),$N$20:$N$95,0))),"") | E39: =IFERROR(INDEX('계좌현황'!E:E,INDEX($L$20:$L$95,MATCH(LARGE($N$20:$N$95,20),$N$20:$N$95,0))),"") | F39: =IFERROR(INDEX('계좌현황'!F:F,INDEX($L$20:$L$95,MATCH(LARGE($N$20:$N$95,20),$N$20:$N$95,0))),"") | G39: =IFERROR(INDEX('계좌현황'!K:K,INDEX($L$20:$L$95,MATCH(LARGE($N$20:$N$95,20),$N$20:$N$95,0))),0) | H39: =IF($B$3=0,0,G39/$B$3) | I39: =I38+H39 | L39: 28 | M39: ='계좌현황'!K28 | N39: =IF(M39="",-1E99,M39*100000+(10000-L39))
A40: 21 | B40: =IFERROR(INDEX('계좌현황'!A:A,INDEX($L$20:$L$95,MATCH(LARGE($N$20:$N$95,21),$N$20:$N$95,0))),"") | C40: =IFERROR(INDEX('계좌현황'!C:C,INDEX($L$20:$L$95,MATCH(LARGE($N$20:$N$95,21),$N$20:$N$95,0))),"") | D40: =IFERROR(INDEX('계좌현황'!D:D,INDEX($L$20:$L$95,MATCH(LARGE($N$20:$N$95,21),$N$20:$N$95,0))),"") | E40: =IFERROR(INDEX('계좌현황'!E:E,INDEX($L$20:$L$95,MATCH(LARGE($N$20:$N$95,21),$N$20:$N$95,0))),"") | F40: =IFERROR(INDEX('계좌현황'!F:F,INDEX($L$20:$L$95,MATCH(LARGE($N$20:$N$95,21),$N$20:$N$95,0))),"") | G40: =IFERROR(INDEX('계좌현황'!K:K,INDEX($L$20:$L$95,MATCH(LARGE($N$20:$N$95,21),$N$20:$N$95,0))),0) | H40: =IF($B$3=0,0,G40/$B$3) | I40: =I39+H40 | L40: 29 | M40: ='계좌현황'!K29 | N40: =IF(M40="",-1E99,M40*100000+(10000-L40))
A41: 22 | B41: =IFERROR(INDEX('계좌현황'!A:A,INDEX($L$20:$L$95,MATCH(LARGE($N$20:$N$95,22),$N$20:$N$95,0))),"") | C41: =IFERROR(INDEX('계좌현황'!C:C,INDEX($L$20:$L$95,MATCH(LARGE($N$20:$N$95,22),$N$20:$N$95,0))),"") | D41: =IFERROR(INDEX('계좌현황'!D:D,INDEX($L$20:$L$95,MATCH(LARGE($N$20:$N$95,22),$N$20:$N$95,0))),"") | E41: =IFERROR(INDEX('계좌현황'!E:E,INDEX($L$20:$L$95,MATCH(LARGE($N$20:$N$95,22),$N$20:$N$95,0))),"") | F41: =IFERROR(INDEX('계좌현황'!F:F,INDEX($L$20:$L$95,MATCH(LARGE($N$20:$N$95,22),$N$20:$N$95,0))),"") | G41: =IFERROR(INDEX('계좌현황'!K:K,INDEX($L$20:$L$95,MATCH(LARGE($N$20:$N$95,22),$N$20:$N$95,0))),0) | H41: =IF($B$3=0,0,G41/$B$3) | I41: =I40+H41 | L41: 30 | M41: ='계좌현황'!K30 | N41: =IF(M41="",-1E99,M41*100000+(10000-L41))
A42: 23 | B42: =IFERROR(INDEX('계좌현황'!A:A,INDEX($L$20:$L$95,MATCH(LARGE($N$20:$N$95,23),$N$20:$N$95,0))),"") | C42: =IFERROR(INDEX('계좌현황'!C:C,INDEX($L$20:$L$95,MATCH(LARGE($N$20:$N$95,23),$N$20:$N$95,0))),"") | D42: =IFERROR(INDEX('계좌현황'!D:D,INDEX($L$20:$L$95,MATCH(LARGE($N$20:$N$95,23),$N$20:$N$95,0))),"") | E42: =IFERROR(INDEX('계좌현황'!E:E,INDEX($L$20:$L$95,MATCH(LARGE($N$20:$N$95,23),$N$20:$N$95,0))),"") | F42: =IFERROR(INDEX('계좌현황'!F:F,INDEX($L$20:$L$95,MATCH(LARGE($N$20:$N$95,23),$N$20:$N$95,0))),"") | G42: =IFERROR(INDEX('계좌현황'!K:K,INDEX($L$20:$L$95,MATCH(LARGE($N$20:$N$95,23),$N$20:$N$95,0))),0) | H42: =IF($B$3=0,0,G42/$B$3) | I42: =I41+H42 | L42: 31 | M42: ='계좌현황'!K31 | N42: =IF(M42="",-1E99,M42*100000+(10000-L42))
A43: 24 | B43: =IFERROR(INDEX('계좌현황'!A:A,INDEX($L$20:$L$95,MATCH(LARGE($N$20:$N$95,24),$N$20:$N$95,0))),"") | C43: =IFERROR(INDEX('계좌현황'!C:C,INDEX($L$20:$L$95,MATCH(LARGE($N$20:$N$95,24),$N$20:$N$95,0))),"") | D43: =IFERROR(INDEX('계좌현황'!D:D,INDEX($L$20:$L$95,MATCH(LARGE($N$20:$N$95,24),$N$20:$N$95,0))),"") | E43: =IFERROR(INDEX('계좌현황'!E:E,INDEX($L$20:$L$95,MATCH(LARGE($N$20:$N$95,24),$N$20:$N$95,0))),"") | F43: =IFERROR(INDEX('계좌현황'!F:F,INDEX($L$20:$L$95,MATCH(LARGE($N$20:$N$95,24),$N$20:$N$95,0))),"") | G43: =IFERROR(INDEX('계좌현황'!K:K,INDEX($L$20:$L$95,MATCH(LARGE($N$20:$N$95,24),$N$20:$N$95,0))),0) | H43: =IF($B$3=0,0,G43/$B$3) | I43: =I42+H43 | L43: 32 | M43: ='계좌현황'!K32 | N43: =IF(M43="",-1E99,M43*100000+(10000-L43))
...

Sheet IMPORTXML함수
C24: https://finance.naver.com/item/sise.naver?code=
C25: //html/body/div[3]/div[2]/div[2]/div[1]/div[3]/div[1]/table/tbody/tr[1]/td[1]/strong

Sheet 올해수익률 계산시트
Q2: KOSPI | R2: INDEXSP:.INX | S2: INDEXNASDAQ:.IXIC | U2: GCW00 | V2: BTCusd | W2: USDKRW
G3: 날짜 | H3: 계좌총액 | I3: 코스피 | J3: S&P500 | K3: 나스닥 | L3: 골드(1온스) | M3: 비트코인(달러) | Q3: 코스피 | R3: S&P500 | S3: 나스닥 | U3: 골드(1온스) | V3: 비트코인-달러 | W3: 달러환율 | X3: S&P500 (달러환율) | Y3: 나스닥 (달러환율) | Z3: 골드 (달러환율) | AA3: 비트코인 (달러환율) | AC3: 달러환율 | AD3: S&P500 (달러환율) | AE3: 나스닥 (달러환율) | AF3: 골드 (달러환율) | AG3: 비트코인 (달러환율)
B4: =VALUE(MID(G4,1,2)) | C4: =VALUE(MID(G4,4,2)) | D4: =IF(F4="12월",(E4+1)&VLOOKUP(F4,인덱스!$C:$D,2,0),E4&VLOOKUP(F4,인덱스!$C:$D,2,0)) | E4: ="20"&MID(G4,1,2) | F4: =VLOOKUP(RIGHT(G4,2),인덱스!B:D,2,0) | G4: 17.12 | H4: 0 | I4: 100 | J4: 100 | K4: 100 | L4: 100 | M4: 100 | Q4: =IFERROR(__xludf.DUMMYFUNCTION("iferror(index('지수RAW'!$V$7:$V$12040,MATCH($D4,'지수RAW'!$R$7:$R$12040,0)-1,1),GOOGLEFINANCE(Q$2))"),2467.49) | R4: =IFERROR(__xludf.DUMMYFUNCTION("iferror(index('지수RAW'!$F$7:$F$12040,MATCH($D4,'지수RAW'!$B$7:$B$12040,0)-1,1),GOOGLEFINANCE(R$2))"),2673.61) | S4: =IFERROR(__xludf.DUMMYFUNCTION("iferror(index('지수RAW'!$N$7:$N$12040,MATCH($D4,'지수RAW'!$J$7:$J$12040,0)-1,1),GOOGLEFINANCE(S$2))"),6903.39) | U4: {=IFERROR(INDEX(지수RAW!$AT$7:$AT$12040,MATCH($D4,지수RAW!$AP$7:$AP$12040,0)-1,1),지수RAW!$AU$4)} | V4: =IFERROR(__xludf.DUMMYFUNCTION("iferror(index('지수RAW'!$AL$7:$AL$12040,MATCH($D4,'지수RAW'!$AH$7:$AH$12040,0)-1,1),GOOGLEFINANCE(V$2))"),13880.99) | W4: =IFERROR(__xludf.DUMMYFUNCTION("iferror(index('지수RAW'!$AD$7:$AD$12040,MATCH($D4,'지수RAW'!$Z$7:$Z$12040,0)-1,1),GOOGLEFINANCE(W$2))"),1066.07) | X4: =$W4*R4 | Y4: =$W4*S4 | Z4: =$W4*U4 | AA4: =$W4*V4 | AC4: 100 | AD4: 100 | AE4: 100 | AF4: 100 | AG4: 100
B5: =IF(C4=12,B4+1,B4) | C5: =IF(C4=12,1,C4+1) | D5: =IF(F5="12월",(E5+1)&VLOOKUP(F5,인덱스!$C:$D,2,0),E5&VLOOKUP(F5,인덱스!$C:$D,2,0)) | E5: ="20"&B5 | F5: =C5&"월" | G5: =B5&"."&VLOOKUP(F5,인덱스!$A:$B,2,0) | H5: =IFERROR(VLOOKUP(G5,#REF!,2,0),) | I5: =IF(Q5="","",I4*(Q5/Q4)) | J5: =IF(R5="","",J4*(R5/R4)) | K5: =IF(S5="","",K4*(S5/S4)) | L5: =IF(U5="","",L4*(U5/U4)) | M5: =IF(V5="","",M4*(V5/V4)) | Q5: =IFERROR(__xludf.DUMMYFUNCTION("iferror(index('지수RAW'!$V$7:$V$12040,MATCH($D5,'지수RAW'!$R$7:$R$12040,0)-1,1),GOOGLEFINANCE(Q$2))"),2566.46) | R5: =IFERROR(__xludf.DUMMYFUNCTION("iferror(index('지수RAW'!$F$7:$F$12040,MATCH($D5,'지수RAW'!$B$7:$B$12040,0)-1,1),GOOGLEFINANCE(R$2))"),2823.81) | S5: =IFERROR(__xludf.DUMMYFUNCTION("iferror(index('지수RAW'!$N$7:$N$12040,MATCH($D5,'지수RAW'!$J$7:$J$12040,0)-1,1),GOOGLEFINANCE(S$2))"),7411.48) | U5: {=IFERROR(INDEX(지수RAW!$AT$7:$AT$12040,MATCH($D5,지수RAW!$AP$7:$AP$12040,0)-1,1),지수RAW!$AU$4)} | V5: =IFERROR(__xludf.DUMMYFUNCTION("iferror(index('지수RAW'!$AL$7:$AL$12040,MATCH($D5,'지수RAW'!$AH$7:$AH$12040,0)-1,1),GOOGLEFINANCE(V$2))"),10022.51) | W5: =IFERROR(__xludf.DUMMYFUNCTION("iferror(index('지수RAW'!$AD$7:$AD$12040,MATCH($D5,'지수RAW'!$Z$7:$Z$12040,0)-1,1),GOOGLEFINANCE(W$2))"),1069.02) | X5: =$W5*R5 | Y5: =$W5*S5 | Z5: =$W5*U5 | AA5: =$W5*V5 | AC5: =IF(Q5="","",AC4*(W5/W4)) | AD5: =IF(R5="","",AD4*(X5/X4)) | AE5: =IF(S5="","",AE4*(Y5/Y4)) | AF5: =IF(U5="","",AF4*(Z5/Z4)) | AG5: =IF(V5="","",AG4*(AA5/AA4))
B6: =IF(C5=12,B5+1,B5) | C6: =IF(C5=12,1,C5+1) | D6: =IF(F6="12월",(E6+1)&VLOOKUP(F6,인덱스!$C:$D,2,0),E6&VLOOKUP(F6,인덱스!$C:$D,2,0)) | E6: ="20"&B6 | F6: =C6&"월" | G6: =B6&"."&VLOOKUP(F6,인덱스!$A:$B,2,0) | H6: =IFERROR(VLOOKUP(G6,#REF!,2,0),) | I6: =IF(Q6="","",I5*(Q6/Q5)) | J6: =IF(R6="","",J5*(R6/R5)) | K6: =IF(S6="","",K5*(S6/S5)) | L6: =IF(U6="","",L5*(U6/U5)) | M6: =IF(V6="","",M5*(V6/V5)) | Q6: =IFERROR(__xludf.DUMMYFUNCTION("iferror(index('지수RAW'!$V$7:$V$12040,MATCH($D6,'지수RAW'!$R$7:$R$12040,0)-1,1),GOOGLEFINANCE(Q$2))"),2427.36) | R6: =IFERROR(__xludf.DUMMYFUNCTION("iferror(index('지수RAW'!$F$7:$F$12040,MATCH($D6,'지수RAW'!$B$7:$B$12040,0)-1,1),GOOGLEFINANCE(R$2))"),2713.83) | S6: =IFERROR(__xludf.DUMMYFUNCTION("iferror(index('지수RAW'!$N$7:$N$12040,MATCH($D6,'지수RAW'!$J$7:$J$12040,0)-1,1),GOOGLEFINANCE(S$2))"),7273.01) | U6: {=IFERROR(INDEX(지수RAW!$AT$7:$AT$12040,MATCH($D6,지수RAW!$AP$7:$AP$12040,0)-1,1),지수RAW!$AU$4)} | V6: =IFERROR(__xludf.DUMMYFUNCTION("iferror(index('지수RAW'!$AL$7:$AL$12040,MATCH($D6,'지수RAW'!$AH$7:$AH$12040,0)-1,1),GOOGLEFINANCE(V$2))"),10542.55) | W6: =IFERROR(__xludf.DUMMYFUNCTION("iferror(index('지수RAW'!$AD$7:$AD$12040,MATCH($D6,'지수RAW'!$Z$7:$Z$12040,0)-1,1),GOOGLEFINANCE(W$2))"),1085.35) | X6: =$W6*R6 | Y6: =$W6*S6 | Z6: =$W6*U6 | AA6: =$W6*V6 | AC6: =IF(Q6="","",AC5*(W6/W5)) | AD6: =IF(R6="","",AD5*(X6/X5)) | AE6: =IF(S6="","",AE5*(Y6/Y5)) | AF6: =IF(U6="","",AF5*(Z6/Z5)) | AG6: =IF(V6="","",AG5*(AA6/AA5))
B7: =IF(C6=12,B6+1,B6) | C7: =IF(C6=12,1,C6+1) | D7: =IF(F7="12월",(E7+1)&VLOOKUP(F7,인덱스!$C:$D,2,0),E7&VLOOKUP(F7,인덱스!$C:$D,2,0)) | E7: ="20"&B7 | F7: =C7&"월" | G7: =B7&"."&VLOOKUP(F7,인덱스!$A:$B,2,0) | H7: =IFERROR(VLOOKUP(G7,#REF!,2,0),) | I7: =IF(Q7="","",I6*(Q7/Q6)) | J7: =IF(R7="","",J6*(R7/R6)) | K7: =IF(S7="","",K6*(S7/S6)) | L7: =IF(U7="","",L6*(U7/U6)) | M7: =IF(V7="","",M6*(V7/V6)) | Q7: =IFERROR(__xludf.DUMMYFUNCTION("iferror(index('지수RAW'!$V$7:$V$12040,MATCH($D7,'지수RAW'!$R$7:$R$12040,0)-1,1),GOOGLEFINANCE(Q$2))"),2445.85) | R7: =IFERROR(__xludf.DUMMYFUNCTION("iferror(index('지수RAW'!$F$7:$F$12040,MATCH($D7,'지수RAW'!$B$7:$B$12040,0)-1,1),GOOGLEFINANCE(R$2))"),2640.87) | S7: =IFERROR(__xludf.DUMMYFUNCTION("iferror(index('지수RAW'!$N$7:$N$12040,MATCH($D7,'지수RAW'!$J$7:$J$12040,0)-1,1),GOOGLEFINANCE(S$2))"),7063.45) | U7: {=IFERROR(INDEX(지수RAW!$AT$7:$AT$12040,MATCH($D7,지수RAW!$AP$7:$AP$12040,0)-1,1),지수RAW!$AU$4)} | V7: =IFERROR(__xludf.DUMMYFUNCTION("iferror(index('지수RAW'!$AL$7:$AL$12040,MATCH($D7,'지수RAW'!$AH$7:$AH$12040,0)-1,1),GOOGLEFINANCE(V$2))"),6927.08) | W7: =IFERROR(__xludf.DUMMYFUNCTION("iferror(index('지수RAW'!$AD$7:$AD$12040,MATCH($D7,'지수RAW'!$Z$7:$Z$12040,0)-1,1),GOOGLEFINANCE(W$2))"),1059.55) | X7: =$W7*R7 | Y7: =$W7*S7 | Z7: =$W7*U7 | AA7: =$W7*V7 | AC7: =IF(Q7="","",AC6*(W7/W6)) | AD7: =IF(R7="","",AD6*(X7/X6)) | AE7: =IF(S7="","",AE6*(Y7/Y6)) | AF7: =IF(U7="","",AF6*(Z7/Z6)) | AG7: =IF(V7="","",AG6*(AA7/AA6))
B8: =IF(C7=12,B7+1,B7) | C8: =IF(C7=12,1,C7+1) | D8: =IF(F8="12월",(E8+1)&VLOOKUP(F8,인덱스!$C:$D,2,0),E8&VLOOKUP(F8,인덱스!$C:$D,2,0)) | E8: ="20"&B8 | F8: =C8&"월" | G8: =B8&"."&VLOOKUP(F8,인덱스!$A:$B,2,0) | H8: =IFERROR(VLOOKUP(G8,#REF!,2,0),) | I8: =IF(Q8="","",I7*(Q8/Q7)) | J8: =IF(R8="","",J7*(R8/R7)) | K8: =IF(S8="","",K7*(S8/S7)) | L8: =IF(U8="","",L7*(U8/U7)) | M8: =IF(V8="","",M7*(V8/V7)) | Q8: =IFERROR(__xludf.DUMMYFUNCTION("iferror(index('지수RAW'!$V$7:$V$12040,MATCH($D8,'지수RAW'!$R$7:$R$12040,0)-1,1),GOOGLEFINANCE(Q$2))"),2515.38) | R8: =IFERROR(__xludf.DUMMYFUNCTION("iferror(index('지수RAW'!$F$7:$F$12040,MATCH($D8,'지수RAW'!$B$7:$B$12040,0)-1,1),GOOGLEFINANCE(R$2))"),2648.05) | S8: =IFERROR(__xludf.DUMMYFUNCTION("iferror(index('지수RAW'!$N$7:$N$12040,MATCH($D8,'지수RAW'!$J$7:$J$12040,0)-1,1),GOOGLEFINANCE(S$2))"),7066.27) | U8: {=IFERROR(INDEX(지수RAW!$AT$7:$AT$12040,MATCH($D8,지수RAW!$AP$7:$AP$12040,0)-1,1),지수RAW!$AU$4)} | V8: =IFERROR(__xludf.DUMMYFUNCTION("iferror(index('지수RAW'!$AL$7:$AL$12040,MATCH($D8,'지수RAW'!$AH$7:$AH$12040,0)-1,1),GOOGLEFINANCE(V$2))"),9231.28) | W8: =IFERROR(__xludf.DUMMYFUNCTION("iferror(index('지수RAW'!$AD$7:$AD$12040,MATCH($D8,'지수RAW'!$Z$7:$Z$12040,0)-1,1),GOOGLEFINANCE(W$2))"),1069.45) | X8: =$W8*R8 | Y8: =$W8*S8 | Z8: =$W8*U8 | AA8: =$W8*V8 | AC8: =IF(Q8="","",AC7*(W8/W7)) | AD8: =IF(R8="","",AD7*(X8/X7)) | AE8: =IF(S8="","",AE7*(Y8/Y7)) | AF8: =IF(U8="","",AF7*(Z8/Z7)) | AG8: =IF(V8="","",AG7*(AA8/AA7))
B9: =IF(C8=12,B8+1,B8) | C9: =IF(C8=12,1,C8+1) | D9: =IF(F9="12월",(E9+1)&VLOOKUP(F9,인덱스!$C:$D,2,0),E9&VLOOKUP(F9,인덱스!$C:$D,2,0)) | E9: ="20"&B9 | F9: =C9&"월" | G9: =B9&"."&VLOOKUP(F9,인덱스!$A:$B,2,0) | H9: =IFERROR(VLOOKUP(G9,#REF!,2,0),) | I9: =IF(Q9="","",I8*(Q9/Q8)) | J9: =IF(R9="","",J8*(R9/R8)) | K9: =IF(S9="","",K8*(S9/S8)) | L9: =IF(U9="","",L8*(U9/U8)) | M9: =IF(V9="","",M8*(V9/V8)) | Q9: =IFERROR(__xludf.DUMMYFUNCTION("iferror(index('지수RAW'!$V$7:$V$12040,MATCH($D9,'지수RAW'!$R$7:$R$12040,0)-1,1),GOOGLEFINANCE(Q$2))"),2423.01) | R9: =IFERROR(__xludf.DUMMYFUNCTION("iferror(index('지수RAW'!$F$7:$F$12040,MATCH($D9,'지수RAW'!$B$7:$B$12040,0)-1,1),GOOGLEFINANCE(R$2))"),2705.27) | S9: =IFERROR(__xludf.DUMMYFUNCTION("iferror(index('지수RAW'!$N$7:$N$12040,MATCH($D9,'지수RAW'!$J$7:$J$12040,0)-1,1),GOOGLEFINANCE(S$2))"),7442.12) | U9: {=IFERROR(INDEX(지수RAW!$AT$7:$AT$12040,MATCH($D9,지수RAW!$AP$7:$AP$12040,0)-1,1),지수RAW!$AU$4)} | V9: =IFERROR(__xludf.DUMMYFUNCTION("iferror(index('지수RAW'!$AL$7:$AL$12040,MATCH($D9,'지수RAW'!$AH$7:$AH$12040,0)-1,1),GOOGLEFINANCE(V$2))"),7318.37) | W9: =IFERROR(__xludf.DUMMYFUNCTION("iferror(index('지수RAW'!$AD$7:$AD$12040,MATCH($D9,'지수RAW'!$Z$7:$Z$12040,0)-1,1),GOOGLEFINANCE(W$2))"),1079.95) | X9: =$W9*R9 | Y9: =$W9*S9 | Z9: =$W9*U9 | AA9: =$W9*V9 | AC9: =IF(Q9="","",AC8*(W9/W8)) | AD9: =IF(R9="","",AD8*(X9/X8)) | AE9: =IF(S9="","",AE8*(Y9/Y8)) | AF9: =IF(U9="","",AF8*(Z9/Z8)) | AG9: =IF(V9="","",AG8*(AA9/AA8))
B10: =IF(C9=12,B9+1,B9) | C10: =IF(C9=12,1,C9+1) | D10: =IF(F10="12월",(E10+1)&VLOOKUP(F10,인덱스!$C:$D,2,0),E10&VLOOKUP(F10,인덱스!$C:$D,2,0)) | E10: ="20"&B10 | F10: =C10&"월" | G10: =B10&"."&VLOOKUP(F10,인덱스!$A:$B,2,0) | H10: =IFERROR(VLOOKUP(G10,#REF!,2,0),) | I10: =IF(Q10="","",I9*(Q10/Q9)) | J10: =IF(R10="","",J9*(R10/R9)) | K10: =IF(S10="","",K9*(S10/S9)) | L10: =IF(U10="","",L9*(U10/U9)) | M10: =IF(V10="","",M9*(V10/V9)) | Q10: =IFERROR(__xludf.DUMMYFUNCTION("iferror(index('지수RAW'!$V$7:$V$12040,MATCH($D10,'지수RAW'!$R$7:$R$12040,0)-1,1),GOOGLEFINANCE(Q$2))"),2326.13) | R10: =IFERROR(__xludf.DUMMYFUNCTION("iferror(index('지수RAW'!$F$7:$F$12040,MATCH($D10,'지수RAW'!$B$7:$B$12040,0)-1,1),GOOGLEFINANCE(R$2))"),2718.37) | S10: =IFERROR(__xludf.DUMMYFUNCTION("iferror(index('지수RAW'!$N$7:$N$12040,MATCH($D10,'지수RAW'!$J$7:$J$12040,0)-1,1),GOOGLEFINANCE(S$2))"),7510.3) | U10: {=IFERROR(INDEX(지수RAW!$AT$7:$AT$12040,MATCH($D10,지수RAW!$AP$7:$AP$12040,0)-1,1),지수RAW!$AU$4)} | V10: =IFERROR(__xludf.DUMMYFUNCTION("iferror(index('지수RAW'!$AL$7:$AL$12040,MATCH($D10,'지수RAW'!$AH$7:$AH$12040,0)-1,1),GOOGLEFINANCE(V$2))"),6387.27) | W10: =IFERROR(__xludf.DUMMYFUNCTION("iferror(index('지수RAW'!$AD$7:$AD$12040,MATCH($D10,'지수RAW'!$Z$7:$Z$12040,0)-1,1),GOOGLEFINANCE(W$2))"),1113.92) | X10: =$W10*R10 | Y10: =$W10*S10 | Z10: =$W10*U10 | AA10: =$W10*V10 | AC10: =IF(Q10="","",AC9*(W10/W9)) | AD10: =IF(R10="","",AD9*(X10/X9)) | AE10: =IF(S10="","",AE9*(Y10/Y9)) | AF10: =IF(U10="","",AF9*(Z10/Z9)) | AG10: =IF(V10="","",AG9*(AA10/AA9))
B11: =IF(C10=12,B10+1,B10) | C11: =IF(C10=12,1,C10+1) | D11: =IF(F11="12월",(E11+1)&VLOOKUP(F11,인덱스!$C:$D,2,0),E11&VLOOKUP(F11,인덱스!$C:$D,2,0)) | E11: ="20"&B11 | F11: =C11&"월" | G11: =B11&"."&VLOOKUP(F11,인덱스!$A:$B,2,0) | H11: =IFERROR(VLOOKUP(G11,#REF!,2,0),) | I11: =IF(Q11="","",I10*(Q11/Q10)) | J11: =IF(R11="","",J10*(R11/R10)) | K11: =IF(S11="","",K10*(S11/S10)) | L11: =IF(U11="","",L10*(U11/U10)) | M11: =IF(V11="","",M10*(V11/V10)) | Q11: =IFERROR(__xludf.DUMMYFUNCTION("iferror(index('지수RAW'!$V$7:$V$12040,MATCH($D11,'지수RAW'!$R$7:$R$12040,0)-1,1),GOOGLEFINANCE(Q$2))"),2295.26) | R11: =IFERROR(__xludf.DUMMYFUNCTION("iferror(index('지수RAW'!$F$7:$F$12040,MATCH($D11,'지수RAW'!$B$7:$B$12040,0)-1,1),GOOGLEFINANCE(R$2))"),2816.29) | S11: =IFERROR(__xludf.DUMMYFUNCTION("iferror(index('지수RAW'!$N$7:$N$12040,MATCH($D11,'지수RAW'!$J$7:$J$12040,0)-1,1),GOOGLEFINANCE(S$2))"),7671.79) | U11: {=IFERROR(INDEX(지수RAW!$AT$7:$AT$12040,MATCH($D11,지수RAW!$AP$7:$AP$12040,0)-1,1),지수RAW!$AU$4)} | V11: =IFERROR(__xludf.DUMMYFUNCTION("iferror(index('지수RAW'!$AL$7:$AL$12040,MATCH($D11,'지수RAW'!$AH$7:$AH$12040,0)-1,1),GOOGLEFINANCE(V$2))"),7736.32) | W11: =IFERROR(__xludf.DUMMYFUNCTION("iferror(index('지수RAW'!$AD$7:$AD$12040,MATCH($D11,'지수RAW'!$Z$7:$Z$12040,0)-1,1),GOOGLEFINANCE(W$2))"),1112.2) | X11: =$W11*R11 | Y11: =$W11*S11 | Z11: =$W11*U11 | AA11: =$W11*V11 | AC11: =IF(Q11="","",AC10*(W11/W10)) | AD11: =IF(R11="","",AD10*(X11/X10)) | AE11: =IF(S11="","",AE10*(Y11/Y10)) | AF11: =IF(U11="","",AF10*(Z11/Z10)) | AG11: =IF(V11="","",AG10*(AA11/AA10))
B12: =IF(C11=12,B11+1,B11) | C12: =IF(C11=12,1,C11+1) | D12: =IF(F12="12월",(E12+1)&VLOOKUP(F12,인덱스!$C:$D,2,0),E12&VLOOKUP(F12,인덱스!$C:$D,2,0)) | E12: ="20"&B12 | F12: =C12&"월" | G12: =B12&"."&VLOOKUP(F12,인덱스!$A:$B,2,0) | H12: =IFERROR(VLOOKUP(G12,#REF!,2,0),) | I12: =IF(Q12="","",I11*(Q12/Q11)) | J12: =IF(R12="","",J11*(R12/R11)) | K12: =IF(S12="","",K11*(S12/S11)) | L12: =IF(U12="","",L11*(U12/U11)) | M12: =IF(V12="","",M11*(V12/V11)) | Q12: =IFERROR(__xludf.DUMMYFUNCTION("iferror(index('지수RAW'!$V$7:$V$12040,MATCH($D12,'지수RAW'!$R$7:$R$12040,0)-1,1),GOOGLEFINANCE(Q$2))"),2322.88) | R12: =IFERROR(__xludf.DUMMYFUNCTION("iferror(index('지수RAW'!$F$7:$F$12040,MATCH($D12,'지수RAW'!$B$7:$B$12040,0)-1,1),GOOGLEFINANCE(R$2))"),2901.52) | S12: =IFERROR(__xludf.DUMMYFUNCTION("iferror(index('지수RAW'!$N$7:$N$12040,MATCH($D12,'지수RAW'!$J$7:$J$12040,0)-1,1),GOOGLEFINANCE(S$2))"),8109.54) | U12: {=IFERROR(INDEX(지수RAW!$AT$7:$AT$12040,MATCH($D12,지수RAW!$AP$7:$AP$12040,0)-1,1),지수RAW!$AU$4)} | V12: =IFERROR(__xludf.DUMMYFUNCTION("iferror(index('지수RAW'!$AL$7:$AL$12040,MATCH($D12,'지수RAW'!$AH$7:$AH$12040,0)-1,1),GOOGLEFINANCE(V$2))"),7012.26) | W12: =IFERROR(__xludf.DUMMYFUNCTION("iferror(index('지수RAW'!$AD$7:$AD$12040,MATCH($D12,'지수RAW'!$Z$7:$Z$12040,0)-1,1),GOOGLEFINANCE(W$2))"),1114.64) | X12: =$W12*R12 | Y12: =$W12*S12 | Z12: =$W12*U12 | AA12: =$W12*V12 | AC12: =IF(Q12="","",AC11*(W12/W11)) | AD12: =IF(R12="","",AD11*(X12/X11)) | AE12: =IF(S12="","",AE11*(Y12/Y11)) | AF12: =IF(U12="","",AF11*(Z12/Z11)) | AG12: =IF(V12="","",AG11*(AA12/AA11))
B13: =IF(C12=12,B12+1,B12) | C13: =IF(C12=12,1,C12+1) | D13: =IF(F13="12월",(E13+1)&VLOOKUP(F13,인덱스!$C:$D,2,0),E13&VLOOKUP(F13,인덱스!$C:$D,2,0)) | E13: ="20"&B13 | F13: =C13&"월" | G13: =B13&"."&VLOOKUP(F13,인덱스!$A:$B,2,0) | H13: =IFERROR(VLOOKUP(G13,#REF!,2,0),) | I13: =IF(Q13="","",I12*(Q13/Q12)) | J13: =IF(R13="","",J12*(R13/R12)) | K13: =IF(S13="","",K12*(S13/S12)) | L13: =IF(U13="","",L12*(U13/U12)) | M13: =IF(V13="","",M12*(V13/V12)) | Q13: =IFERROR(__xludf.DUMMYFUNCTION("iferror(index('지수RAW'!$V$7:$V$12040,MATCH($D13,'지수RAW'!$R$7:$R$12040,0)-1,1),GOOGLEFINANCE(Q$2))"),2343.07) | R13: =IFERROR(__xludf.DUMMYFUNCTION("iferror(index('지수RAW'!$F$7:$F$12040,MATCH($D13,'지수RAW'!$B$7:$B$12040,0)-1,1),GOOGLEFINANCE(R$2))"),2913.98) | S13: =IFERROR(__xludf.DUMMYFUNCTION("iferror(index('지수RAW'!$N$7:$N$12040,MATCH($D13,'지수RAW'!$J$7:$J$12040,0)-1,1),GOOGLEFINANCE(S$2))"),8046.35) | U13: {=IFERROR(INDEX(지수RAW!$AT$7:$AT$12040,MATCH($D13,지수RAW!$AP$7:$AP$12040,0)-1,1),지수RAW!$AU$4)} | V13: =IFERROR(__xludf.DUMMYFUNCTION("iferror(index('지수RAW'!$AL$7:$AL$12040,MATCH($D13,'지수RAW'!$AH$7:$AH$12040,0)-1,1),GOOGLEFINANCE(V$2))"),6618.76) | W13: =IFERROR(__xludf.DUMMYFUNCTION("iferror(index('지수RAW'!$AD$7:$AD$12040,MATCH($D13,'지수RAW'!$Z$7:$Z$12040,0)-1,1),GOOGLEFINANCE(W$2))"),1109.01) | X13: =$W13*R13 | Y13: =$W13*S13 | Z13: =$W13*U13 | AA13: =$W13*V13 | AC13: =IF(Q13="","",AC12*(W13/W12)) | AD13: =IF(R13="","",AD12*(X13/X12)) | AE13: =IF(S13="","",AE12*(Y13/Y12)) | AF13: =IF(U13="","",AF12*(Z13/Z12)) | AG13: =IF(V13="","",AG12*(AA13/AA12))
B14: =IF(C13=12,B13+1,B13) | C14: =IF(C13=12,1,C13+1) | D14: =IF(F14="12월",(E14+1)&VLOOKUP(F14,인덱스!$C:$D,2,0),E14&VLOOKUP(F14,인덱스!$C:$D,2,0)) | E14: ="20"&B14 | F14: =C14&"월" | G14: =B14&"."&VLOOKUP(F14,인덱스!$A:$B,2,0) | H14: =IFERROR(VLOOKUP(G14,#REF!,2,0),) | I14: =IF(Q14="","",I13*(Q14/Q13)) | J14: =IF(R14="","",J13*(R14/R13)) | K14: =IF(S14="","",K13*(S14/S13)) | L14: =IF(U14="","",L13*(U14/U13)) | M14: =IF(V14="","",M13*(V14/V13)) | Q14: =IFERROR(__xludf.DUMMYFUNCTION("iferror(index('지수RAW'!$V$7:$V$12040,MATCH($D14,'지수RAW'!$R$7:$R$12040,0)-1,1),GOOGLEFINANCE(Q$2))"),2029.69) | R14: =IFERROR(__xludf.DUMMYFUNCTION("iferror(index('지수RAW'!$F$7:$F$12040,MATCH($D14,'지수RAW'!$B$7:$B$12040,0)-1,1),GOOGLEFINANCE(R$2))"),2711.74) | S14: =IFERROR(__xludf.DUMMYFUNCTION("iferror(index('지수RAW'!$N$7:$N$12040,MATCH($D14,'지수RAW'!$J$7:$J$12040,0)-1,1),GOOGLEFINANCE(S$2))"),7305.9) | U14: {=IFERROR(INDEX(지수RAW!$AT$7:$AT$12040,MATCH($D14,지수RAW!$AP$7:$AP$12040,0)-1,1),지수RAW!$AU$4)} | V14: =IFERROR(__xludf.DUMMYFUNCTION("iferror(index('지수RAW'!$AL$7:$AL$12040,MATCH($D14,'지수RAW'!$AH$7:$AH$12040,0)-1,1),GOOGLEFINANCE(V$2))"),6340.38) | W14: =IFERROR(__xludf.DUMMYFUNCTION("iferror(index('지수RAW'!$AD$7:$AD$12040,MATCH($D14,'지수RAW'!$Z$7:$Z$12040,0)-1,1),GOOGLEFINANCE(W$2))"),1140.97) | X14: =$W14*R14 | Y14: =$W14*S14 | Z14: =$W14*U14 | AA14: =$W14*V14 | AC14: =IF(Q14="","",AC13*(W14/W13)) | AD14: =IF(R14="","",AD13*(X14/X13)) | AE14: =IF(S14="","",AE13*(Y14/Y13)) | AF14: =IF(U14="","",AF13*(Z14/Z13)) | AG14: =IF(V14="","",AG13*(AA14/AA13))
B15: =IF(C14=12,B14+1,B14) | C15: =IF(C14=12,1,C14+1) | D15: =IF(F15="12월",(E15+1)&VLOOKUP(F15,인덱스!$C:$D,2,0),E15&VLOOKUP(F15,인덱스!$C:$D,2,0)) | E15: ="20"&B15 | F15: =C15&"월" | G15: =B15&"."&VLOOKUP(F15,인덱스!$A:$B,2,0) | H15: =IFERROR(VLOOKUP(G15,#REF!,2,0),) | I15: =IF(Q15="","",I14*(Q15/Q14)) | J15: =IF(R15="","",J14*(R15/R14)) | K15: =IF(S15="","",K14*(S15/S14)) | L15: =IF(U15="","",L14*(U15/U14)) | M15: =IF(V15="","",M14*(V15/V14)) | Q15: =IFERROR(__xludf.DUMMYFUNCTION("iferror(index('지수RAW'!$V$7:$V$12040,MATCH($D15,'지수RAW'!$R$7:$R$12040,0)-1,1),GOOGLEFINANCE(Q$2))"),2096.86) | R15: =IFERROR(__xludf.DUMMYFUNCTION("iferror(index('지수RAW'!$F$7:$F$12040,MATCH($D15,'지수RAW'!$B$7:$B$12040,0)-1,1),GOOGLEFINANCE(R$2))"),2760.17) | S15: =IFERROR(__xludf.DUMMYFUNCTION("iferror(index('지수RAW'!$N$7:$N$12040,MATCH($D15,'지수RAW'!$J$7:$J$12040,0)-1,1),GOOGLEFINANCE(S$2))"),7330.54) | U15: {=IFERROR(INDEX(지수RAW!$AT$7:$AT$12040,MATCH($D15,지수RAW!$AP$7:$AP$12040,0)-1,1),지수RAW!$AU$4)} | V15: =IFERROR(__xludf.DUMMYFUNCTION("iferror(index('지수RAW'!$AL$7:$AL$12040,MATCH($D15,'지수RAW'!$AH$7:$AH$12040,0)-1,1),GOOGLEFINANCE(V$2))"),4021.237) | W15: =IFERROR(__xludf.DUMMYFUNCTION("iferror(index('지수RAW'!$AD$7:$AD$12040,MATCH($D15,'지수RAW'!$Z$7:$Z$12040,0)-1,1),GOOGLEFINANCE(W$2))"),1119.53) | X15: =$W15*R15 | Y15: =$W15*S15 | Z15: =$W15*U15 | AA15: =$W15*V15 | AC15: =IF(Q15="","",AC14*(W15/W14)) | AD15: =IF(R15="","",AD14*(X15/X14)) | AE15: =IF(S15="","",AE14*(Y15/Y14)) | AF15: =IF(U15="","",AF14*(Z15/Z14)) | AG15: =IF(V15="","",AG14*(AA15/AA14))
B16: =IF(C15=12,B15+1,B15) | C16: =IF(C15=12,1,C15+1) | D16: =IF(F16="12월",(E16+1)&VLOOKUP(F16,인덱스!$C:$D,2,0),E16&VLOOKUP(F16,인덱스!$C:$D,2,0)) | E16: ="20"&B16 | F16: =C16&"월" | G16: =B16&"."&VLOOKUP(F16,인덱스!$A:$B,2,0) | H16: =IFERROR(VLOOKUP(G16,#REF!,2,0),) | I16: =IF(Q16="","",I15*(Q16/Q15)) | J16: =IF(R16="","",J15*(R16/R15)) | K16: =IF(S16="","",K15*(S16/S15)) | L16: =IF(U16="","",L15*(U16/U15)) | M16: =IF(V16="","",M15*(V16/V15)) | Q16: =IFERROR(__xludf.DUMMYFUNCTION("iferror(index('지수RAW'!$V$7:$V$12040,MATCH($D16,'지수RAW'!$R$7:$R$12040,0)-1,1),GOOGLEFINANCE(Q$2))"),2041.04) | R16: =IFERROR(__xludf.DUMMYFUNCTION("iferror(index('지수RAW'!$F$7:$F$12040,MATCH($D16,'지수RAW'!$B$7:$B$12040,0)-1,1),GOOGLEFINANCE(R$2))"),2506.85) | S16: =IFERROR(__xludf.DUMMYFUNCTION("iferror(index('지수RAW'!$N$7:$N$12040,MATCH($D16,'지수RAW'!$J$7:$J$12040,0)-1,1),GOOGLEFINANCE(S$2))"),6635.28) | U16: {=IFERROR(INDEX(지수RAW!$AT$7:$AT$12040,MATCH($D16,지수RAW!$AP$7:$AP$12040,0)-1,1),지수RAW!$AU$4)} | V16: =IFERROR(__xludf.DUMMYFUNCTION("iferror(index('지수RAW'!$AL$7:$AL$12040,MATCH($D16,'지수RAW'!$AH$7:$AH$12040,0)-1,1),GOOGLEFINANCE(V$2))"),3711.907) | W16: =IFERROR(__xludf.DUMMYFUNCTION("iferror(index('지수RAW'!$AD$7:$AD$12040,MATCH($D16,'지수RAW'!$Z$7:$Z$12040,0)-1,1),GOOGLEFINANCE(W$2))"),1112.5) | X16: =$W16*R16 | Y16: =$W16*S16 | Z16: =$W16*U16 | AA16: =$W16*V16 | AC16: =IF(Q16="","",AC15*(W16/W15)) | AD16: =IF(R16="","",AD15*(X16/X15)) | AE16: =IF(S16="","",AE15*(Y16/Y15)) | AF16: =IF(U16="","",AF15*(Z16/Z15)) | AG16: =IF(V16="","",AG15*(AA16/AA15))
B17: =IF(C16=12,B16+1,B16) | C17: =IF(C16=12,1,C16+1) | D17: =IF(F17="12월",(E17+1)&VLOOKUP(F17,인덱스!$C:$D,2,0),E17&VLOOKUP(F17,인덱스!$C:$D,2,0)) | E17: ="20"&B17 | F17: =C17&"월" | G17: =B17&"."&VLOOKUP(F17,인덱스!$A:$B,2,0) | H17: =IFERROR(VLOOKUP(G17,#REF!,2,0),) | I17: =IF(Q17="","",I16*(Q17/Q16)) | J17: =IF(R17="","",J16*(R17/R16)) | K17: =IF(S17="","",K16*(S17/S16)) | L17: =IF(U17="","",L16*(U17/U16)) | M17: =IF(V17="","",M16*(V17/V16)) | Q17: =IFERROR(__xludf.DUMMYFUNCTION("iferror(index('지수RAW'!$V$7:$V$12040,MATCH($D17,'지수RAW'!$R$7:$R$12040,0)-1,1),GOOGLEFINANCE(Q$2))"),2204.85) | R17: =IFERROR(__xludf.DUMMYFUNCTION("iferror(index('지수RAW'!$F$7:$F$12040,MATCH($D17,'지수RAW'!$B$7:$B$12040,0)-1,1),GOOGLEFINANCE(R$2))"),2704.1) | S17: =IFERROR(__xludf.DUMMYFUNCTION("iferror(index('지수RAW'!$N$7:$N$12040,MATCH($D17,'지수RAW'!$J$7:$J$12040,0)-1,1),GOOGLEFINANCE(S$2))"),7281.74) | U17: {=IFERROR(INDEX(지수RAW!$AT$7:$AT$12040,MATCH($D17,지수RAW!$AP$7:$AP$12040,0)-1,1),지수RAW!$AU$4)} | V17: =IFERROR(__xludf.DUMMYFUNCTION("iferror(index('지수RAW'!$AL$7:$AL$12040,MATCH($D17,'지수RAW'!$AH$7:$AH$12040,0)-1,1),GOOGLEFINANCE(V$2))"),3419.343) | W17: =IFERROR(__xludf.DUMMYFUNCTION("iferror(index('지수RAW'!$AD$7:$AD$12040,MATCH($D17,'지수RAW'!$Z$7:$Z$12040,0)-1,1),GOOGLEFINANCE(W$2))"),1111.55) | X17: =$W17*R17 | Y17: =$W17*S17 | Z17: =$W17*U17 | AA17: =$W17*V17 | AC17: =IF(Q17="","",AC16*(W17/W16)) | AD17: =IF(R17="","",AD16*(X17/X16)) | AE17: =IF(S17="","",AE16*(Y17/Y16)) | AF17: =IF(U17="","",AF16*(Z17/Z16)) | AG17: =IF(V17="","",AG16*(AA17/AA16))
B18: =IF(C17=12,B17+1,B17) | C18: =IF(C17=12,1,C17+1) | D18: =IF(F18="12월",(E18+1)&VLOOKUP(F18,인덱스!$C:$D,2,0),E18&VLOOKUP(F18,인덱스!$C:$D,2,0)) | E18: ="20"&B18 | F18: =C18&"월" | G18: =B18&"."&VLOOKUP(F18,인덱스!$A:$B,2,0) | H18: =IFERROR(VLOOKUP(G18,#REF!,2,0),) | I18: =IF(Q18="","",I17*(Q18/Q17)) | J18: =IF(R18="","",J17*(R18/R17)) | K18: =IF(S18="","",K17*(S18/S17)) | L18: =IF(U18="","",L17*(U18/U17)) | M18: =IF(V18="","",M17*(V18/V17)) | Q18: =IFERROR(__xludf.DUMMYFUNCTION("iferror(index('지수RAW'!$V$7:$V$12040,MATCH($D18,'지수RAW'!$R$7:$R$12040,0)-1,1),GOOGLEFINANCE(Q$2))"),2195.44) | R18: =IFERROR(__xludf.DUMMYFUNCTION("iferror(index('지수RAW'!$F$7:$F$12040,MATCH($D18,'지수RAW'!$B$7:$B$12040,0)-1,1),GOOGLEFINANCE(R$2))"),2784.49) | S18: =IFERROR(__xludf.DUMMYFUNCTION("iferror(index('지수RAW'!$N$7:$N$12040,MATCH($D18,'지수RAW'!$J$7:$J$12040,0)-1,1),GOOGLEFINANCE(S$2))"),7532.53) | U18: {=IFERROR(INDEX(지수RAW!$AT$7:$AT$12040,MATCH($D18,지수RAW!$AP$7:$AP$12040,0)-1,1),지수RAW!$AU$4)} | V18: =IFERROR(__xludf.DUMMYFUNCTION("iferror(index('지수RAW'!$AL$7:$AL$12040,MATCH($D18,'지수RAW'!$AH$7:$AH$12040,0)-1,1),GOOGLEFINANCE(V$2))"),3801.876) | W18: =IFERROR(__xludf.DUMMYFUNCTION("iferror(index('지수RAW'!$AD$7:$AD$12040,MATCH($D18,'지수RAW'!$Z$7:$Z$12040,0)-1,1),GOOGLEFINANCE(W$2))"),1124.22) | X18: =$W18*R18 | Y18: =$W18*S18 | Z18: =$W18*U18 | AA18: =$W18*V18 | AC18: =IF(Q18="","",AC17*(W18/W17)) | AD18: =IF(R18="","",AD17*(X18/X17)) | AE18: =IF(S18="","",AE17*(Y18/Y17)) | AF18: =IF(U18="","",AF17*(Z18/Z17)) | AG18: =IF(V18="","",AG17*(AA18/AA17))
B19: =IF(C18=12,B18+1,B18) | C19: =IF(C18=12,1,C18+1) | D19: =IF(F19="12월",(E19+1)&VLOOKUP(F19,인덱스!$C:$D,2,0),E19&VLOOKUP(F19,인덱스!$C:$D,2,0)) | E19: ="20"&B19 | F19: =C19&"월" | G19: =B19&"."&VLOOKUP(F19,인덱스!$A:$B,2,0) | H19: =IFERROR(VLOOKUP(G19,#REF!,2,0),) | I19: =IF(Q19="","",I18*(Q19/Q18)) | J19: =IF(R19="","",J18*(R19/R18)) | K19: =IF(S19="","",K18*(S19/S18)) | L19: =IF(U19="","",L18*(U19/U18)) | M19: =IF(V19="","",M18*(V19/V18)) | Q19: =IFERROR(__xludf.DUMMYFUNCTION("iferror(index('지수RAW'!$V$7:$V$12040,MATCH($D19,'지수RAW'!$R$7:$R$12040,0)-1,1),GOOGLEFINANCE(Q$2))"),2140.67) | R19: =IFERROR(__xludf.DUMMYFUNCTION("iferror(index('지수RAW'!$F$7:$F$12040,MATCH($D19,'지수RAW'!$B$7:$B$12040,0)-1,1),GOOGLEFINANCE(R$2))"),2834.4) | S19: =IFERROR(__xludf.DUMMYFUNCTION("iferror(index('지수RAW'!$N$7:$N$12040,MATCH($D19,'지수RAW'!$J$7:$J$12040,0)-1,1),GOOGLEFINANCE(S$2))"),7729.32) | U19: {=IFERROR(INDEX(지수RAW!$AT$7:$AT$12040,MATCH($D19,지수RAW!$AP$7:$AP$12040,0)-1,1),지수RAW!$AU$4)} | V19: =IFERROR(__xludf.DUMMYFUNCTION("iferror(index('지수RAW'!$AL$7:$AL$12040,MATCH($D19,'지수RAW'!$AH$7:$AH$12040,0)-1,1),GOOGLEFINANCE(V$2))"),4121.252) | W19: =IFERROR(__xludf.DUMMYFUNCTION("iferror(index('지수RAW'!$AD$7:$AD$12040,MATCH($D19,'지수RAW'!$Z$7:$Z$12040,0)-1,1),GOOGLEFINANCE(W$2))"),1136.7) | X19: =$W19*R19 | Y19: =$W19*S19 | Z19: =$W19*U19 | AA19: =$W19*V19 | AC19: =IF(Q19="","",AC18*(W19/W18)) | AD19: =IF(R19="","",AD18*(X19/X18)) | AE19: =IF(S19="","",AE18*(Y19/Y18)) | AF19: =IF(U19="","",AF18*(Z19/Z18)) | AG19: =IF(V19="","",AG18*(AA19/AA18))
B20: =IF(C19=12,B19+1,B19) | C20: =IF(C19=12,1,C19+1) | D20: =IF(F20="12월",(E20+1)&VLOOKUP(F20,인덱스!$C:$D,2,0),E20&VLOOKUP(F20,인덱스!$C:$D,2,0)) | E20: ="20"&B20 | F20: =C20&"월" | G20: =B20&"."&VLOOKUP(F20,인덱스!$A:$B,2,0) | H20: =IFERROR(VLOOKUP(G20,#REF!,2,0),) | I20: =IF(Q20="","",I19*(Q20/Q19)) | J20: =IF(R20="","",J19*(R20/R19)) | K20: =IF(S20="","",K19*(S20/S19)) | L20: =IF(U20="","",L19*(U20/U19)) | M20: =IF(V20="","",M19*(V20/V19)) | Q20: =IFERROR(__xludf.DUMMYFUNCTION("iferror(index('지수RAW'!$V$7:$V$12040,MATCH($D20,'지수RAW'!$R$7:$R$12040,0)-1,1),GOOGLEFINANCE(Q$2))"),2203.59) | R20: =IFERROR(__xludf.DUMMYFUNCTION("iferror(index('지수RAW'!$F$7:$F$12040,MATCH($D20,'지수RAW'!$B$7:$B$12040,0)-1,1),GOOGLEFINANCE(R$2))"),2945.83) | S20: =IFERROR(__xludf.DUMMYFUNCTION("iferror(index('지수RAW'!$N$7:$N$12040,MATCH($D20,'지수RAW'!$J$7:$J$12040,0)-1,1),GOOGLEFINANCE(S$2))"),8095.39) | U20: {=IFERROR(INDEX(지수RAW!$AT$7:$AT$12040,MATCH($D20,지수RAW!$AP$7:$AP$12040,0)-1,1),지수RAW!$AU$4)} | V20: =IFERROR(__xludf.DUMMYFUNCTION("iferror(index('지수RAW'!$AL$7:$AL$12040,MATCH($D20,'지수RAW'!$AH$7:$AH$12040,0)-1,1),GOOGLEFINANCE(V$2))"),5286.545) | W20: =IFERROR(__xludf.DUMMYFUNCTION("iferror(index('지수RAW'!$AD$7:$AD$12040,MATCH($D20,'지수RAW'!$Z$7:$Z$12040,0)-1,1),GOOGLEFINANCE(W$2))"),1163.26) | X20: =$W20*R20 | Y20: =$W20*S20 | Z20: =$W20*U20 | AA20: =$W20*V20 | AC20: =IF(Q20="","",AC19*(W20/W19)) | AD20: =IF(R20="","",AD19*(X20/X19)) | AE20: =IF(S20="","",AE19*(Y20/Y19)) | AF20: =IF(U20="","",AF19*(Z20/Z19)) | AG20: =IF(V20="","",AG19*(AA20/AA19))
B21: =IF(C20=12,B20+1,B20) | C21: =IF(C20=12,1,C20+1) | D21: =IF(F21="12월",(E21+1)&VLOOKUP(F21,인덱스!$C:$D,2,0),E21&VLOOKUP(F21,인덱스!$C:$D,2,0)) | E21: ="20"&B21 | F21: =C21&"월" | G21: =B21&"."&VLOOKUP(F21,인덱스!$A:$B,2,0) | H21: =IFERROR(VLOOKUP(G21,#REF!,2,0),) | I21: =IF(Q21="","",I20*(Q21/Q20)) | J21: =IF(R21="","",J20*(R21/R20)) | K21: =IF(S21="","",K20*(S21/S20)) | L21: =IF(U21="","",L20*(U21/U20)) | M21: =IF(V21="","",M20*(V21/V20)) | Q21: =IFERROR(__xludf.DUMMYFUNCTION("iferror(index('지수RAW'!$V$7:$V$12040,MATCH($D21,'지수RAW'!$R$7:$R$12040,0)-1,1),GOOGLEFINANCE(Q$2))"),2041.74) | R21: =IFERROR(__xludf.DUMMYFUNCTION("iferror(index('지수RAW'!$F$7:$F$12040,MATCH($D21,'지수RAW'!$B$7:$B$12040,0)-1,1),GOOGLEFINANCE(R$2))"),2752.06) | S21: =IFERROR(__xludf.DUMMYFUNCTION("iferror(index('지수RAW'!$N$7:$N$12040,MATCH($D21,'지수RAW'!$J$7:$J$12040,0)-1,1),GOOGLEFINANCE(S$2))"),7453.15) | U21: {=IFERROR(INDEX(지수RAW!$AT$7:$AT$12040,MATCH($D21,지수RAW!$AP$7:$AP$12040,0)-1,1),지수RAW!$AU$4)} | V21: =IFERROR(__xludf.DUMMYFUNCTION("iferror(index('지수RAW'!$AL$7:$AL$12040,MATCH($D21,'지수RAW'!$AH$7:$AH$12040,0)-1,1),GOOGLEFINANCE(V$2))"),8554.387) | W21: =IFERROR(__xludf.DUMMYFUNCTION("iferror(index('지수RAW'!$AD$7:$AD$12040,MATCH($D21,'지수RAW'!$Z$7:$Z$12040,0)-1,1),GOOGLEFINANCE(W$2))"),1187.97) | X21: =$W21*R21 | Y21: =$W21*S21 | Z21: =$W21*U21 | AA21: =$W21*V21 | AC21: =IF(Q21="","",AC20*(W21/W20)) | AD21: =IF(R21="","",AD20*(X21/X20)) | AE21: =IF(S21="","",AE20*(Y21/Y20)) | AF21: =IF(U21="","",AF20*(Z21/Z20)) | AG21: =IF(V21="","",AG20*(AA21/AA20))
B22: =IF(C21=12,B21+1,B21) | C22: =IF(C21=12,1,C21+1) | D22: =IF(F22="12월",(E22+1)&VLOOKUP(F22,인덱스!$C:$D,2,0),E22&VLOOKUP(F22,인덱스!$C:$D,2,0)) | E22: ="20"&B22 | F22: =C22&"월" | G22: =B22&"."&VLOOKUP(F22,인덱스!$A:$B,2,0) | H22: =IFERROR(VLOOKUP(G22,#REF!,2,0),) | I22: =IF(Q22="","",I21*(Q22/Q21)) | J22: =IF(R22="","",J21*(R22/R21)) | K22: =IF(S22="","",K21*(S22/S21)) | L22: =IF(U22="","",L21*(U22/U21)) | M22: =IF(V22="","",M21*(V22/V21)) | Q22: =IFERROR(__xludf.DUMMYFUNCTION("iferror(index('지수RAW'!$V$7:$V$12040,MATCH($D22,'지수RAW'!$R$7:$R$12040,0)-1,1),GOOGLEFINANCE(Q$2))"),2130.62) | R22: =IFERROR(__xludf.DUMMYFUNCTION("iferror(index('지수RAW'!$F$7:$F$12040,MATCH($D22,'지수RAW'!$B$7:$B$12040,0)-1,1),GOOGLEFINANCE(R$2))"),2941.76) | S22: =IFERROR(__xludf.DUMMYFUNCTION("iferror(index('지수RAW'!$N$7:$N$12040,MATCH($D22,'지수RAW'!$J$7:$J$12040,0)-1,1),GOOGLEFINANCE(S$2))"),8006.24) | U22: {=IFERROR(INDEX(지수RAW!$AT$7:$AT$12040,MATCH($D22,지수RAW!$AP$7:$AP$12040,0)-1,1),지수RAW!$AU$4)} | V22: =IFERROR(__xludf.DUMMYFUNCTION("iferror(index('지수RAW'!$AL$7:$AL$12040,MATCH($D22,'지수RAW'!$AH$7:$AH$12040,0)-1,1),GOOGLEFINANCE(V$2))"),10769.18) | W22: =IFERROR(__xludf.DUMMYFUNCTION("iferror(index('지수RAW'!$AD$7:$AD$12040,MATCH($D22,'지수RAW'!$Z$7:$Z$12040,0)-1,1),GOOGLEFINANCE(W$2))"),1155.6) | X22: =$W22*R22 | Y22: =$W22*S22 | Z22: =$W22*U22 | AA22: =$W22*V22 | AC22: =IF(Q22="","",AC21*(W22/W21)) | AD22: =IF(R22="","",AD21*(X22/X21)) | AE22: =IF(S22="","",AE21*(Y22/Y21)) | AF22: =IF(U22="","",AF21*(Z22/Z21)) | AG22: =IF(V22="","",AG21*(AA22/AA21))
B23: =IF(C22=12,B22+1,B22) | C23: =IF(C22=12,1,C22+1) | D23: =IF(F23="12월",(E23+1)&VLOOKUP(F23,인덱스!$C:$D,2,0),E23&VLOOKUP(F23,인덱스!$C:$D,2,0)) | E23: ="20"&B23 | F23: =C23&"월" | G23: =B23&"."&VLOOKUP(F23,인덱스!$A:$B,2,0) | H23: =IFERROR(VLOOKUP(G23,#REF!,2,0),) | I23: =IF(Q23="","",I22*(Q23/Q22)) | J23: =IF(R23="","",J22*(R23/R22)) | K23: =IF(S23="","",K22*(S23/S22)) | L23: =IF(U23="","",L22*(U23/U22)) | M23: =IF(V23="","",M22*(V23/V22)) | Q23: =IFERROR(__xludf.DUMMYFUNCTION("iferror(index('지수RAW'!$V$7:$V$12040,MATCH($D23,'지수RAW'!$R$7:$R$12040,0)-1,1),GOOGLEFINANCE(Q$2))"),2024.55) | R23: =IFERROR(__xludf.DUMMYFUNCTION("iferror(index('지수RAW'!$F$7:$F$12040,MATCH($D23,'지수RAW'!$B$7:$B$12040,0)-1,1),GOOGLEFINANCE(R$2))"),2980.38) | S23: =IFERROR(__xludf.DUMMYFUNCTION("iferror(index('지수RAW'!$N$7:$N$12040,MATCH($D23,'지수RAW'!$J$7:$J$12040,0)-1,1),GOOGLEFINANCE(S$2))"),8175.42) | U23: {=IFERROR(INDEX(지수RAW!$AT$7:$AT$12040,MATCH($D23,지수RAW!$AP$7:$AP$12040,0)-1,1),지수RAW!$AU$4)} | V23: =IFERROR(__xludf.DUMMYFUNCTION("iferror(index('지수RAW'!$AL$7:$AL$12040,MATCH($D23,'지수RAW'!$AH$7:$AH$12040,0)-1,1),GOOGLEFINANCE(V$2))"),10084.75) | W23: =IFERROR(__xludf.DUMMYFUNCTION("iferror(index('지수RAW'!$AD$7:$AD$12040,MATCH($D23,'지수RAW'!$Z$7:$Z$12040,0)-1,1),GOOGLEFINANCE(W$2))"),1186.31) | X23: =$W23*R23 | Y23: =$W23*S23 | Z23: =$W23*U23 | AA23: =$W23*V23 | AC23: =IF(Q23="","",AC22*(W23/W22)) | AD23: =IF(R23="","",AD22*(X23/X22)) | AE23: =IF(S23="","",AE22*(Y23/Y22)) | AF23: =IF(U23="","",AF22*(Z23/Z22)) | AG23: =IF(V23="","",AG22*(AA23/AA22))
