Workbook

Sheet 계좌현황
C3: 종목별 실적 & 비중
I5: $1 = ￦1,326 | J5: 1325.79
C6: 국가 | D6: 종목코드 (티커) | E6: 종목명 | F6: 수량 | G6: 평단가 | I6: 현재가 | K6: 평가액 [원화] | L6: 투자비중 | M6: 누적수익 [원화] | N6: 총수익률 [평가+배당] | O6: 종목
G7: 원화 | H7: 달러 | I7: 원화 | J7: 달러
A8: 계좌 | B8: 번호 | K8: =SUM(K9:K83) -> 7.448868e+08 | M8: =SUM(M9:M83) -> 21139567 | N8: =IFERROR(M8/(K8-M8),) -> 0.029208495
A9: DC | B9: 1 | C9: 한국 | D9: 458760 | E9: TIGER 미배당다우커버드콜2호 | F9: 9359 | G9: 9435 | I9: 10600 | K9: =IFERROR(I9*F9+J9*$J$5*F9,) -> 99205400 | L9: =IFERROR(K9/$K$8,) -> 0.13318185 | M9: =IFERROR(K9-G9*F9-H9*$J$5*F9,) -> 10903235 | N9: =IFERROR(M9/(K9-M9),) -> 0.12347642 | O9: 다우커
A10: DC | B10: 2 | C10: 한국 | D10: 490490 | E10: SOL미국배당미국채혼합50 | F10: 3821 | G10: 10603 | I10: 10590 | K10: =IFERROR(I10*F10+J10*$J$5*F10,) -> 40464390 | L10: =IFERROR(K10/$K$8,) -> 0.054322872 | M10: =IFERROR(K10-G10*F10-H10*$J$5*F10,) -> -49673 | N10: =IFERROR(M10/(K10-M10),) -> -0.0012260681 | O10: 미배당국채
A11: DC | B11: 3 | C11: 한국 | D11: 0008S0 | E11: TIGER 미국배당다우존스타겟데일리커버드콜 | F11: 3000 | G11: 8910 | I11: 9515 | K11: =IFERROR(I11*F11+J11*$J$5*F11,) -> 28545000 | L11: =IFERROR(K11/$K$8,) -> 0.038321259 | M11: =IFERROR(K11-G11*F11-H11*$J$5*F11,) -> 1815000 | N11: =IFERROR(M11/(K11-M11),) -> 0.067901235 | O11: 다우커
A12: DC | B12: 4 | C12: 한국 | D12: 498410 | E12: KODEX금융고배당TOP10타겟위클리커버드콜 | F12: 2377 | G12: 12286 | I12: 10750 | K12: =IFERROR(I12*F12+J12*$J$5*F12,) -> 25552750 | L12: =IFERROR(K12/$K$8,) -> 0.034304206 | M12: =IFERROR(K12-G12*F12-H12*$J$5*F12,) -> -3651072 | N12: =IFERROR(M12/(K12-M12),) -> -0.12502035 | O12: 국내금융배당
A13: DC | B13: 5 | C13: 한국 | D13: 472170 | E13: TIGER 미국테크TOP10채권혼합 | F13: 3649 | G13: 13954 | I13: 13855 | K13: =IFERROR(I13*F13+J13*$J$5*F13,) -> 50556895 | L13: =IFERROR(K13/$K$8,) -> 0.067871917 | M13: =IFERROR(K13-G13*F13-H13*$J$5*F13,) -> -361251 | N13: =IFERROR(M13/(K13-M13),) -> -0.0070947399 | O13: 테크채권
A14: DC | B14: 6 | C14: 한국 | D14: 468380 | E14: KODEX iShares미국하이일드액티브 | F14: 2000 | G14: 11685 | I14: 10155 | K14: =IFERROR(I14*F14+J14*$J$5*F14,) -> 20310000 | L14: =IFERROR(K14/$K$8,) -> 0.027265888 | M14: =IFERROR(K14-G14*F14-H14*$J$5*F14,) -> -3060000 | N14: =IFERROR(M14/(K14-M14),) -> -0.1309371 | O14: 달러
A15: DC | B15: 7 | C15: 한국 | D15: 329200 | E15: TIGER리츠부동산인프라 | F15: 5000 | G15: 4395 | I15: 4000 | K15: =IFERROR(I15*F15+J15*$J$5*F15,) -> 20000000 | L15: =IFERROR(K15/$K$8,) -> 0.026849717 | M15: =IFERROR(K15-G15*F15-H15*$J$5*F15,) -> -1975000 | N15: =IFERROR(M15/(K15-M15),) -> -0.089874858 | O15: 국내리츠
A16: DC | B16: 8 | C16: 한국 | D16: 379810 | E16: KODEX 미국나스닥100 | F16: 523 | G16: 27046 | I16: 25725 | K16: =IFERROR(I16*F16+J16*$J$5*F16,) -> 13454175 | L16: =IFERROR(K16/$K$8,) -> 0.01806204 | M16: =IFERROR(K16-G16*F16-H16*$J$5*F16,) -> -690883 | N16: =IFERROR(M16/(K16-M16),) -> -0.048842712 | O16: 나스닥
A17: 개인연금1 | B17: 9 | C17: 한국 | D17: 474220 | E17: TIGER미국테크TOP10커버드콜 | F17: 3260 | G17: 10680 | I17: 14445 | K17: =IFERROR(I17*F17+J17*$J$5*F17,) -> 47090700 | L17: =IFERROR(K17/$K$8,) -> 0.063218599 | M17: =IFERROR(K17-G17*F17-H17*$J$5*F17,) -> 12273900 | N17: =IFERROR(M17/(K17-M17),) -> 0.35252809 | O17: 테커
A18: 개인연금1 | B18: 10 | C18: 한국 | D18: 458760 | E18: TIGER 미배당다우커버드콜2호 | F18: 4055 | G18: 10101 | I18: 10600 | K18: =IFERROR(I18*F18+J18*$J$5*F18,) -> 42983000 | L18: =IFERROR(K18/$K$8,) -> 0.05770407 | M18: =IFERROR(K18-G18*F18-H18*$J$5*F18,) -> 2023445 | N18: =IFERROR(M18/(K18-M18),) -> 0.049401049 | O18: 다우커
A19: 개인연금1 | B19: 11 | C19: 한국 | D19: 446720 | E19: SOL 미국배당다우존스 | F19: 1330 | G19: 10517 | I19: 13355 | K19: =IFERROR(I19*F19+J19*$J$5*F19,) -> 17762150 | L19: =IFERROR(K19/$K$8,) -> 0.023845435 | M19: =IFERROR(K19-G19*F19-H19*$J$5*F19,) -> 3774540 | N19: =IFERROR(M19/(K19-M19),) -> 0.26984882 | O19: 다우
A20: 개인연금1 | B20: 12 | C20: 한국 | D20: 433330 | E20: SOL 미국 S&P500 | F20: 1061 | G20: 20547 | I20: 21090 | K20: =IFERROR(I20*F20+J20*$J$5*F20,) -> 22376490 | L20: =IFERROR(K20/$K$8,) -> 0.030040122 | M20: =IFERROR(K20-G20*F20-H20*$J$5*F20,) -> 576123 | N20: =IFERROR(M20/(K20-M20),) -> 0.026427216 | O20: 슨피
... A23: 개인연금2 | B23: 15 | C23: 한국 | D23: 360750 | E23: TIGER미국S&P500 | F23: 221 | G23: 25497 | I23: 25285 | K23: =IFERROR(I23*F23+J23*$J$5*F23,) -> 5587985 | L23: =IFERROR(K23/$K$8,) -> 0.0075017909 | M23: =IFERROR(K23-G23*F23-H23*$J$5*F23,) -> -46852 | N23: =IFERROR(M23/(K23-M23),) -> -0.0083147037 | O23: 슨피
A24: ISA | B24: 16 | C24: 한국 | D24: 483280 | E24: KODEX 미국AI테크TOP10타겟커버드콜 | F24: 2226 | G24: 10928 | I24: 11075 | K24: =IFERROR(I24*F24+J24*$J$5*F24,) -> 24652950 | L24: =IFERROR(K24/$K$8,) -> 0.033096237 | M24: =IFERROR(K24-G24*F24-H24*$J$5*F24,) -> 327222 | N24: =IFERROR(M24/(K24-M24),) -> 0.013451684
A25: ISA | B25: 17 | C25: 한국 | D25: 458760 | E25: TIGER 미배당다우커버드콜2호 | F25: 1964 | G25: 9906 | I25: 10600 | K25: =IFERROR(I25*F25+J25*$J$5*F25,) -> 20818400 | L25: =IFERROR(K25/$K$8,) -> 0.027948408 | M25: =IFERROR(K25-G25*F25-H25*$J$5*F25,) -> 1363016 | N25: =IFERROR(M25/(K25-M25),) -> 0.07005855 | O25: 다우커
A26: ISA | B26: 18 | C26: 한국 | D26: 474220 | E26: TIGER미국테크TOP10커버드콜 | F26: 1350 | G26: 12013 | I26: 14445 | K26: =IFERROR(I26*F26+J26*$J$5*F26,) -> 19500750 | L26: =IFERROR(K26/$K$8,) -> 0.026179481 | M26: =IFERROR(K26-G26*F26-H26*$J$5*F26,) -> 3283200 | N26: =IFERROR(M26/(K26-M26),) -> 0.20244735 | O26: 테커
A27: ISA | B27: 19 | C27: 한국 | D27: 457480 | E27: ACE테슬라밸류체인액티브 | F27: 515 | G27: 16707 | I27: 16275 | K27: =IFERROR(I27*F27+J27*$J$5*F27,) -> 8381625 | L27: =IFERROR(K27/$K$8,) -> 0.011252213 | M27: =IFERROR(K27-G27*F27-H27*$J$5*F27,) -> -222480 | N27: =IFERROR(M27/(K27-M27),) -> -0.025857425 | O27: 테슬라
A28: ISA | B28: 20 | C28: 한국 | D28: 473330 | E28: SOL 미국 30년국채커버드콜(합성) | F28: 960 | G28: 9360 | I28: 7530 | K28: =IFERROR(I28*F28+J28*$J$5*F28,) -> 7228800 | L28: =IFERROR(K28/$K$8,) -> 0.0097045619 | M28: =IFERROR(K28-G28*F28-H28*$J$5*F28,) -> -1756800 | N28: =IFERROR(M28/(K28-M28),) -> -0.19551282 | O28: 미국채커
A29: ISA | B29: 21 | C29: 한국 | D29: 000270 | E29: 기아 | F29: 34 | G29: 110746 | I29: 108800 | K29: =IFERROR(I29*F29+J29*$J$5*F29,) -> 3699200 | L29: =IFERROR(K29/$K$8,) -> 0.0049661237 | M29: =IFERROR(K29-G29*F29-H29*$J$5*F29,) -> -66164 | N29: =IFERROR(M29/(K29-M29),) -> -0.017571741 | O29: 기아
A30: ISA | B30: 22 | C30: 한국 | D30: 498270 | E30: KIWOOM 미국양자컴퓨팅 | F30: 297 | G30: 12814 | I30: 12615 | K30: =IFERROR(I30*F30+J30*$J$5*F30,) -> 3746655 | L30: =IFERROR(K30/$K$8,) -> 0.0050298314 | M30: =IFERROR(K30-G30*F30-H30*$J$5*F30,) -> -59103 | N30: =IFERROR(M30/(K30-M30),) -> -0.015529889 | O30: 양자
A31: ISA | B31: 23 | C31: 한국 | D31: 0072R0 | E31: TIGER KRX금현물 | F31: 481 | G31: 13495 | I31: 11600 | K31: =IFERROR(I31*F31+J31*$J$5*F31,) -> 5579600 | L31: =IFERROR(K31/$K$8,) -> 0.0074905342 | M31: =IFERROR(K31-G31*F31-H31*$J$5*F31,) -> -911495 | N31: =IFERROR(M31/(K31-M31),) -> -0.14042238 | O31: 금
A32: ISA | B32: 24 | C32: 한국 | D32: 005389 | E32: 현대차3우B | F32: 13 | G32: 160810 | I32: 160200 | K32: =IFERROR(I32*F32+J32*$J$5*F32,) -> 2082600 | L32: =IFERROR(K32/$K$8,) -> 0.0027958611 | M32: =IFERROR(K32-G32*F32-H32*$J$5*F32,) -> -7930 | N32: =IFERROR(M32/(K32-M32),) -> -0.0037932964 | O32: 현대차
A33: ISA | B33: 25 | C33: 한국 | D33: 364980 | E33: TIGER 2차전지TOP10 | F33: 176 | G33: 8477 | I33: 9865 | K33: =IFERROR(I33*F33+J33*$J$5*F33,) -> 1736240 | L33: =IFERROR(K33/$K$8,) -> 0.0023308777 | M33: =IFERROR(K33-G33*F33-H33*$J$5*F33,) -> 244288 | N33: =IFERROR(M33/(K33-M33),) -> 0.16373717 | O33: 이차전지
A34: ISA | B34: 26 | C34: 한국 | D34: 476690 | E34: TIGER 글로벌비만치료제 TOP2 Plus | F34: 100 | G34: 9378 | I34: 10205 | K34: =IFERROR(I34*F34+J34*$J$5*F34,) -> 1020500 | L34: =IFERROR(K34/$K$8,) -> 0.0013700068 | M34: =IFERROR(K34-G34*F34-H34*$J$5*F34,) -> 82700 | N34: =IFERROR(M34/(K34-M34),) -> 0.088185114 | O34: 헬스
A35: ISA | B35: 27 | C35: 한국 | D35: 475380 | E35: RISE 글로벌리얼티인컴 | F35: 101 | G35: 9891 | I35: 9545 | K35: =IFERROR(I35*F35+J35*$J$5*F35,) -> 964045 | L35: =IFERROR(K35/$K$8,) -> 0.0012942168 | M35: =IFERROR(K35-G35*F35-H35*$J$5*F35,) -> -34946 | N35: =IFERROR(M35/(K35-M35),) -> -0.034981296 | O35: 리츠
A36: 일반계좌 | B36: 28 | C36: 한국 | D36: 005930 | E36: 삼성전자 | F36: 55 | G36: 160500 | I36: 214500 | K36: =IFERROR(I36*F36+J36*$J$5*F36,) -> 11797500 | L36: =IFERROR(K36/$K$8,) -> 0.015837977 | M36: =IFERROR(K36-G36*F36-H36*$J$5*F36,) -> 2970000 | N36: =IFERROR(M36/(K36-M36),) -> 0.3364486 | O36: 삼전
... A38: 일반계좌 | B38: 30 | C38: 한국 | D38: 498400 | E38: KODEX 200타켓위클리커버드콜 | F38: 704 | G38: 21207 | I38: 16005 | K38: =IFERROR(I38*F38+J38*$J$5*F38,) -> 11267520 | L38: =IFERROR(K38/$K$8,) -> 0.015126486 | M38: =IFERROR(K38-G38*F38-H38*$J$5*F38,) -> -3662208 | N38: =IFERROR(M38/(K38-M38),) -> -0.24529636 | O38: 헬스
A39: 일반계좌 | B39: 31 | C39: 미국 | D39: TSLA | E39: 테슬라 | F39: 17 | H39: 280.9963 | J39: 380.34 | K39: =IFERROR(I39*F39+J39*$J$5*F39,) -> 8572266.4 | L39: =IFERROR(K39/$K$8,) -> 0.011508146 | M39: =IFERROR(K39-G39*F39-H39*$J$5*F39,) -> 2239050.9 | N39: =IFERROR(M39/(K39-M39),) -> 0.35354094 | O39: 테슬라
A40: 일반계좌 | B40: 32 | C40: 미국 | D40: O | E40: 리얼티인컴 | F40: 53 | H40: 53.53 | J40: 55.959999 | K40: =IFERROR(I40*F40+J40*$J$5*F40,) -> 3932134 | L40: =IFERROR(K40/$K$8,) -> 0.0052788343 | M40: =IFERROR(K40-G40*F40-H40*$J$5*F40,) -> 170748.43 | N40: =IFERROR(M40/(K40-M40),) -> 0.045395088 | O40: 미국리츠
A41: 일반계좌 | B41: 33 | C41: 미국 | D41: IONQ | E41: 아이온큐 | F41: 91 | H41: 29.68 | J41: 31.925301 | K41: =IFERROR(I41*F41+J41*$J$5*F41,) -> 3851688.2 | L41: =IFERROR(K41/$K$8,) -> 0.005170837 | M41: =IFERROR(K41-G41*F41-H41*$J$5*F41,) -> 270888.53 | N41: =IFERROR(M41/(K41-M41),) -> 0.07565029 | O41: 양자
A42: 일반계좌 | B42: 34 | C42: 미국 | D42: AAPL | E42: 애플 | F42: 9 | H42: 208.16 | J42: 345.345 | K42: =IFERROR(I42*F42+J42*$J$5*F42,) -> 4120694.5 | L42: =IFERROR(K42/$K$8,) -> 0.0055319742 | M42: =IFERROR(K42-G42*F42-H42*$J$5*F42,) -> 1636906.5 | N42: =IFERROR(M42/(K42-M42),) -> 0.65903632 | O42: 애플
A43: 일반계좌 | B43: 35 | C43: 한국 | D43: 024110 | E43: 기업은행 | F43: 179 | G43: 21932 | I43: 19850 | K43: =IFERROR(I43*F43+J43*$J$5*F43,) -> 3553150 | L43: =IFERROR(K43/$K$8,) -> 0.0047700537 | M43: =IFERROR(K43-G43*F43-H43*$J$5*F43,) -> -372678 | N43: =IFERROR(M43/(K43-M43),) -> -0.094929783 | O43: 기업은행
A44: 일반계좌 | B44: 36 | C44: 한국 | D44: 352820 | E44: 하이브 | F44: 18 | G44: 222701 | I44: 175800 | K44: =IFERROR(I44*F44+J44*$J$5*F44,) -> 3164400 | L44: =IFERROR(K44/$K$8,) -> 0.0042481623 | M44: =IFERROR(K44-G44*F44-H44*$J$5*F44,) -> -844218 | N44: =IFERROR(M44/(K44-M44),) -> -0.21060076 | O44: 엔터
A45: 일반계좌 | B45: 37 | C45: 미국 | D45: QLD | E45: QLD | F45: 62 | H45: 87.726 | J45: 88.330002 | K45: =IFERROR(I45*F45+J45*$J$5*F45,) -> 7260636.1 | L45: =IFERROR(K45/$K$8,) -> 0.0097473013 | M45: =IFERROR(K45-G45*F45-H45*$J$5*F45,) -> 49648.334 | N45: =IFERROR(M45/(K45-M45),) -> 0.0068850949 | O45: 나스닥
A46: 일반계좌2 | B46: 38 | C46: 미국 | D46: QLD | E46: QLD | F46: 78 | H46: 87.64 | J46: 88.330002 | K46: =IFERROR(I46*F46+J46*$J$5*F46,) -> 9134348.6 | L46: =IFERROR(K46/$K$8,) -> 0.012262734 | M46: =IFERROR(K46-G46*F46-H46*$J$5*F46,) -> 71354.207 | N46: =IFERROR(M46/(K46-M46),) -> 0.0078731382 | O46: 나스닥
...

Sheet 금액순
A1: 금액순 · 포트폴리오 비중 100% (계좌현황 자동연동)
A2: 왼쪽 '계좌현황' 시트의 평가액(K열)·계좌(A열)을 수식으로 참조합니다. 왼쪽을 수정·정렬하면 이 탭 수치가 함께 바뀝니다. (Google 스프레드시트 / Excel 365 권장)
A3: 총 평가액 | B3: =SUM(계좌현황!K9:K83) -> 7.448868e+08 | C3: 종목수 | D3: =COUNTA(계좌현황!E9:E83) -> 75
A5: ① 계좌별 합계 (왼쪽 자동집계)
A6: 계좌 | B6: 평가액 | C6: 비중 | D6: 종목수
A7: DC | B7: =SUMIF(계좌현황!A:A,A7,계좌현황!K:K) -> 298088610 | C7: =IF($B$3=0,0,B7/$B$3) -> 0.40017975 | D7: =COUNTIF(계좌현황!A9:A83,A7) -> 8
A8: 개인연금1 | B8: =SUMIF(계좌현황!A:A,A8,계좌현황!K:K) -> 134936215 | C8: =IF($B$3=0,0,B8/$B$3) -> 0.18114996 | D8: =COUNTIF(계좌현황!A9:A83,A8) -> 5
A9: 개인연금2 | B9: =SUMIF(계좌현황!A:A,A9,계좌현황!K:K) -> 15587715 | C9: =IF($B$3=0,0,B9/$B$3) -> 0.020926287 | D9: =COUNTIF(계좌현황!A9:A83,A9) -> 2
A10: ISA | B10: =SUMIF(계좌현황!A:A,A10,계좌현황!K:K) -> 99411365 | C10: =IF($B$3=0,0,B10/$B$3) -> 0.13345835 | D10: =COUNTIF(계좌현황!A9:A83,A10) -> 12
A11: 일반계좌 | B11: =SUMIF(계좌현황!A:A,A11,계좌현황!K:K) -> 94096948 | C11: =IF($B$3=0,0,B11/$B$3) -> 0.12632382 | D11: =COUNTIF(계좌현황!A9:A83,A11) -> 38
A12: CMA | B12: =SUMIF(계좌현황!A:A,A12,계좌현황!K:K) -> 40325031 | C12: =IF($B$3=0,0,B12/$B$3) -> 0.054135784 | D12: =COUNTIF(계좌현황!A9:A83,A12) -> 1
A13: IRP | B13: =SUMIF(계좌현황!A:A,A13,계좌현황!K:K) -> 39020010 | C13: =IF($B$3=0,0,B13/$B$3) -> 0.052383812 | D13: =COUNTIF(계좌현황!A9:A83,A13) -> 4
A14: 은행예금 | B14: =SUMIF(계좌현황!A:A,A14,계좌현황!K:K) -> 13435000 | C14: =IF($B$3=0,0,B14/$B$3) -> 0.018036298 | D14: =COUNTIF(계좌현황!A9:A83,A14) -> 1
A15: 일반계좌2 | B15: =SUMIF(계좌현황!A:A,A15,계좌현황!K:K) -> 9134348.6 | C15: =IF($B$3=0,0,B15/$B$3) -> 0.012262734 | D15: =COUNTIF(계좌현황!A9:A83,A15) -> 1
A16: TOSS | B16: =SUMIF(계좌현황!A:A,A16,계좌현황!K:K) -> 851554.92 | C16: =IF($B$3=0,0,B16/$B$3) -> 0.0011432004 | D16: =COUNTIF(계좌현황!A9:A83,A16) -> 3
A19: ② 전체 종목 금액 내림차순 100% (왼쪽 K열 기준 자동정렬) | L19: ← 자동계산용(원본행/미러)
A20: 순위 | B20: 계좌 | C20: 국가 | D20: 종목코드 | E20: 종목명 | F20: 수량 | G20: 평가액 | H20: 비중 | I20: 누적비중 | L20: 원본행 | M20: 평가액미러 | N20: 정렬키
A21: 1 | B21: =IFERROR(INDEX(계좌현황!A:A,INDEX($L$21:$L$95,MATCH(LARGE($N$21:$N$95,1),$N$21:$N$95,0))),"") -> DC | C21: =IFERROR(INDEX(계좌현황!C:C,INDEX($L$21:$L$95,MATCH(LARGE($N$21:$N$95,1),$N$21:$N$95,0))),"") -> 한국 | D21: =IFERROR(INDEX(계좌현황!D:D,INDEX($L$21:$L$95,MATCH(LARGE($N$21:$N$95,1),$N$21:$N$95,0))),"") -> 458760 | E21: =IFERROR(INDEX(계좌현황!E:E,INDEX($L$21:$L$95,MATCH(LARGE($N$21:$N$95,1),$N$21:$N$95,0))),"") -> TIGER 미배당다우커버드콜2호 | F21: =IFERROR(INDEX(계좌현황!F:F,INDEX($L$21:$L$95,MATCH(LARGE($N$21:$N$95,1),$N$21:$N$95,0))),"") -> 9359 | G21: =IFERROR(INDEX(계좌현황!K:K,INDEX($L$21:$L$95,MATCH(LARGE($N$21:$N$95,1),$N$21:$N$95,0))),0) -> 99205400 | H21: =IF($B$3=0,0,G21/$B$3) -> 0.13318185 | I21: =H21 -> 0.13318185 | L21: 9 | M21: =계좌현황!K9 -> 99205400 | N21: =IF(M21="",-1E+99,M21*100000+(10000-L21)) -> 9920540009991
A22: 2 | B22: =IFERROR(INDEX(계좌현황!A:A,INDEX($L$21:$L$95,MATCH(LARGE($N$21:$N$95,2),$N$21:$N$95,0))),"") -> DC | C22: =IFERROR(INDEX(계좌현황!C:C,INDEX($L$21:$L$95,MATCH(LARGE($N$21:$N$95,2),$N$21:$N$95,0))),"") -> 한국 | D22: =IFERROR(INDEX(계좌현황!D:D,INDEX($L$21:$L$95,MATCH(LARGE($N$21:$N$95,2),$N$21:$N$95,0))),"") -> 472170 | E22: =IFERROR(INDEX(계좌현황!E:E,INDEX($L$21:$L$95,MATCH(LARGE($N$21:$N$95,2),$N$21:$N$95,0))),"") -> TIGER 미국테크TOP10채권혼합 | F22: =IFERROR(INDEX(계좌현황!F:F,INDEX($L$21:$L$95,MATCH(LARGE($N$21:$N$95,2),$N$21:$N$95,0))),"") -> 3649 | G22: =IFERROR(INDEX(계좌현황!K:K,INDEX($L$21:$L$95,MATCH(LARGE($N$21:$N$95,2),$N$21:$N$95,0))),0) -> 50556895 | H22: =IF($B$3=0,0,G22/$B$3) -> 0.067871917 | I22: =I21+H22 -> 0.20105376 | L22: 10 | M22: =계좌현황!K10 -> 40464390 | N22: =IF(M22="",-1E+99,M22*100000+(10000-L22)) -> 4046439009990
A23: 3 | B23: =IFERROR(INDEX(계좌현황!A:A,INDEX($L$21:$L$95,MATCH(LARGE($N$21:$N$95,3),$N$21:$N$95,0))),"") -> 개인연금1 | C23: =IFERROR(INDEX(계좌현황!C:C,INDEX($L$21:$L$95,MATCH(LARGE($N$21:$N$95,3),$N$21:$N$95,0))),"") -> 한국 | D23: =IFERROR(INDEX(계좌현황!D:D,INDEX($L$21:$L$95,MATCH(LARGE($N$21:$N$95,3),$N$21:$N$95,0))),"") -> 474220 | E23: =IFERROR(INDEX(계좌현황!E:E,INDEX($L$21:$L$95,MATCH(LARGE($N$21:$N$95,3),$N$21:$N$95,0))),"") -> TIGER미국테크TOP10커버드콜 | F23: =IFERROR(INDEX(계좌현황!F:F,INDEX($L$21:$L$95,MATCH(LARGE($N$21:$N$95,3),$N$21:$N$95,0))),"") -> 3260 | G23: =IFERROR(INDEX(계좌현황!K:K,INDEX($L$21:$L$95,MATCH(LARGE($N$21:$N$95,3),$N$21:$N$95,0))),0) -> 47090700 | H23: =IF($B$3=0,0,G23/$B$3) -> 0.063218599 | I23: =I22+H23 -> 0.26427236 | L23: 11 | M23: =계좌현황!K11 -> 28545000 | N23: =IF(M23="",-1E+99,M23*100000+(10000-L23)) -> 2854500009989
A24: 4 | B24: =IFERROR(INDEX(계좌현황!A:A,INDEX($L$21:$L$95,MATCH(LARGE($N$21:$N$95,4),$N$21:$N$95,0))),"") -> 개인연금1 | C24: =IFERROR(INDEX(계좌현황!C:C,INDEX($L$21:$L$95,MATCH(LARGE($N$21:$N$95,4),$N$21:$N$95,0))),"") -> 한국 | D24: =IFERROR(INDEX(계좌현황!D:D,INDEX($L$21:$L$95,MATCH(LARGE($N$21:$N$95,4),$N$21:$N$95,0))),"") -> 458760 | E24: =IFERROR(INDEX(계좌현황!E:E,INDEX($L$21:$L$95,MATCH(LARGE($N$21:$N$95,4),$N$21:$N$95,0))),"") -> TIGER 미배당다우커버드콜2호 | F24: =IFERROR(INDEX(계좌현황!F:F,INDEX($L$21:$L$95,MATCH(LARGE($N$21:$N$95,4),$N$21:$N$95,0))),"") -> 4055 | G24: =IFERROR(INDEX(계좌현황!K:K,INDEX($L$21:$L$95,MATCH(LARGE($N$21:$N$95,4),$N$21:$N$95,0))),0) -> 42983000 | H24: =IF($B$3=0,0,G24/$B$3) -> 0.05770407 | I24: =I23+H24 -> 0.32197643 | L24: 12 | M24: =계좌현황!K12 -> 25552750 | N24: =IF(M24="",-1E+99,M24*100000+(10000-L24)) -> 2555275009988
A25: 5 | B25: =IFERROR(INDEX(계좌현황!A:A,INDEX($L$21:$L$95,MATCH(LARGE($N$21:$N$95,5),$N$21:$N$95,0))),"") -> DC | C25: =IFERROR(INDEX(계좌현황!C:C,INDEX($L$21:$L$95,MATCH(LARGE($N$21:$N$95,5),$N$21:$N$95,0))),"") -> 한국 | D25: =IFERROR(INDEX(계좌현황!D:D,INDEX($L$21:$L$95,MATCH(LARGE($N$21:$N$95,5),$N$21:$N$95,0))),"") -> 490490 | E25: =IFERROR(INDEX(계좌현황!E:E,INDEX($L$21:$L$95,MATCH(LARGE($N$21:$N$95,5),$N$21:$N$95,0))),"") -> SOL미국배당미국채혼합50 | F25: =IFERROR(INDEX(계좌현황!F:F,INDEX($L$21:$L$95,MATCH(LARGE($N$21:$N$95,5),$N$21:$N$95,0))),"") -> 3821 | G25: =IFERROR(INDEX(계좌현황!K:K,INDEX($L$21:$L$95,MATCH(LARGE($N$21:$N$95,5),$N$21:$N$95,0))),0) -> 40464390 | H25: =IF($B$3=0,0,G25/$B$3) -> 0.054322872 | I25: =I24+H25 -> 0.37629931 | L25: 13 | M25: =계좌현황!K13 -> 50556895 | N25: =IF(M25="",-1E+99,M25*100000+(10000-L25)) -> 5055689509987
A26: 6 | B26: =IFERROR(INDEX(계좌현황!A:A,INDEX($L$21:$L$95,MATCH(LARGE($N$21:$N$95,6),$N$21:$N$95,0))),"") -> CMA | C26: =IFERROR(INDEX(계좌현황!C:C,INDEX($L$21:$L$95,MATCH(LARGE($N$21:$N$95,6),$N$21:$N$95,0))),"") -> 0 | D26: =IFERROR(INDEX(계좌현황!D:D,INDEX($L$21:$L$95,MATCH(LARGE($N$21:$N$95,6),$N$21:$N$95,0))),"") -> 현금 | E26: =IFERROR(INDEX(계좌현황!E:E,INDEX($L$21:$L$95,MATCH(LARGE($N$21:$N$95,6),$N$21:$N$95,0))),"") -> CMA RP | F26: =IFERROR(INDEX(계좌현황!F:F,INDEX($L$21:$L$95,MATCH(LARGE($N$21:$N$95,6),$N$21:$N$95,0))),"") -> 1 | G26: =IFERROR(INDEX(계좌현황!K:K,INDEX($L$21:$L$95,MATCH(LARGE($N$21:$N$95,6),$N$21:$N$95,0))),0) -> 40325031 | H26: =IF($B$3=0,0,G26/$B$3) -> 0.054135784 | I26: =I25+H26 -> 0.43043509 | L26: 14 | M26: =계좌현황!K14 -> 20310000 | N26: =IF(M26="",-1E+99,M26*100000+(10000-L26)) -> 2031000009986
A27: 7 | B27: =IFERROR(INDEX(계좌현황!A:A,INDEX($L$21:$L$95,MATCH(LARGE($N$21:$N$95,7),$N$21:$N$95,0))),"") -> DC | C27: =IFERROR(INDEX(계좌현황!C:C,INDEX($L$21:$L$95,MATCH(LARGE($N$21:$N$95,7),$N$21:$N$95,0))),"") -> 한국 | D27: =IFERROR(INDEX(계좌현황!D:D,INDEX($L$21:$L$95,MATCH(LARGE($N$21:$N$95,7),$N$21:$N$95,0))),"") -> 0008S0 | E27: =IFERROR(INDEX(계좌현황!E:E,INDEX($L$21:$L$95,MATCH(LARGE($N$21:$N$95,7),$N$21:$N$95,0))),"") -> TIGER 미국배당다우존스타겟데일리커버드콜 | F27: =IFERROR(INDEX(계좌현황!F:F,INDEX($L$21:$L$95,MATCH(LARGE($N$21:$N$95,7),$N$21:$N$95,0))),"") -> 3000 | G27: =IFERROR(INDEX(계좌현황!K:K,INDEX($L$21:$L$95,MATCH(LARGE($N$21:$N$95,7),$N$21:$N$95,0))),0) -> 28545000 | H27: =IF($B$3=0,0,G27/$B$3) -> 0.038321259 | I27: =I26+H27 -> 0.46875635 | L27: 15 | M27: =계좌현황!K15 -> 20000000 | N27: =IF(M27="",-1E+99,M27*100000+(10000-L27)) -> 2000000009985
A28: 8 | B28: =IFERROR(INDEX(계좌현황!A:A,INDEX($L$21:$L$95,MATCH(LARGE($N$21:$N$95,8),$N$21:$N$95,0))),"") -> DC | C28: =IFERROR(INDEX(계좌현황!C:C,INDEX($L$21:$L$95,MATCH(LARGE($N$21:$N$95,8),$N$21:$N$95,0))),"") -> 한국 | D28: =IFERROR(INDEX(계좌현황!D:D,INDEX($L$21:$L$95,MATCH(LARGE($N$21:$N$95,8),$N$21:$N$95,0))),"") -> 498410 | E28: =IFERROR(INDEX(계좌현황!E:E,INDEX($L$21:$L$95,MATCH(LARGE($N$21:$N$95,8),$N$21:$N$95,0))),"") -> KODEX금융고배당TOP10타겟위클리커버드콜 | F28: =IFERROR(INDEX(계좌현황!F:F,INDEX($L$21:$L$95,MATCH(LARGE($N$21:$N$95,8),$N$21:$N$95,0))),"") -> 2377 | G28: =IFERROR(INDEX(계좌현황!K:K,INDEX($L$21:$L$95,MATCH(LARGE($N$21:$N$95,8),$N$21:$N$95,0))),0) -> 25552750 | H28: =IF($B$3=0,0,G28/$B$3) -> 0.034304206 | I28: =I27+H28 -> 0.50306056 | L28: 16 | M28: =계좌현황!K16 -> 13454175 | N28: =IF(M28="",-1E+99,M28*100000+(10000-L28)) -> 1345417509984
A29: 9 | B29: =IFERROR(INDEX(계좌현황!A:A,INDEX($L$21:$L$95,MATCH(LARGE($N$21:$N$95,9),$N$21:$N$95,0))),"") -> ISA | C29: =IFERROR(INDEX(계좌현황!C:C,INDEX($L$21:$L$95,MATCH(LARGE($N$21:$N$95,9),$N$21:$N$95,0))),"") -> 한국 | D29: =IFERROR(INDEX(계좌현황!D:D,INDEX($L$21:$L$95,MATCH(LARGE($N$21:$N$95,9),$N$21:$N$95,0))),"") -> 483280 | E29: =IFERROR(INDEX(계좌현황!E:E,INDEX($L$21:$L$95,MATCH(LARGE($N$21:$N$95,9),$N$21:$N$95,0))),"") -> KODEX 미국AI테크TOP10타겟커버드콜 | F29: =IFERROR(INDEX(계좌현황!F:F,INDEX($L$21:$L$95,MATCH(LARGE($N$21:$N$95,9),$N$21:$N$95,0))),"") -> 2226 | G29: =IFERROR(INDEX(계좌현황!K:K,INDEX($L$21:$L$95,MATCH(LARGE($N$21:$N$95,9),$N$21:$N$95,0))),0) -> 24652950 | H29: =IF($B$3=0,0,G29/$B$3) -> 0.033096237 | I29: =I28+H29 -> 0.53615679 | L29: 17 | M29: =계좌현황!K17 -> 47090700 | N29: =IF(M29="",-1E+99,M29*100000+(10000-L29)) -> 4709070009983
A30: 10 | B30: =IFERROR(INDEX(계좌현황!A:A,INDEX($L$21:$L$95,MATCH(LARGE($N$21:$N$95,10),$N$21:$N$95,0))),"") -> 개인연금1 | C30: =IFERROR(INDEX(계좌현황!C:C,INDEX($L$21:$L$95,MATCH(LARGE($N$21:$N$95,10),$N$21:$N$95,0))),"") -> 한국 | D30: =IFERROR(INDEX(계좌현황!D:D,INDEX($L$21:$L$95,MATCH(LARGE($N$21:$N$95,10),$N$21:$N$95,0))),"") -> 433330 | E30: =IFERROR(INDEX(계좌현황!E:E,INDEX($L$21:$L$95,MATCH(LARGE($N$21:$N$95,10),$N$21:$N$95,0))),"") -> SOL 미국 S&P500 | F30: =IFERROR(INDEX(계좌현황!F:F,INDEX($L$21:$L$95,MATCH(LARGE($N$21:$N$95,10),$N$21:$N$95,0))),"") -> 1061 | G30: =IFERROR(INDEX(계좌현황!K:K,INDEX($L$21:$L$95,MATCH(LARGE($N$21:$N$95,10),$N$21:$N$95,0))),0) -> 22376490 | H30: =IF($B$3=0,0,G30/$B$3) -> 0.030040122 | I30: =I29+H30 -> 0.56619691 | L30: 18 | M30: =계좌현황!K18 -> 42983000 | N30: =IF(M30="",-1E+99,M30*100000+(10000-L30)) -> 4298300009982
A31: 11 | B31: =IFERROR(INDEX(계좌현황!A:A,INDEX($L$21:$L$95,MATCH(LARGE($N$21:$N$95,11),$N$21:$N$95,0))),"") -> ISA | C31: =IFERROR(INDEX(계좌현황!C:C,INDEX($L$21:$L$95,MATCH(LARGE($N$21:$N$95,11),$N$21:$N$95,0))),"") -> 한국 | D31: =IFERROR(INDEX(계좌현황!D:D,INDEX($L$21:$L$95,MATCH(LARGE($N$21:$N$95,11),$N$21:$N$95,0))),"") -> 458760 | E31: =IFERROR(INDEX(계좌현황!E:E,INDEX($L$21:$L$95,MATCH(LARGE($N$21:$N$95,11),$N$21:$N$95,0))),"") -> TIGER 미배당다우커버드콜2호 | F31: =IFERROR(INDEX(계좌현황!F:F,INDEX($L$21:$L$95,MATCH(LARGE($N$21:$N$95,11),$N$21:$N$95,0))),"") -> 1964 | G31: =IFERROR(INDEX(계좌현황!K:K,INDEX($L$21:$L$95,MATCH(LARGE($N$21:$N$95,11),$N$21:$N$95,0))),0) -> 20818400 | H31: =IF($B$3=0,0,G31/$B$3) -> 0.027948408 | I31: =I30+H31 -> 0.59414532 | L31: 19 | M31: =계좌현황!K19 -> 17762150 | N31: =IF(M31="",-1E+99,M31*100000+(10000-L31)) -> 1776215009981
A32: 12 | B32: =IFERROR(INDEX(계좌현황!A:A,INDEX($L$21:$L$95,MATCH(LARGE($N$21:$N$95,12),$N$21:$N$95,0))),"") -> DC | C32: =IFERROR(INDEX(계좌현황!C:C,INDEX($L$21:$L$95,MATCH(LARGE($N$21:$N$95,12),$N$21:$N$95,0))),"") -> 한국 | D32: =IFERROR(INDEX(계좌현황!D:D,INDEX($L$21:$L$95,MATCH(LARGE($N$21:$N$95,12),$N$21:$N$95,0))),"") -> 468380 | E32: =IFERROR(INDEX(계좌현황!E:E,INDEX($L$21:$L$95,MATCH(LARGE($N$21:$N$95,12),$N$21:$N$95,0))),"") -> KODEX iShares미국하이일드액티브 | F32: =IFERROR(INDEX(계좌현황!F:F,INDEX($L$21:$L$95,MATCH(LARGE($N$21:$N$95,12),$N$21:$N$95,0))),"") -> 2000 | G32: =IFERROR(INDEX(계좌현황!K:K,INDEX($L$21:$L$95,MATCH(LARGE($N$21:$N$95,12),$N$21:$N$95,0))),0) -> 20310000 | H32: =IF($B$3=0,0,G32/$B$3) -> 0.027265888 | I32: =I31+H32 -> 0.62141121 | L32: 20 | M32: =계좌현황!K20 -> 22376490 | N32: =IF(M32="",-1E+99,M32*100000+(10000-L32)) -> 2237649009980
A33: 13 | B33: =IFERROR(INDEX(계좌현황!A:A,INDEX($L$21:$L$95,MATCH(LARGE($N$21:$N$95,13),$N$21:$N$95,0))),"") -> DC | C33: =IFERROR(INDEX(계좌현황!C:C,INDEX($L$21:$L$95,MATCH(LARGE($N$21:$N$95,13),$N$21:$N$95,0))),"") -> 한국 | D33: =IFERROR(INDEX(계좌현황!D:D,INDEX($L$21:$L$95,MATCH(LARGE($N$21:$N$95,13),$N$21:$N$95,0))),"") -> 329200 | E33: =IFERROR(INDEX(계좌현황!E:E,INDEX($L$21:$L$95,MATCH(LARGE($N$21:$N$95,13),$N$21:$N$95,0))),"") -> TIGER리츠부동산인프라 | F33: =IFERROR(INDEX(계좌현황!F:F,INDEX($L$21:$L$95,MATCH(LARGE($N$21:$N$95,13),$N$21:$N$95,0))),"") -> 5000 | G33: =IFERROR(INDEX(계좌현황!K:K,INDEX($L$21:$L$95,MATCH(LARGE($N$21:$N$95,13),$N$21:$N$95,0))),0) -> 20000000 | H33: =IF($B$3=0,0,G33/$B$3) -> 0.026849717 | I33: =I32+H33 -> 0.64826093 | L33: 21 | M33: =계좌현황!K21 -> 4723875 | N33: =IF(M33="",-1E+99,M33*100000+(10000-L33)) -> 472387509979
A34: 14 | B34: =IFERROR(INDEX(계좌현황!A:A,INDEX($L$21:$L$95,MATCH(LARGE($N$21:$N$95,14),$N$21:$N$95,0))),"") -> ISA | C34: =IFERROR(INDEX(계좌현황!C:C,INDEX($L$21:$L$95,MATCH(LARGE($N$21:$N$95,14),$N$21:$N$95,0))),"") -> 한국 | D34: =IFERROR(INDEX(계좌현황!D:D,INDEX($L$21:$L$95,MATCH(LARGE($N$21:$N$95,14),$N$21:$N$95,0))),"") -> 474220 | E34: =IFERROR(INDEX(계좌현황!E:E,INDEX($L$21:$L$95,MATCH(LARGE($N$21:$N$95,14),$N$21:$N$95,0))),"") -> TIGER미국테크TOP10커버드콜 | F34: =IFERROR(INDEX(계좌현황!F:F,INDEX($L$21:$L$95,MATCH(LARGE($N$21:$N$95,14),$N$21:$N$95,0))),"") -> 1350 | G34: =IFERROR(INDEX(계좌현황!K:K,INDEX($L$21:$L$95,MATCH(LARGE($N$21:$N$95,14),$N$21:$N$95,0))),0) -> 19500750 | H34: =IF($B$3=0,0,G34/$B$3) -> 0.026179481 | I34: =I33+H34 -> 0.67444041 | L34: 22 | M34: =계좌현황!K22 -> 9999730 | N34: =IF(M34="",-1E+99,M34*100000+(10000-L34)) -> 999973009978
A35: 15 | B35: =IFERROR(INDEX(계좌현황!A:A,INDEX($L$21:$L$95,MATCH(LARGE($N$21:$N$95,15),$N$21:$N$95,0))),"") -> 개인연금1 | C35: =IFERROR(INDEX(계좌현황!C:C,INDEX($L$21:$L$95,MATCH(LARGE($N$21:$N$95,15),$N$21:$N$95,0))),"") -> 한국 | D35: =IFERROR(INDEX(계좌현황!D:D,INDEX($L$21:$L$95,MATCH(LARGE($N$21:$N$95,15),$N$21:$N$95,0))),"") -> 446720 | E35: =IFERROR(INDEX(계좌현황!E:E,INDEX($L$21:$L$95,MATCH(LARGE($N$21:$N$95,15),$N$21:$N$95,0))),"") -> SOL 미국배당다우존스 | F35: =IFERROR(INDEX(계좌현황!F:F,INDEX($L$21:$L$95,MATCH(LARGE($N$21:$N$95,15),$N$21:$N$95,0))),"") -> 1330 | G35: =IFERROR(INDEX(계좌현황!K:K,INDEX($L$21:$L$95,MATCH(LARGE($N$21:$N$95,15),$N$21:$N$95,0))),0) -> 17762150 | H35: =IF($B$3=0,0,G35/$B$3) -> 0.023845435 | I35: =I34+H35 -> 0.69828584 | L35: 23 | M35: =계좌현황!K23 -> 5587985 | N35: =IF(M35="",-1E+99,M35*100000+(10000-L35)) -> 558798509977
A36: 16 | B36: =IFERROR(INDEX(계좌현황!A:A,INDEX($L$21:$L$95,MATCH(LARGE($N$21:$N$95,16),$N$21:$N$95,0))),"") -> DC | C36: =IFERROR(INDEX(계좌현황!C:C,INDEX($L$21:$L$95,MATCH(LARGE($N$21:$N$95,16),$N$21:$N$95,0))),"") -> 한국 | D36: =IFERROR(INDEX(계좌현황!D:D,INDEX($L$21:$L$95,MATCH(LARGE($N$21:$N$95,16),$N$21:$N$95,0))),"") -> 379810 | E36: =IFERROR(INDEX(계좌현황!E:E,INDEX($L$21:$L$95,MATCH(LARGE($N$21:$N$95,16),$N$21:$N$95,0))),"") -> KODEX 미국나스닥100 | F36: =IFERROR(INDEX(계좌현황!F:F,INDEX($L$21:$L$95,MATCH(LARGE($N$21:$N$95,16),$N$21:$N$95,0))),"") -> 523 | G36: =IFERROR(INDEX(계좌현황!K:K,INDEX($L$21:$L$95,MATCH(LARGE($N$21:$N$95,16),$N$21:$N$95,0))),0) -> 13454175 | H36: =IF($B$3=0,0,G36/$B$3) -> 0.01806204 | I36: =I35+H36 -> 0.71634788 | L36: 24 | M36: =계좌현황!K24 -> 24652950 | N36: =IF(M36="",-1E+99,M36*100000+(10000-L36)) -> 2465295009976
A37: 17 | B37: =IFERROR(INDEX(계좌현황!A:A,INDEX($L$21:$L$95,MATCH(LARGE($N$21:$N$95,17),$N$21:$N$95,0))),"") -> 은행예금 | C37: =IFERROR(INDEX(계좌현황!C:C,INDEX($L$21:$L$95,MATCH(LARGE($N$21:$N$95,17),$N$21:$N$95,0))),"") -> 0 | D37: =IFERROR(INDEX(계좌현황!D:D,INDEX($L$21:$L$95,MATCH(LARGE($N$21:$N$95,17),$N$21:$N$95,0))),"") -> 현금 | E37: =IFERROR(INDEX(계좌현황!E:E,INDEX($L$21:$L$95,MATCH(LARGE($N$21:$N$95,17),$N$21:$N$95,0))),"") -> 새마을 예금 | F37: =IFERROR(INDEX(계좌현황!F:F,INDEX($L$21:$L$95,MATCH(LARGE($N$21:$N$95,17),$N$21:$N$95,0))),"") -> 1 | G37: =IFERROR(INDEX(계좌현황!K:K,INDEX($L$21:$L$95,MATCH(LARGE($N$21:$N$95,17),$N$21:$N$95,0))),0) -> 13435000 | H37: =IF($B$3=0,0,G37/$B$3) -> 0.018036298 | I37: =I36+H37 -> 0.73438418 | L37: 25 | M37: =계좌현황!K25 -> 20818400 | N37: =IF(M37="",-1E+99,M37*100000+(10000-L37)) -> 2081840009975
A38: 18 | B38: =IFERROR(INDEX(계좌현황!A:A,INDEX($L$21:$L$95,MATCH(LARGE($N$21:$N$95,18),$N$21:$N$95,0))),"") -> 일반계좌 | C38: =IFERROR(INDEX(계좌현황!C:C,INDEX($L$21:$L$95,MATCH(LARGE($N$21:$N$95,18),$N$21:$N$95,0))),"") -> 한국 | D38: =IFERROR(INDEX(계좌현황!D:D,INDEX($L$21:$L$95,MATCH(LARGE($N$21:$N$95,18),$N$21:$N$95,0))),"") -> 005930 | E38: =IFERROR(INDEX(계좌현황!E:E,INDEX($L$21:$L$95,MATCH(LARGE($N$21:$N$95,18),$N$21:$N$95,0))),"") -> 삼성전자 | F38: =IFERROR(INDEX(계좌현황!F:F,INDEX($L$21:$L$95,MATCH(LARGE($N$21:$N$95,18),$N$21:$N$95,0))),"") -> 55 | G38: =IFERROR(INDEX(계좌현황!K:K,INDEX($L$21:$L$95,MATCH(LARGE($N$21:$N$95,18),$N$21:$N$95,0))),0) -> 11797500 | H38: =IF($B$3=0,0,G38/$B$3) -> 0.015837977 | I38: =I37+H38 -> 0.75022216 | L38: 26 | M38: =계좌현황!K26 -> 19500750 | N38: =IF(M38="",-1E+99,M38*100000+(10000-L38)) -> 1950075009974
A39: 19 | B39: =IFERROR(INDEX(계좌현황!A:A,INDEX($L$21:$L$95,MATCH(LARGE($N$21:$N$95,19),$N$21:$N$95,0))),"") -> IRP | C39: =IFERROR(INDEX(계좌현황!C:C,INDEX($L$21:$L$95,MATCH(LARGE($N$21:$N$95,19),$N$21:$N$95,0))),"") -> 한국 | D39: =IFERROR(INDEX(계좌현황!D:D,INDEX($L$21:$L$95,MATCH(LARGE($N$21:$N$95,19),$N$21:$N$95,0))),"") -> 438100 | E39: =IFERROR(INDEX(계좌현황!E:E,INDEX($L$21:$L$95,MATCH(LARGE($N$21:$N$95,19),$N$21:$N$95,0))),"") -> ACE미국나스닥100미국채혼합50액티브 | F39: =IFERROR(INDEX(계좌현황!F:F,INDEX($L$21:$L$95,MATCH(LARGE($N$21:$N$95,19),$N$21:$N$95,0))),"") -> 794 | G39: =IFERROR(INDEX(계좌현황!K:K,INDEX($L$21:$L$95,MATCH(LARGE($N$21:$N$95,19),$N$21:$N$95,0))),0) -> 11560640 | H39: =IF($B$3=0,0,G39/$B$3) -> 0.015519996 | I39: =I38+H39 -> 0.76574215 | L39: 27 | M39: =계좌현황!K27 -> 8381625 | N39: =IF(M39="",-1E+99,M39*100000+(10000-L39)) -> 838162509973
A40: 20 | B40: =IFERROR(INDEX(계좌현황!A:A,INDEX($L$21:$L$95,MATCH(LARGE($N$21:$N$95,20),$N$21:$N$95,0))),"") -> 일반계좌 | C40: =IFERROR(INDEX(계좌현황!C:C,INDEX($L$21:$L$95,MATCH(LARGE($N$21:$N$95,20),$N$21:$N$95,0))),"") -> 한국 | D40: =IFERROR(INDEX(계좌현황!D:D,INDEX($L$21:$L$95,MATCH(LARGE($N$21:$N$95,20),$N$21:$N$95,0))),"") -> 498400 | E40: =IFERROR(INDEX(계좌현황!E:E,INDEX($L$21:$L$95,MATCH(LARGE($N$21:$N$95,20),$N$21:$N$95,0))),"") -> KODEX 200타켓위클리커버드콜 | F40: =IFERROR(INDEX(계좌현황!F:F,INDEX($L$21:$L$95,MATCH(LARGE($N$21:$N$95,20),$N$21:$N$95,0))),"") -> 704 | G40: =IFERROR(INDEX(계좌현황!K:K,INDEX($L$21:$L$95,MATCH(LARGE($N$21:$N$95,20),$N$21:$N$95,0))),0) -> 11267520 | H40: =IF($B$3=0,0,G40/$B$3) -> 0.015126486 | I40: =I39+H40 -> 0.78086864 | L40: 28 | M40: =계좌현황!K28 -> 7228800 | N40: =IF(M40="",-1E+99,M40*100000+(10000-L40)) -> 722880009972
A41: 21 | B41: =IFERROR(INDEX(계좌현황!A:A,INDEX($L$21:$L$95,MATCH(LARGE($N$21:$N$95,21),$N$21:$N$95,0))),"") -> 개인연금2 | C41: =IFERROR(INDEX(계좌현황!C:C,INDEX($L$21:$L$95,MATCH(LARGE($N$21:$N$95,21),$N$21:$N$95,0))),"") -> 한국 | D41: =IFERROR(INDEX(계좌현황!D:D,INDEX($L$21:$L$95,MATCH(LARGE($N$21:$N$95,21),$N$21:$N$95,0))),"") -> 367380 | E41: =IFERROR(INDEX(계좌현황!E:E,INDEX($L$21:$L$95,MATCH(LARGE($N$21:$N$95,21),$N$21:$N$95,0))),"") -> ACE 미국나스닥100 | F41: =IFERROR(INDEX(계좌현황!F:F,INDEX($L$21:$L$95,MATCH(LARGE($N$21:$N$95,21),$N$21:$N$95,0))),"") -> 338 | G41: =IFERROR(INDEX(계좌현황!K:K,INDEX($L$21:$L$95,MATCH(LARGE($N$21:$N$95,21),$N$21:$N$95,0))),0) -> 9999730 | H41: =IF($B$3=0,0,G41/$B$3) -> 0.013424496 | I41: =I40+H41 -> 0.79429314 | L41: 29 | M41: =계좌현황!K29 -> 3699200 | N41: =IF(M41="",-1E+99,M41*100000+(10000-L41)) -> 369920009971
A42: 22 | B42: =IFERROR(INDEX(계좌현황!A:A,INDEX($L$21:$L$95,MATCH(LARGE($N$21:$N$95,22),$N$21:$N$95,0))),"") -> IRP | C42: =IFERROR(INDEX(계좌현황!C:C,INDEX($L$21:$L$95,MATCH(LARGE($N$21:$N$95,22),$N$21:$N$95,0))),"") -> 한국 | D42: =IFERROR(INDEX(계좌현황!D:D,INDEX($L$21:$L$95,MATCH(LARGE($N$21:$N$95,22),$N$21:$N$95,0))),"") -> 133690 | E42: =IFERROR(INDEX(계좌현황!E:E,INDEX($L$21:$L$95,MATCH(LARGE($N$21:$N$95,22),$N$21:$N$95,0))),"") -> TIGER 미국나스닥100 | F42: =IFERROR(INDEX(계좌현황!F:F,INDEX($L$21:$L$95,MATCH(LARGE($N$21:$N$95,22),$N$21:$N$95,0))),"") -> 57 | G42: =IFERROR(INDEX(계좌현황!K:K,INDEX($L$21:$L$95,MATCH(LARGE($N$21:$N$95,22),$N$21:$N$95,0))),0) -> 9804000 | H42: =IF($B$3=0,0,G42/$B$3) -> 0.013161731 | I42: =I41+H42 -> 0.80745487 | L42: 30 | M42: =계좌현황!K30 -> 3746655 | N42: =IF(M42="",-1E+99,M42*100000+(10000-L42)) -> 374665509970
A43: 23 | B43: =IFERROR(INDEX(계좌현황!A:A,INDEX($L$21:$L$95,MATCH(LARGE($N$21:$N$95,23),$N$21:$N$95,0))),"") -> IRP | C43: =IFERROR(INDEX(계좌현황!C:C,INDEX($L$21:$L$95,MATCH(LARGE($N$21:$N$95,23),$N$21:$N$95,0))),"") -> 한국 | D43: =IFERROR(INDEX(계좌현황!D:D,INDEX($L$21:$L$95,MATCH(LARGE($N$21:$N$95,23),$N$21:$N$95,0))),"") -> 381170 | E43: =IFERROR(INDEX(계좌현황!E:E,INDEX($L$21:$L$95,MATCH(LARGE($N$21:$N$95,23),$N$21:$N$95,0))),"") -> TIGER 미국테크TOP10 INDXX | F43: =IFERROR(INDEX(계좌현황!F:F,INDEX($L$21:$L$95,MATCH(LARGE($N$21:$N$95,23),$N$21:$N$95,0))),"") -> 323 | G43: =IFERROR(INDEX(계좌현황!K:K,INDEX($L$21:$L$95,MATCH(LARGE($N$21:$N$95,23),$N$21:$N$95,0))),0) -> 9725530 | H43: =IF($B$3=0,0,G43/$B$3) -> 0.013056387 | I43: =I42+H43 -> 0.82051126 | L43: 31 | M43: =계좌현황!K31 -> 5579600 | N43: =IF(M43="",-1E+99,M43*100000+(10000-L43)) -> 557960009969
...

Sheet IMPORTXML함수
C24: https://finance.naver.com/item/sise.naver?code=
C25: //html/body/div[3]/div[2]/div[2]/div[1]/div[3]/div[1]/table/tbody/tr[1]/td[1]/strong

Sheet 올해수익률 계산시트
Q2: KOSPI | R2: INDEXSP:.INX | S2: INDEXNASDAQ:.IXIC | U2: GCW00 | V2: BTCusd | W2: USDKRW
G3: 날짜 | H3: 계좌총액 | I3: 코스피 | J3: S&P500 | K3: 나스닥 | L3: 골드(1온스) | M3: 비트코인(달러) | Q3: 코스피 | R3: S&P500 | S3: 나스닥 | U3: 골드(1온스) | V3: 비트코인-달러 | W3: 달러환율 | X3: S&P500 (달러환율) | Y3: 나스닥 (달러환율) | Z3: 골드 (달러환율) | AA3: 비트코인 (달러환율) | AC3: 달러환율 | AD3: S&P500 (달러환율) | AE3: 나스닥 (달러환율) | AF3: 골드 (달러환율) | AG3: 비트코인 (달러환율)
B4: =VALUE(MID(G4,1,2)) -> 17 | C4: =VALUE(MID(G4,4,2)) -> 12 | D4: =IF(F4="12월",(E4+1)&VLOOKUP(F4,인덱스!$C:$D,2,0),E4&VLOOKUP(F4,인덱스!$C:$D,2,0)) -> 20181 | E4: ="20"&MID(G4,1,2) -> 2017 | F4: =VLOOKUP(RIGHT(G4,2),인덱스!B:D,2,0) -> 12월 | G4: 17.12 | H4: 0 | I4: 100 | J4: 100 | K4: 100 | L4: 100 | M4: 100 | Q4: =IFERROR(__xludf.DUMMYFUNCTION("iferror(index('지수RAW'!$V$7:$V$12040,MATCH($D4,'지수RAW'!$R$7:$R$12040,0)-1,1),GOOGLEFINANCE(Q$2))"),2467.49) -> 2467.49 | R4: =IFERROR(__xludf.DUMMYFUNCTION("iferror(index('지수RAW'!$F$7:$F$12040,MATCH($D4,'지수RAW'!$B$7:$B$12040,0)-1,1),GOOGLEFINANCE(R$2))"),2673.61) -> 2673.61 | S4: =IFERROR(__xludf.DUMMYFUNCTION("iferror(index('지수RAW'!$N$7:$N$12040,MATCH($D4,'지수RAW'!$J$7:$J$12040,0)-1,1),GOOGLEFINANCE(S$2))"),6903.39) -> 6903.39 | U4: {=IFERROR(INDEX(지수RAW!$AT$7:$AT$12040,MATCH($D4,지수RAW!$AP$7:$AP$12040,0)-1,1),지수RAW!$AU$4)} -> 1309.3 | V4: =IFERROR(__xludf.DUMMYFUNCTION("iferror(index('지수RAW'!$AL$7:$AL$12040,MATCH($D4,'지수RAW'!$AH$7:$AH$12040,0)-1,1),GOOGLEFINANCE(V$2))"),13880.99) -> 13880.99 | W4: =IFERROR(__xludf.DUMMYFUNCTION("iferror(index('지수RAW'!$AD$7:$AD$12040,MATCH($D4,'지수RAW'!$Z$7:$Z$12040,0)-1,1),GOOGLEFINANCE(W$2))"),1066.07) -> 1066.07 | X4: =$W4*R4 -> 2850255.4 | Y4: =$W4*S4 -> 7359497 | Z4: =$W4*U4 -> 1395805.5 | AA4: =$W4*V4 -> 14798107 | AC4: 100 | AD4: 100 | AE4: 100 | AF4: 100 | AG4: 100
B5: =IF(C4=12,B4+1,B4) -> 18 | C5: =IF(C4=12,1,C4+1) -> 1 | D5: =IF(F5="12월",(E5+1)&VLOOKUP(F5,인덱스!$C:$D,2,0),E5&VLOOKUP(F5,인덱스!$C:$D,2,0)) -> 20182 | E5: ="20"&B5 -> 2018 | F5: =C5&"월" -> 1월 | G5: =B5&"."&VLOOKUP(F5,인덱스!$A:$B,2,0) -> 18.01 | H5: =IFERROR(VLOOKUP(G5,#REF!,2,0),) -> 0 | I5: =IF(Q5="","",I4*(Q5/Q4)) -> 104.01096 | J5: =IF(R5="","",J4*(R5/R4)) -> 105.61787 | K5: =IF(S5="","",K4*(S5/S4)) -> 107.36001 | L5: =IF(U5="","",L4*(U5/U4)) -> 102.58153 | M5: =IF(V5="","",M4*(V5/V4)) -> 72.203135 | Q5: =IFERROR(__xludf.DUMMYFUNCTION("iferror(index('지수RAW'!$V$7:$V$12040,MATCH($D5,'지수RAW'!$R$7:$R$12040,0)-1,1),GOOGLEFINANCE(Q$2))"),2566.46) -> 2566.46 | R5: =IFERROR(__xludf.DUMMYFUNCTION("iferror(index('지수RAW'!$F$7:$F$12040,MATCH($D5,'지수RAW'!$B$7:$B$12040,0)-1,1),GOOGLEFINANCE(R$2))"),2823.81) -> 2823.81 | S5: =IFERROR(__xludf.DUMMYFUNCTION("iferror(index('지수RAW'!$N$7:$N$12040,MATCH($D5,'지수RAW'!$J$7:$J$12040,0)-1,1),GOOGLEFINANCE(S$2))"),7411.48) -> 7411.48 | U5: {=IFERROR(INDEX(지수RAW!$AT$7:$AT$12040,MATCH($D5,지수RAW!$AP$7:$AP$12040,0)-1,1),지수RAW!$AU$4)} -> 1343.1 | V5: =IFERROR(__xludf.DUMMYFUNCTION("iferror(index('지수RAW'!$AL$7:$AL$12040,MATCH($D5,'지수RAW'!$AH$7:$AH$12040,0)-1,1),GOOGLEFINANCE(V$2))"),10022.51) -> 10022.51 | W5: =IFERROR(__xludf.DUMMYFUNCTION("iferror(index('지수RAW'!$AD$7:$AD$12040,MATCH($D5,'지수RAW'!$Z$7:$Z$12040,0)-1,1),GOOGLEFINANCE(W$2))"),1069.02) -> 1069.02 | X5: =$W5*R5 -> 3018709.4 | Y5: =$W5*S5 -> 7923020.3 | Z5: =$W5*U5 -> 1435800.8 | AA5: =$W5*V5 -> 10714264 | AC5: =IF(Q5="","",AC4*(W5/W4)) -> 100.27672 | AD5: =IF(R5="","",AD4*(X5/X4)) -> 105.91014 | AE5: =IF(S5="","",AE4*(Y5/Y4)) -> 107.65709 | AF5: =IF(U5="","",AF4*(Z5/Z4)) -> 102.86539 | AG5: =IF(V5="","",AG4*(AA5/AA4)) -> 72.402934
B6: =IF(C5=12,B5+1,B5) -> 18 | C6: =IF(C5=12,1,C5+1) -> 2 | D6: =IF(F6="12월",(E6+1)&VLOOKUP(F6,인덱스!$C:$D,2,0),E6&VLOOKUP(F6,인덱스!$C:$D,2,0)) -> 20183 | E6: ="20"&B6 -> 2018 | F6: =C6&"월" -> 2월 | G6: =B6&"."&VLOOKUP(F6,인덱스!$A:$B,2,0) -> 18.02 | H6: =IFERROR(VLOOKUP(G6,#REF!,2,0),) -> 0 | I6: =IF(Q6="","",I5*(Q6/Q5)) -> 98.373651 | J6: =IF(R6="","",J5*(R6/R5)) -> 101.50433 | K6: =IF(S6="","",K5*(S6/S5)) -> 105.35418 | L6: =IF(U6="","",L5*(U6/U5)) -> 100.65684 | M6: =IF(V6="","",M5*(V6/V5)) -> 75.949554 | Q6: =IFERROR(__xludf.DUMMYFUNCTION("iferror(index('지수RAW'!$V$7:$V$12040,MATCH($D6,'지수RAW'!$R$7:$R$12040,0)-1,1),GOOGLEFINANCE(Q$2))"),2427.36) -> 2427.36 | R6: =IFERROR(__xludf.DUMMYFUNCTION("iferror(index('지수RAW'!$F$7:$F$12040,MATCH($D6,'지수RAW'!$B$7:$B$12040,0)-1,1),GOOGLEFINANCE(R$2))"),2713.83) -> 2713.83 | S6: =IFERROR(__xludf.DUMMYFUNCTION("iferror(index('지수RAW'!$N$7:$N$12040,MATCH($D6,'지수RAW'!$J$7:$J$12040,0)-1,1),GOOGLEFINANCE(S$2))"),7273.01) -> 7273.01 | U6: {=IFERROR(INDEX(지수RAW!$AT$7:$AT$12040,MATCH($D6,지수RAW!$AP$7:$AP$12040,0)-1,1),지수RAW!$AU$4)} -> 1317.9 | V6: =IFERROR(__xludf.DUMMYFUNCTION("iferror(index('지수RAW'!$AL$7:$AL$12040,MATCH($D6,'지수RAW'!$AH$7:$AH$12040,0)-1,1),GOOGLEFINANCE(V$2))"),10542.55) -> 10542.55 | W6: =IFERROR(__xludf.DUMMYFUNCTION("iferror(index('지수RAW'!$AD$7:$AD$12040,MATCH($D6,'지수RAW'!$Z$7:$Z$12040,0)-1,1),GOOGLEFINANCE(W$2))"),1085.35) -> 1085.35 | X6: =$W6*R6 -> 2945455.4 | Y6: =$W6*S6 -> 7893761.4 | Z6: =$W6*U6 -> 1430382.8 | AA6: =$W6*V6 -> 11442357 | AC6: =IF(Q6="","",AC5*(W6/W5)) -> 101.80851 | AD6: =IF(R6="","",AD5*(X6/X5)) -> 103.34005 | AE6: =IF(S6="","",AE5*(Y6/Y5)) -> 107.25952 | AF6: =IF(U6="","",AF5*(Z6/Z5)) -> 102.47723 | AG6: =IF(V6="","",AG5*(AA6/AA5)) -> 77.323111
B7: =IF(C6=12,B6+1,B6) -> 18 | C7: =IF(C6=12,1,C6+1) -> 3 | D7: =IF(F7="12월",(E7+1)&VLOOKUP(F7,인덱스!$C:$D,2,0),E7&VLOOKUP(F7,인덱스!$C:$D,2,0)) -> 20184 | E7: ="20"&B7 -> 2018 | F7: =C7&"월" -> 3월 | G7: =B7&"."&VLOOKUP(F7,인덱스!$A:$B,2,0) -> 18.03 | H7: =IFERROR(VLOOKUP(G7,#REF!,2,0),) -> 0 | I7: =IF(Q7="","",I6*(Q7/Q6)) -> 99.122995 | J7: =IF(R7="","",J6*(R7/R6)) -> 98.775438 | K7: =IF(S7="","",K6*(S7/S6)) -> 102.31857 | L7: =IF(U7="","",L6*(U7/U6)) -> 101.37478 | M7: =IF(V7="","",M6*(V7/V6)) -> 49.903357 | Q7: =IFERROR(__xludf.DUMMYFUNCTION("iferror(index('지수RAW'!$V$7:$V$12040,MATCH($D7,'지수RAW'!$R$7:$R$12040,0)-1,1),GOOGLEFINANCE(Q$2))"),2445.85) -> 2445.85 | R7: =IFERROR(__xludf.DUMMYFUNCTION("iferror(index('지수RAW'!$F$7:$F$12040,MATCH($D7,'지수RAW'!$B$7:$B$12040,0)-1,1),GOOGLEFINANCE(R$2))"),2640.87) -> 2640.87 | S7: =IFERROR(__xludf.DUMMYFUNCTION("iferror(index('지수RAW'!$N$7:$N$12040,MATCH($D7,'지수RAW'!$J$7:$J$12040,0)-1,1),GOOGLEFINANCE(S$2))"),7063.45) -> 7063.45 | U7: {=IFERROR(INDEX(지수RAW!$AT$7:$AT$12040,MATCH($D7,지수RAW!$AP$7:$AP$12040,0)-1,1),지수RAW!$AU$4)} -> 1327.3 | V7: =IFERROR(__xludf.DUMMYFUNCTION("iferror(index('지수RAW'!$AL$7:$AL$12040,MATCH($D7,'지수RAW'!$AH$7:$AH$12040,0)-1,1),GOOGLEFINANCE(V$2))"),6927.08) -> 6927.08 | W7: =IFERROR(__xludf.DUMMYFUNCTION("iferror(index('지수RAW'!$AD$7:$AD$12040,MATCH($D7,'지수RAW'!$Z$7:$Z$12040,0)-1,1),GOOGLEFINANCE(W$2))"),1059.55) -> 1059.55 | X7: =$W7*R7 -> 2798133.8 | Y7: =$W7*S7 -> 7484078.4 | Z7: =$W7*U7 -> 1406340.7 | AA7: =$W7*V7 -> 7339587.6 | AC7: =IF(Q7="","",AC6*(W7/W6)) -> 99.388408 | AD7: =IF(R7="","",AD6*(X7/X6)) -> 98.171336 | AE7: =IF(S7="","",AE6*(Y7/Y6)) -> 101.6928 | AF7: =IF(U7="","",AF6*(Z7/Z6)) -> 100.75478 | AG7: =IF(V7="","",AG6*(AA7/AA6)) -> 49.598152
B8: =IF(C7=12,B7+1,B7) -> 18 | C8: =IF(C7=12,1,C7+1) -> 4 | D8: =IF(F8="12월",(E8+1)&VLOOKUP(F8,인덱스!$C:$D,2,0),E8&VLOOKUP(F8,인덱스!$C:$D,2,0)) -> 20185 | E8: ="20"&B8 -> 2018 | F8: =C8&"월" -> 4월 | G8: =B8&"."&VLOOKUP(F8,인덱스!$A:$B,2,0) -> 18.04 | H8: =IFERROR(VLOOKUP(G8,#REF!,2,0),) -> 0 | I8: =IF(Q8="","",I7*(Q8/Q7)) -> 101.94084 | J8: =IF(R8="","",J7*(R8/R7)) -> 99.043989 | K8: =IF(S8="","",K7*(S8/S7)) -> 102.35942 | L8: =IF(U8="","",L7*(U8/U7)) -> 100.75613 | M8: =IF(V8="","",M7*(V8/V7)) -> 66.503038 | Q8: =IFERROR(__xludf.DUMMYFUNCTION("iferror(index('지수RAW'!$V$7:$V$12040,MATCH($D8,'지수RAW'!$R$7:$R$12040,0)-1,1),GOOGLEFINANCE(Q$2))"),2515.38) -> 2515.38 | R8: =IFERROR(__xludf.DUMMYFUNCTION("iferror(index('지수RAW'!$F$7:$F$12040,MATCH($D8,'지수RAW'!$B$7:$B$12040,0)-1,1),GOOGLEFINANCE(R$2))"),2648.05) -> 2648.05 | S8: =IFERROR(__xludf.DUMMYFUNCTION("iferror(index('지수RAW'!$N$7:$N$12040,MATCH($D8,'지수RAW'!$J$7:$J$12040,0)-1,1),GOOGLEFINANCE(S$2))"),7066.27) -> 7066.27 | U8: {=IFERROR(INDEX(지수RAW!$AT$7:$AT$12040,MATCH($D8,지수RAW!$AP$7:$AP$12040,0)-1,1),지수RAW!$AU$4)} -> 1319.2 | V8: =IFERROR(__xludf.DUMMYFUNCTION("iferror(index('지수RAW'!$AL$7:$AL$12040,MATCH($D8,'지수RAW'!$AH$7:$AH$12040,0)-1,1),GOOGLEFINANCE(V$2))"),9231.28) -> 9231.28 | W8: =IFERROR(__xludf.DUMMYFUNCTION("iferror(index('지수RAW'!$AD$7:$AD$12040,MATCH($D8,'지수RAW'!$Z$7:$Z$12040,0)-1,1),GOOGLEFINANCE(W$2))"),1069.45) -> 1069.45 | X8: =$W8*R8 -> 2831957.1 | Y8: =$W8*S8 -> 7557022.5 | Z8: =$W8*U8 -> 1410818.4 | AA8: =$W8*V8 -> 9872392.4 | AC8: =IF(Q8="","",AC7*(W8/W7)) -> 100.31705 | AD8: =IF(R8="","",AD7*(X8/X7)) -> 99.358011 | AE8: =IF(S8="","",AE7*(Y8/Y7)) -> 102.68395 | AF8: =IF(U8="","",AF7*(Z8/Z7)) -> 101.07558 | AG8: =IF(V8="","",AG7*(AA8/AA7)) -> 66.713887
B9: =IF(C8=12,B8+1,B8) -> 18 | C9: =IF(C8=12,1,C8+1) -> 5 | D9: =IF(F9="12월",(E9+1)&VLOOKUP(F9,인덱스!$C:$D,2,0),E9&VLOOKUP(F9,인덱스!$C:$D,2,0)) -> 20186 | E9: ="20"&B9 -> 2018 | F9: =C9&"월" -> 5월 | G9: =B9&"."&VLOOKUP(F9,인덱스!$A:$B,2,0) -> 18.05 | H9: =IFERROR(VLOOKUP(G9,#REF!,2,0),) -> 0 | I9: =IF(Q9="","",I8*(Q9/Q8)) -> 98.197358 | J9: =IF(R9="","",J8*(R9/R8)) -> 101.18417 | K9: =IF(S9="","",K8*(S9/S8)) -> 107.80385 | L9: =IF(U9="","",L8*(U9/U8)) -> 99.648667 | M9: =IF(V9="","",M8*(V9/V8)) -> 52.722248 | Q9: =IFERROR(__xludf.DUMMYFUNCTION("iferror(index('지수RAW'!$V$7:$V$12040,MATCH($D9,'지수RAW'!$R$7:$R$12040,0)-1,1),GOOGLEFINANCE(Q$2))"),2423.01) -> 2423.01 | R9: =IFERROR(__xludf.DUMMYFUNCTION("iferror(index('지수RAW'!$F$7:$F$12040,MATCH($D9,'지수RAW'!$B$7:$B$12040,0)-1,1),GOOGLEFINANCE(R$2))"),2705.27) -> 2705.27 | S9: =IFERROR(__xludf.DUMMYFUNCTION("iferror(index('지수RAW'!$N$7:$N$12040,MATCH($D9,'지수RAW'!$J$7:$J$12040,0)-1,1),GOOGLEFINANCE(S$2))"),7442.12) -> 7442.12 | U9: {=IFERROR(INDEX(지수RAW!$AT$7:$AT$12040,MATCH($D9,지수RAW!$AP$7:$AP$12040,0)-1,1),지수RAW!$AU$4)} -> 1304.7 | V9: =IFERROR(__xludf.DUMMYFUNCTION("iferror(index('지수RAW'!$AL$7:$AL$12040,MATCH($D9,'지수RAW'!$AH$7:$AH$12040,0)-1,1),GOOGLEFINANCE(V$2))"),7318.37) -> 7318.37 | W9: =IFERROR(__xludf.DUMMYFUNCTION("iferror(index('지수RAW'!$AD$7:$AD$12040,MATCH($D9,'지수RAW'!$Z$7:$Z$12040,0)-1,1),GOOGLEFINANCE(W$2))"),1079.95) -> 1079.95 | X9: =$W9*R9 -> 2921556.3 | Y9: =$W9*S9 -> 8037117.5 | Z9: =$W9*U9 -> 1409010.8 | AA9: =$W9*V9 -> 7903473.7 | AC9: =IF(Q9="","",AC8*(W9/W8)) -> 101.30198 | AD9: =IF(R9="","",AD8*(X9/X8)) -> 102.50156 | AE9: =IF(S9="","",AE8*(Y9/Y8)) -> 109.20743 | AF9: =IF(U9="","",AF8*(Z9/Z8)) -> 100.94607 | AG9: =IF(V9="","",AG8*(AA9/AA8)) -> 53.40868
B10: =IF(C9=12,B9+1,B9) -> 18 | C10: =IF(C9=12,1,C9+1) -> 6 | D10: =IF(F10="12월",(E10+1)&VLOOKUP(F10,인덱스!$C:$D,2,0),E10&VLOOKUP(F10,인덱스!$C:$D,2,0)) -> 20187 | E10: ="20"&B10 -> 2018 | F10: =C10&"월" -> 6월 | G10: =B10&"."&VLOOKUP(F10,인덱스!$A:$B,2,0) -> 18.06 | H10: =IFERROR(VLOOKUP(G10,#REF!,2,0),) -> 0 | I10: =IF(Q10="","",I9*(Q10/Q9)) -> 94.271101 | J10: =IF(R10="","",J9*(R10/R9)) -> 101.67414 | K10: =IF(S10="","",K9*(S10/S9)) -> 108.79148 | L10: =IF(U10="","",L9*(U10/U9)) -> 95.814557 | M10: =IF(V10="","",M9*(V10/V9)) -> 46.014513 | Q10: =IFERROR(__xludf.DUMMYFUNCTION("iferror(index('지수RAW'!$V$7:$V$12040,MATCH($D10,'지수RAW'!$R$7:$R$12040,0)-1,1),GOOGLEFINANCE(Q$2))"),2326.13) -> 2326.13 | R10: =IFERROR(__xludf.DUMMYFUNCTION("iferror(index('지수RAW'!$F$7:$F$12040,MATCH($D10,'지수RAW'!$B$7:$B$12040,0)-1,1),GOOGLEFINANCE(R$2))"),2718.37) -> 2718.37 | S10: =IFERROR(__xludf.DUMMYFUNCTION("iferror(index('지수RAW'!$N$7:$N$12040,MATCH($D10,'지수RAW'!$J$7:$J$12040,0)-1,1),GOOGLEFINANCE(S$2))"),7510.3) -> 7510.3 | U10: {=IFERROR(INDEX(지수RAW!$AT$7:$AT$12040,MATCH($D10,지수RAW!$AP$7:$AP$12040,0)-1,1),지수RAW!$AU$4)} -> 1254.5 | V10: =IFERROR(__xludf.DUMMYFUNCTION("iferror(index('지수RAW'!$AL$7:$AL$12040,MATCH($D10,'지수RAW'!$AH$7:$AH$12040,0)-1,1),GOOGLEFINANCE(V$2))"),6387.27) -> 6387.27 | W10: =IFERROR(__xludf.DUMMYFUNCTION("iferror(index('지수RAW'!$AD$7:$AD$12040,MATCH($D10,'지수RAW'!$Z$7:$Z$12040,0)-1,1),GOOGLEFINANCE(W$2))"),1113.92) -> 1113.92 | X10: =$W10*R10 -> 3028046.7 | Y10: =$W10*S10 -> 8365873.4 | Z10: =$W10*U10 -> 1397412.6 | AA10: =$W10*V10 -> 7114907.8 | AC10: =IF(Q10="","",AC9*(W10/W9)) -> 104.48845 | AD10: =IF(R10="","",AD9*(X10/X9)) -> 106.23773 | AE10: =IF(S10="","",AE9*(Y10/Y9)) -> 113.67453 | AF10: =IF(U10="","",AF9*(Z10/Z9)) -> 100.11514 | AG10: =IF(V10="","",AG9*(AA10/AA9)) -> 48.079851
B11: =IF(C10=12,B10+1,B10) -> 18 | C11: =IF(C10=12,1,C10+1) -> 7 | D11: =IF(F11="12월",(E11+1)&VLOOKUP(F11,인덱스!$C:$D,2,0),E11&VLOOKUP(F11,인덱스!$C:$D,2,0)) -> 20188 | E11: ="20"&B11 -> 2018 | F11: =C11&"월" -> 7월 | G11: =B11&"."&VLOOKUP(F11,인덱스!$A:$B,2,0) -> 18.07 | H11: =IFERROR(VLOOKUP(G11,#REF!,2,0),) -> 0 | I11: =IF(Q11="","",I10*(Q11/Q10)) -> 93.020033 | J11: =IF(R11="","",J10*(R11/R10)) -> 105.3366 | K11: =IF(S11="","",K10*(S11/S10)) -> 111.13076 | L11: =IF(U11="","",L10*(U11/U10)) -> 94.218285 | M11: =IF(V11="","",M10*(V11/V10)) -> 55.733201 | Q11: =IFERROR(__xludf.DUMMYFUNCTION("iferror(index('지수RAW'!$V$7:$V$12040,MATCH($D11,'지수RAW'!$R$7:$R$12040,0)-1,1),GOOGLEFINANCE(Q$2))"),2295.26) -> 2295.26 | R11: =IFERROR(__xludf.DUMMYFUNCTION("iferror(index('지수RAW'!$F$7:$F$12040,MATCH($D11,'지수RAW'!$B$7:$B$12040,0)-1,1),GOOGLEFINANCE(R$2))"),2816.29) -> 2816.29 | S11: =IFERROR(__xludf.DUMMYFUNCTION("iferror(index('지수RAW'!$N$7:$N$12040,MATCH($D11,'지수RAW'!$J$7:$J$12040,0)-1,1),GOOGLEFINANCE(S$2))"),7671.79) -> 7671.79 | U11: {=IFERROR(INDEX(지수RAW!$AT$7:$AT$12040,MATCH($D11,지수RAW!$AP$7:$AP$12040,0)-1,1),지수RAW!$AU$4)} -> 1233.6 | V11: =IFERROR(__xludf.DUMMYFUNCTION("iferror(index('지수RAW'!$AL$7:$AL$12040,MATCH($D11,'지수RAW'!$AH$7:$AH$12040,0)-1,1),GOOGLEFINANCE(V$2))"),7736.32) -> 7736.32 | W11: =IFERROR(__xludf.DUMMYFUNCTION("iferror(index('지수RAW'!$AD$7:$AD$12040,MATCH($D11,'지수RAW'!$Z$7:$Z$12040,0)-1,1),GOOGLEFINANCE(W$2))"),1112.2) -> 1112.2 | X11: =$W11*R11 -> 3132277.7 | Y11: =$W11*S11 -> 8532564.8 | Z11: =$W11*U11 -> 1372009.9 | AA11: =$W11*V11 -> 8604335.1 | AC11: =IF(Q11="","",AC10*(W11/W10)) -> 104.32711 | AD11: =IF(R11="","",AD10*(X11/X10)) -> 109.89463 | AE11: =IF(S11="","",AE10*(Y11/Y10)) -> 115.93951 | AF11: =IF(U11="","",AF10*(Z11/Z10)) -> 98.295211 | AG11: =IF(V11="","",AG10*(AA11/AA10)) -> 58.144836
B12: =IF(C11=12,B11+1,B11) -> 18 | C12: =IF(C11=12,1,C11+1) -> 8 | D12: =IF(F12="12월",(E12+1)&VLOOKUP(F12,인덱스!$C:$D,2,0),E12&VLOOKUP(F12,인덱스!$C:$D,2,0)) -> 20189 | E12: ="20"&B12 -> 2018 | F12: =C12&"월" -> 8월 | G12: =B12&"."&VLOOKUP(F12,인덱스!$A:$B,2,0) -> 18.08 | H12: =IFERROR(VLOOKUP(G12,#REF!,2,0),) -> 0 | I12: =IF(Q12="","",I11*(Q12/Q11)) -> 94.139389 | J12: =IF(R12="","",J11*(R12/R11)) -> 108.52443 | K12: =IF(S12="","",K11*(S12/S11)) -> 117.47185 | L12: =IF(U12="","",L11*(U12/U11)) -> 92.163752 | M12: =IF(V12="","",M11*(V12/V11)) -> 50.517002 | Q12: =IFERROR(__xludf.DUMMYFUNCTION("iferror(index('지수RAW'!$V$7:$V$12040,MATCH($D12,'지수RAW'!$R$7:$R$12040,0)-1,1),GOOGLEFINANCE(Q$2))"),2322.88) -> 2322.88 | R12: =IFERROR(__xludf.DUMMYFUNCTION("iferror(index('지수RAW'!$F$7:$F$12040,MATCH($D12,'지수RAW'!$B$7:$B$12040,0)-1,1),GOOGLEFINANCE(R$2))"),2901.52) -> 2901.52 | S12: =IFERROR(__xludf.DUMMYFUNCTION("iferror(index('지수RAW'!$N$7:$N$12040,MATCH($D12,'지수RAW'!$J$7:$J$12040,0)-1,1),GOOGLEFINANCE(S$2))"),8109.54) -> 8109.54 | U12: {=IFERROR(INDEX(지수RAW!$AT$7:$AT$12040,MATCH($D12,지수RAW!$AP$7:$AP$12040,0)-1,1),지수RAW!$AU$4)} -> 1206.7 | V12: =IFERROR(__xludf.DUMMYFUNCTION("iferror(index('지수RAW'!$AL$7:$AL$12040,MATCH($D12,'지수RAW'!$AH$7:$AH$12040,0)-1,1),GOOGLEFINANCE(V$2))"),7012.26) -> 7012.26 | W12: =IFERROR(__xludf.DUMMYFUNCTION("iferror(index('지수RAW'!$AD$7:$AD$12040,MATCH($D12,'지수RAW'!$Z$7:$Z$12040,0)-1,1),GOOGLEFINANCE(W$2))"),1114.64) -> 1114.64 | X12: =$W12*R12 -> 3234150.3 | Y12: =$W12*S12 -> 9039217.7 | Z12: =$W12*U12 -> 1345036.1 | AA12: =$W12*V12 -> 7816145.5 | AC12: =IF(Q12="","",AC11*(W12/W11)) -> 104.55599 | AD12: =IF(R12="","",AD11*(X12/X11)) -> 113.46879 | AE12: =IF(S12="","",AE11*(Y12/Y11)) -> 122.82385 | AF12: =IF(U12="","",AF11*(Z12/Z11)) -> 96.362719 | AG12: =IF(V12="","",AG11*(AA12/AA11)) -> 52.81855
B13: =IF(C12=12,B12+1,B12) -> 18 | C13: =IF(C12=12,1,C12+1) -> 9 | D13: =IF(F13="12월",(E13+1)&VLOOKUP(F13,인덱스!$C:$D,2,0),E13&VLOOKUP(F13,인덱스!$C:$D,2,0)) -> 201810 | E13: ="20"&B13 -> 2018 | F13: =C13&"월" -> 9월 | G13: =B13&"."&VLOOKUP(F13,인덱스!$A:$B,2,0) -> 18.09 | H13: =IFERROR(VLOOKUP(G13,#REF!,2,0),) -> 0 | I13: =IF(Q13="","",I12*(Q13/Q12)) -> 94.957629 | J13: =IF(R13="","",J12*(R13/R12)) -> 108.99047 | K13: =IF(S13="","",K12*(S13/S12)) -> 116.5565 | L13: =IF(U13="","",L12*(U13/U12)) -> 91.361796 | M13: =IF(V13="","",M12*(V13/V12)) -> 47.68219 | Q13: =IFERROR(__xludf.DUMMYFUNCTION("iferror(index('지수RAW'!$V$7:$V$12040,MATCH($D13,'지수RAW'!$R$7:$R$12040,0)-1,1),GOOGLEFINANCE(Q$2))"),2343.07) -> 2343.07 | R13: =IFERROR(__xludf.DUMMYFUNCTION("iferror(index('지수RAW'!$F$7:$F$12040,MATCH($D13,'지수RAW'!$B$7:$B$12040,0)-1,1),GOOGLEFINANCE(R$2))"),2913.98) -> 2913.98 | S13: =IFERROR(__xludf.DUMMYFUNCTION("iferror(index('지수RAW'!$N$7:$N$12040,MATCH($D13,'지수RAW'!$J$7:$J$12040,0)-1,1),GOOGLEFINANCE(S$2))"),8046.35) -> 8046.35 | U13: {=IFERROR(INDEX(지수RAW!$AT$7:$AT$12040,MATCH($D13,지수RAW!$AP$7:$AP$12040,0)-1,1),지수RAW!$AU$4)} -> 1196.2 | V13: =IFERROR(__xludf.DUMMYFUNCTION("iferror(index('지수RAW'!$AL$7:$AL$12040,MATCH($D13,'지수RAW'!$AH$7:$AH$12040,0)-1,1),GOOGLEFINANCE(V$2))"),6618.76) -> 6618.76 | W13: =IFERROR(__xludf.DUMMYFUNCTION("iferror(index('지수RAW'!$AD$7:$AD$12040,MATCH($D13,'지수RAW'!$Z$7:$Z$12040,0)-1,1),GOOGLEFINANCE(W$2))"),1109.01) -> 1109.01 | X13: =$W13*R13 -> 3231633 | Y13: =$W13*S13 -> 8923482.6 | Z13: =$W13*U13 -> 1326597.8 | AA13: =$W13*V13 -> 7340271 | AC13: =IF(Q13="","",AC12*(W13/W12)) -> 104.02788 | AD13: =IF(R13="","",AD12*(X13/X12)) -> 113.38047 | AE13: =IF(S13="","",AE12*(Y13/Y12)) -> 121.25126 | AF13: =IF(U13="","",AF12*(Z13/Z12)) -> 95.041738 | AG13: =IF(V13="","",AG12*(AA13/AA12)) -> 49.60277
B14: =IF(C13=12,B13+1,B13) -> 18 | C14: =IF(C13=12,1,C13+1) -> 10 | D14: =IF(F14="12월",(E14+1)&VLOOKUP(F14,인덱스!$C:$D,2,0),E14&VLOOKUP(F14,인덱스!$C:$D,2,0)) -> 201811 | E14: ="20"&B14 -> 2018 | F14: =C14&"월" -> 10월 | G14: =B14&"."&VLOOKUP(F14,인덱스!$A:$B,2,0) -> 18.10 | H14: =IFERROR(VLOOKUP(G14,#REF!,2,0),) -> 0 | I14: =IF(Q14="","",I13*(Q14/Q13)) -> 82.257274 | J14: =IF(R14="","",J13*(R14/R13)) -> 101.42616 | K14: =IF(S14="","",K13*(S14/S13)) -> 105.83061 | L14: =IF(U14="","",L13*(U14/U13)) -> 92.797678 | M14: =IF(V14="","",M13*(V14/V13)) -> 45.676713 | Q14: =IFERROR(__xludf.DUMMYFUNCTION("iferror(index('지수RAW'!$V$7:$V$12040,MATCH($D14,'지수RAW'!$R$7:$R$12040,0)-1,1),GOOGLEFINANCE(Q$2))"),2029.69) -> 2029.69 | R14: =IFERROR(__xludf.DUMMYFUNCTION("iferror(index('지수RAW'!$F$7:$F$12040,MATCH($D14,'지수RAW'!$B$7:$B$12040,0)-1,1),GOOGLEFINANCE(R$2))"),2711.74) -> 2711.74 | S14: =IFERROR(__xludf.DUMMYFUNCTION("iferror(index('지수RAW'!$N$7:$N$12040,MATCH($D14,'지수RAW'!$J$7:$J$12040,0)-1,1),GOOGLEFINANCE(S$2))"),7305.9) -> 7305.9 | U14: {=IFERROR(INDEX(지수RAW!$AT$7:$AT$12040,MATCH($D14,지수RAW!$AP$7:$AP$12040,0)-1,1),지수RAW!$AU$4)} -> 1215 | V14: =IFERROR(__xludf.DUMMYFUNCTION("iferror(index('지수RAW'!$AL$7:$AL$12040,MATCH($D14,'지수RAW'!$AH$7:$AH$12040,0)-1,1),GOOGLEFINANCE(V$2))"),6340.38) -> 6340.38 | W14: =IFERROR(__xludf.DUMMYFUNCTION("iferror(index('지수RAW'!$AD$7:$AD$12040,MATCH($D14,'지수RAW'!$Z$7:$Z$12040,0)-1,1),GOOGLEFINANCE(W$2))"),1140.97) -> 1140.97 | X14: =$W14*R14 -> 3094014 | Y14: =$W14*S14 -> 8335812.7 | Z14: =$W14*U14 -> 1386278.6 | AA14: =$W14*V14 -> 7234183.4 | AC14: =IF(Q14="","",AC13*(W14/W13)) -> 107.02581 | AD14: =IF(R14="","",AD13*(X14/X13)) -> 108.55217 | AE14: =IF(S14="","",AE13*(Y14/Y13)) -> 113.26607 | AF14: =IF(U14="","",AF13*(Z14/Z13)) -> 99.317462 | AG14: =IF(V14="","",AG13*(AA14/AA13)) -> 48.88587
B15: =IF(C14=12,B14+1,B14) -> 18 | C15: =IF(C14=12,1,C14+1) -> 11 | D15: =IF(F15="12월",(E15+1)&VLOOKUP(F15,인덱스!$C:$D,2,0),E15&VLOOKUP(F15,인덱스!$C:$D,2,0)) -> 201812 | E15: ="20"&B15 -> 2018 | F15: =C15&"월" -> 11월 | G15: =B15&"."&VLOOKUP(F15,인덱스!$A:$B,2,0) -> 18.11 | H15: =IFERROR(VLOOKUP(G15,#REF!,2,0),) -> 0 | I15: =IF(Q15="","",I14*(Q15/Q14)) -> 84.979473 | J15: =IF(R15="","",J14*(R15/R14)) -> 103.23757 | K15: =IF(S15="","",K14*(S15/S14)) -> 106.18754 | L15: =IF(U15="","",L14*(U15/U14)) -> 93.637822 | M15: =IF(V15="","",M14*(V15/V14)) -> 28.969382 | Q15: =IFERROR(__xludf.DUMMYFUNCTION("iferror(index('지수RAW'!$V$7:$V$12040,MATCH($D15,'지수RAW'!$R$7:$R$12040,0)-1,1),GOOGLEFINANCE(Q$2))"),2096.86) -> 2096.86 | R15: =IFERROR(__xludf.DUMMYFUNCTION("iferror(index('지수RAW'!$F$7:$F$12040,MATCH($D15,'지수RAW'!$B$7:$B$12040,0)-1,1),GOOGLEFINANCE(R$2))"),2760.17) -> 2760.17 | S15: =IFERROR(__xludf.DUMMYFUNCTION("iferror(index('지수RAW'!$N$7:$N$12040,MATCH($D15,'지수RAW'!$J$7:$J$12040,0)-1,1),GOOGLEFINANCE(S$2))"),7330.54) -> 7330.54 | U15: {=IFERROR(INDEX(지수RAW!$AT$7:$AT$12040,MATCH($D15,지수RAW!$AP$7:$AP$12040,0)-1,1),지수RAW!$AU$4)} -> 1226 | V15: =IFERROR(__xludf.DUMMYFUNCTION("iferror(index('지수RAW'!$AL$7:$AL$12040,MATCH($D15,'지수RAW'!$AH$7:$AH$12040,0)-1,1),GOOGLEFINANCE(V$2))"),4021.237) -> 4021.237 | W15: =IFERROR(__xludf.DUMMYFUNCTION("iferror(index('지수RAW'!$AD$7:$AD$12040,MATCH($D15,'지수RAW'!$Z$7:$Z$12040,0)-1,1),GOOGLEFINANCE(W$2))"),1119.53) -> 1119.53 | X15: =$W15*R15 -> 3090093.1 | Y15: =$W15*S15 -> 8206759.4 | Z15: =$W15*U15 -> 1372543.8 | AA15: =$W15*V15 -> 4501895.5 | AC15: =IF(Q15="","",AC14*(W15/W14)) -> 105.01468 | AD15: =IF(R15="","",AD14*(X15/X14)) -> 108.4146 | AE15: =IF(S15="","",AE14*(Y15/Y14)) -> 111.51251 | AF15: =IF(U15="","",AF14*(Z15/Z14)) -> 98.333459 | AG15: =IF(V15="","",AG14*(AA15/AA14)) -> 30.422104
B16: =IF(C15=12,B15+1,B15) -> 18 | C16: =IF(C15=12,1,C15+1) -> 12 | D16: =IF(F16="12월",(E16+1)&VLOOKUP(F16,인덱스!$C:$D,2,0),E16&VLOOKUP(F16,인덱스!$C:$D,2,0)) -> 20191 | E16: ="20"&B16 -> 2018 | F16: =C16&"월" -> 12월 | G16: =B16&"."&VLOOKUP(F16,인덱스!$A:$B,2,0) -> 18.12 | H16: =IFERROR(VLOOKUP(G16,#REF!,2,0),) -> 0 | I16: =IF(Q16="","",I15*(Q16/Q15)) -> 82.717255 | J16: =IF(R16="","",J15*(R16/R15)) -> 93.76274 | K16: =IF(S16="","",K15*(S16/S15)) -> 96.116256 | L16: =IF(U16="","",L15*(U16/U15)) -> 97.861453 | M16: =IF(V16="","",M15*(V16/V15)) -> 26.740939 | Q16: =IFERROR(__xludf.DUMMYFUNCTION("iferror(index('지수RAW'!$V$7:$V$12040,MATCH($D16,'지수RAW'!$R$7:$R$12040,0)-1,1),GOOGLEFINANCE(Q$2))"),2041.04) -> 2041.04 | R16: =IFERROR(__xludf.DUMMYFUNCTION("iferror(index('지수RAW'!$F$7:$F$12040,MATCH($D16,'지수RAW'!$B$7:$B$12040,0)-1,1),GOOGLEFINANCE(R$2))"),2506.85) -> 2506.85 | S16: =IFERROR(__xludf.DUMMYFUNCTION("iferror(index('지수RAW'!$N$7:$N$12040,MATCH($D16,'지수RAW'!$J$7:$J$12040,0)-1,1),GOOGLEFINANCE(S$2))"),6635.28) -> 6635.28 | U16: {=IFERROR(INDEX(지수RAW!$AT$7:$AT$12040,MATCH($D16,지수RAW!$AP$7:$AP$12040,0)-1,1),지수RAW!$AU$4)} -> 1281.3 | V16: =IFERROR(__xludf.DUMMYFUNCTION("iferror(index('지수RAW'!$AL$7:$AL$12040,MATCH($D16,'지수RAW'!$AH$7:$AH$12040,0)-1,1),GOOGLEFINANCE(V$2))"),3711.907) -> 3711.907 | W16: =IFERROR(__xludf.DUMMYFUNCTION("iferror(index('지수RAW'!$AD$7:$AD$12040,MATCH($D16,'지수RAW'!$Z$7:$Z$12040,0)-1,1),GOOGLEFINANCE(W$2))"),1112.5) -> 1112.5 | X16: =$W16*R16 -> 2788870.6 | Y16: =$W16*S16 -> 7381749 | Z16: =$W16*U16 -> 1425446.2 | AA16: =$W16*V16 -> 4129496.5 | AC16: =IF(Q16="","",AC15*(W16/W15)) -> 104.35525 | AD16: =IF(R16="","",AD15*(X16/X15)) -> 97.846341 | AE16: =IF(S16="","",AE15*(Y16/Y15)) -> 100.30236 | AF16: =IF(U16="","",AF15*(Z16/Z15)) -> 102.12356 | AG16: =IF(V16="","",AG15*(AA16/AA15)) -> 27.905573
B17: =IF(C16=12,B16+1,B16) -> 19 | C17: =IF(C16=12,1,C16+1) -> 1 | D17: =IF(F17="12월",(E17+1)&VLOOKUP(F17,인덱스!$C:$D,2,0),E17&VLOOKUP(F17,인덱스!$C:$D,2,0)) -> 20192 | E17: ="20"&B17 -> 2019 | F17: =C17&"월" -> 1월 | G17: =B17&"."&VLOOKUP(F17,인덱스!$A:$B,2,0) -> 19.01 | H17: =IFERROR(VLOOKUP(G17,#REF!,2,0),) -> 0 | I17: =IF(Q17="","",I16*(Q17/Q16)) -> 89.355985 | J17: =IF(R17="","",J16*(R17/R16)) -> 101.14041 | K17: =IF(S17="","",K16*(S17/S16)) -> 105.48064 | L17: =IF(U17="","",L16*(U17/U16)) -> 101.21439 | M17: =IF(V17="","",M16*(V17/V16)) -> 24.633279 | Q17: =IFERROR(__xludf.DUMMYFUNCTION("iferror(index('지수RAW'!$V$7:$V$12040,MATCH($D17,'지수RAW'!$R$7:$R$12040,0)-1,1),GOOGLEFINANCE(Q$2))"),2204.85) -> 2204.85 | R17: =IFERROR(__xludf.DUMMYFUNCTION("iferror(index('지수RAW'!$F$7:$F$12040,MATCH($D17,'지수RAW'!$B$7:$B$12040,0)-1,1),GOOGLEFINANCE(R$2))"),2704.1) -> 2704.1 | S17: =IFERROR(__xludf.DUMMYFUNCTION("iferror(index('지수RAW'!$N$7:$N$12040,MATCH($D17,'지수RAW'!$J$7:$J$12040,0)-1,1),GOOGLEFINANCE(S$2))"),7281.74) -> 7281.74 | U17: {=IFERROR(INDEX(지수RAW!$AT$7:$AT$12040,MATCH($D17,지수RAW!$AP$7:$AP$12040,0)-1,1),지수RAW!$AU$4)} -> 1325.2 | V17: =IFERROR(__xludf.DUMMYFUNCTION("iferror(index('지수RAW'!$AL$7:$AL$12040,MATCH($D17,'지수RAW'!$AH$7:$AH$12040,0)-1,1),GOOGLEFINANCE(V$2))"),3419.343) -> 3419.343 | W17: =IFERROR(__xludf.DUMMYFUNCTION("iferror(index('지수RAW'!$AD$7:$AD$12040,MATCH($D17,'지수RAW'!$Z$7:$Z$12040,0)-1,1),GOOGLEFINANCE(W$2))"),1111.55) -> 1111.55 | X17: =$W17*R17 -> 3005742.4 | Y17: =$W17*S17 -> 8094018.1 | Z17: =$W17*U17 -> 1473026.1 | AA17: =$W17*V17 -> 3800770.7 | AC17: =IF(Q17="","",AC16*(W17/W16)) -> 104.26614 | AD17: =IF(R17="","",AD16*(X17/X16)) -> 105.45519 | AE17: =IF(S17="","",AE16*(Y17/Y16)) -> 109.98059 | AF17: =IF(U17="","",AF16*(Z17/Z16)) -> 105.53233 | AG17: =IF(V17="","",AG16*(AA17/AA16)) -> 25.684168
B18: =IF(C17=12,B17+1,B17) -> 19 | C18: =IF(C17=12,1,C17+1) -> 2 | D18: =IF(F18="12월",(E18+1)&VLOOKUP(F18,인덱스!$C:$D,2,0),E18&VLOOKUP(F18,인덱스!$C:$D,2,0)) -> 20193 | E18: ="20"&B18 -> 2019 | F18: =C18&"월" -> 2월 | G18: =B18&"."&VLOOKUP(F18,인덱스!$A:$B,2,0) -> 19.02 | H18: =IFERROR(VLOOKUP(G18,#REF!,2,0),) -> 0 | I18: =IF(Q18="","",I17*(Q18/Q17)) -> 88.974626 | J18: =IF(R18="","",J17*(R18/R17)) -> 104.1472 | K18: =IF(S18="","",K17*(S18/S17)) -> 109.11349 | L18: =IF(U18="","",L17*(U18/U17)) -> 100.51936 | M18: =IF(V18="","",M17*(V18/V17)) -> 27.389084 | Q18: =IFERROR(__xludf.DUMMYFUNCTION("iferror(index('지수RAW'!$V$7:$V$12040,MATCH($D18,'지수RAW'!$R$7:$R$12040,0)-1,1),GOOGLEFINANCE(Q$2))"),2195.44) -> 2195.44 | R18: =IFERROR(__xludf.DUMMYFUNCTION("iferror(index('지수RAW'!$F$7:$F$12040,MATCH($D18,'지수RAW'!$B$7:$B$12040,0)-1,1),GOOGLEFINANCE(R$2))"),2784.49) -> 2784.49 | S18: =IFERROR(__xludf.DUMMYFUNCTION("iferror(index('지수RAW'!$N$7:$N$12040,MATCH($D18,'지수RAW'!$J$7:$J$12040,0)-1,1),GOOGLEFINANCE(S$2))"),7532.53) -> 7532.53 | U18: {=IFERROR(INDEX(지수RAW!$AT$7:$AT$12040,MATCH($D18,지수RAW!$AP$7:$AP$12040,0)-1,1),지수RAW!$AU$4)} -> 1316.1 | V18: =IFERROR(__xludf.DUMMYFUNCTION("iferror(index('지수RAW'!$AL$7:$AL$12040,MATCH($D18,'지수RAW'!$AH$7:$AH$12040,0)-1,1),GOOGLEFINANCE(V$2))"),3801.876) -> 3801.876 | W18: =IFERROR(__xludf.DUMMYFUNCTION("iferror(index('지수RAW'!$AD$7:$AD$12040,MATCH($D18,'지수RAW'!$Z$7:$Z$12040,0)-1,1),GOOGLEFINANCE(W$2))"),1124.22) -> 1124.22 | X18: =$W18*R18 -> 3130379.3 | Y18: =$W18*S18 -> 8468220.9 | Z18: =$W18*U18 -> 1479585.9 | AA18: =$W18*V18 -> 4274145 | AC18: =IF(Q18="","",AC17*(W18/W17)) -> 105.45461 | AD18: =IF(R18="","",AD17*(X18/X17)) -> 109.82803 | AE18: =IF(S18="","",AE17*(Y18/Y17)) -> 115.06521 | AF18: =IF(U18="","",AF17*(Z18/Z17)) -> 106.0023 | AG18: =IF(V18="","",AG17*(AA18/AA17)) -> 28.883053
